Workbook

Sheet 2011
A2: 2011 | B2: Tháng | C2: 1 | D2: 2 | E2: 3 | F2: 4 | G2: 5 | H2: 6 | I2: 7 | J2: 8 | K2: 9 | L2: 10 | M2: 11 | N2: 12
A3: Sản lượng [tr.kwh] | B3: Buôn Tua Srah | C3: 20.36022 | D3: 13.2335 | E3: 32.38392 | F3: 22.10473 | G3: 13.20159 | H3: 23.40821 | I3: 26.18775 | J3: 32.64566 | K3: 24.48477 | L3: 57.841044 | M3: 40.54699 | N3: 35.03804
B4: Buôn Kuốp | C4: 67.0074 | D4: 33.6937 | E4: 61.7548 | F4: 58.13992 | G4: 41.222 | H4: 134.8409 | I4: 138.4777 | J4: 165.659 | K4: 159.8654 | L4: 186.99843 | M4: 151.0607 | N4: 146.0193
B5: Srê Pốk 3 | C5: 45.438944 | D5: 38.32763 | E5: 40.16233 | F5: 47.26508 | G5: 44.83983 | H5: 120.19458 | I5: 109.09842 | J5: 134.28808 | K5: 139.98536 | L5: 153.80946 | M5: 121.84898 | N5: 111.80434
B6: Tổng SL | C6: =SUM(C3:C5) -> 132.80656 | D6: =SUM(D3:D5) -> 85.25483 | E6: =SUM(E3:E5) -> 134.30105 | F6: =SUM(F3:F5) -> 127.50973 | G6: =SUM(G3:G5) -> 99.26342 | H6: =SUM(H3:H5) -> 278.44369 | I6: =SUM(I3:I5) -> 273.76387 | J6: =SUM(J3:J5) -> 332.59274 | ... N6: =SUM(N3:N5) -> 292.86168 | O6: =SUM(C6:N6) -> 2793.2387
A7: Qv[m3/s] | B7: Buôn Tua Srah | C7: 38.738901 | D7: 27.375714 | E7: 31.266452 | F7: 28.102333 | G7: 44.509282 | H7: 93.037875 | I7: 99.703548 | J7: 132.49587 | K7: 178.27869 | L7: 269.91674 | M7: 114.62364 | N7: 78.933501
B8: Buôn Kuốp | C8: 102.52958 | D8: 51.785294 | E8: 95.840348 | F8: 86.302944 | G8: 63.986307 | H8: 207.32219 | I8: 206.37612 | J8: 246.5064 | K8: 256.36646 | L8: 521.44682 | M8: 296.26387 | N8: 217.26832
B9: Srê Pốk 3 | C9: 138.14023 | D9: 89.401538 | E9: 119.48977 | F9: 127.35359 | G9: 113.12717 | H9: 299.59664 | I9: 287.3075 | J9: 329.96972 | K9: 378.19711 | L9: 683.25019 | M9: 383.07581 | N9: 278.49357
A10: Nh độ trung bình Đak Lak

Sheet 2012
A2: 2012 | B2: Tháng | C2: 1 | D2: 2 | E2: 3 | F2: 4 | G2: 5 | H2: 6 | I2: 7 | J2: 8 | K2: 9 | L2: 10 | M2: 11 | N2: 12
A3: Sản lượng [tr.kwh] | B3: Buôn Tua Srah | C3: 17.5932 | D3: 24.94517 | E3: 30.77642 | F3: 18.33162 | G3: 32.24081 | H3: 18.23986 | I3: 23.38631 | J3: 24.5884 | K3: 20.33348 | L3: 61.82758 | M3: 45.54044 | N3: 26.21386
B4: Buôn Kuốp | C4: 72.3597 | D4: 54.996 | E4: 64.9281 | F4: 85.383 | G4: 107.4793 | H4: 71.3818 | I4: 90.2008 | J4: 89.81539 | K4: 129.15731 | L4: 197.9634 | M4: 126.4997 | N4: 60.7525
B5: Srê Pốk 3 | C5: 59.67432 | D5: 45.21073 | E5: 53.4509 | F5: 68.85603 | G5: 89.70359 | H5: 59.16254 | I5: 85.5031 | J5: 70.4134 | K5: 128.244 | L5: 162.0315 | M5: 98.2735 | N5: 51.8919
B6: Tổng SL | C6: =SUM(C3:C5) -> 149.62722 | D6: =SUM(D3:D5) -> 125.1519 | E6: =SUM(E3:E5) -> 149.15542 | F6: =SUM(F3:F5) -> 172.57065 | G6: =SUM(G3:G5) -> 229.4237 | H6: =SUM(H3:H5) -> 148.7842 | I6: =SUM(I3:I5) -> 199.09021 | J6: =SUM(J3:J5) -> 184.81719 | ... N6: =SUM(N3:N5) -> 138.85826 | O6: =SUM(C6:N6) -> 2467.3497
A7: Qv[m3/s] | B7: Buôn Tua Srah | C7: 55.972894 | D7: 40.181793 | E7: 32.362718 | F7: 67.798986 | G7: 64.259356 | H7: 69.118346 | I7: 99.439609 | J7: 99.352768 | K7: 216.54866 | L7: 230.99618 | M7: 85.825744 | N7: 50.229207
B8: Buôn Kuốp | C8: 107.80451 | D8: 88.78174 | E8: 106.74732 | F8: 139.19058 | G8: 166.96087 | H8: 117.49011 | I8: 142.8783 | J8: 138.94243 | K8: 215.86121 | L8: 396.08518 | M8: 198.77782 | N8: 100.21833
B9: Srê Pốk 3 | C9: 149.43791 | D9: 119.94285 | E9: 131.3246 | F9: 178.58927 | G9: 222.09614 | H9: 159.66054 | I9: 198.9925 | J9: 186.6959 | K9: 341.46844 | L9: 503.63967 | M9: 251.19641 | N9: 120.80567
A10: Nh độ trung bình Đak Lak

Sheet 2013
A2: 2013 | B2: Tháng | C2: 1 | D2: 2 | E2: 3 | F2: 4 | G2: 5 | H2: 6 | I2: 7 | J2: 8 | K2: 9 | L2: 10 | M2: 11 | N2: 12
A3: Sản lượng [tr.kwh] | B3: Buôn Tua Srah | C3: 14.8712 | D3: 12.562 | E3: 19.8315 | F3: 15.3008 | G3: 14.8426 | H3: 25.203587 | I3: 28.0868 | J3: 28.7976 | K3: 27.6682 | L3: 52.666 | M3: 29.3862 | N3: 23.6578
B4: Buôn Kuốp | C4: 40.0302 | D4: 19.7265 | E4: 37.5998 | F4: 30.851 | G4: 48.6099 | H4: 101.43202 | I4: 131.5686 | J4: 123.1328 | K4: 101.0059 | L4: 171.2066 | M4: 137.9204 | N4: 92.8843
B5: Srê Pốk 3 | C5: 29.3931 | D5: 19.7365 | E5: 34.729 | F5: 29.2267 | G5: 42.7624 | H5: 95.330378 | I5: 117.224 | J5: 109.4514 | K5: 92.4506 | L5: 144.6243 | M5: 108.6551 | N5: 73.2728
B6: Tổng SL | C6: =SUM(C3:C5) -> 84.2945 | D6: =SUM(D3:D5) -> 52.025 | E6: =SUM(E3:E5) -> 92.1603 | F6: =SUM(F3:F5) -> 75.3785 | G6: =SUM(G3:G5) -> 106.2149 | H6: =SUM(H3:H5) -> 221.96598 | I6: =SUM(I3:I5) -> 276.8794 | J6: =SUM(J3:J5) -> 261.3818 | ... N6: =SUM(N3:N5) -> 189.8149 | O6: =SUM(C6:N6) -> 2225.6986
A7: Qv[m3/s] | B7: Buôn Tua Srah | C7: 41.046547 | D7: 28.786989 | E7: 25.524188 | F7: 31.451485 | G7: 50.590148 | H7: 99.378532 | I7: 133.13818 | J7: 128.81654 | K7: 188.24695 | L7: 161.7535 | M7: 97.149583 | N7: 56.430754
B8: Buôn Kuốp | C8: 63.127122 | D8: 43.621885 | E8: 60.753311 | F8: 56.528831 | G8: 79.147664 | H8: 159.44253 | I8: 202.28723 | J8: 193.73232 | K8: 247.08143 | L8: 397.59522 | M8: 242.35144 | N8: 141.83356
B9: Srê Pốk 3 | C9: 87.389783 | D9: 56.888558 | E9: 82.588299 | F9: 73.786034 | G9: 109.71457 | H9: 242.06339 | I9: 292.04648 | J9: 270.01632 | K9: 354.64919 | L9: 491.37926 | M9: 293.03302 | N9: 175.15001
A10: Nh độ trung bình Đak Lak

Sheet 2014
A2: 2014 | B2: Tháng | C2: 1 | D2: 2 | E2: 3 | F2: 4 | G2: 5 | H2: 6 | I2: 7 | J2: 8 | K2: 9 | L2: 10 | M2: 11 | N2: 12
A3: Sản lượng [tr.kwh] | B3: Buôn Tua Srah | C3: 25.793 | D3: 25.0957 | E3: 29.4891 | F3: 14.04501 | G3: 10.383187 | H3: 19.245 | I3: 42.0276 | J3: 38.6109 | K3: 32.2169 | L3: 50.4257 | M3: 17.2343 | N3: 17.038915
B4: Buôn Kuốp | C4: 57.8553 | D4: 47.6954 | E4: 58.5853 | F4: 35.4518 | G4: 47.9816 | H4: 79.4217 | I4: 193.5838 | J4: 187.1901 | K4: 151.3705 | L4: 156.6713 | M4: 69.2145 | N4: 59.4885
B5: Srê Pốk 3 | C5: 42.3856 | D5: 40.9999 | E5: 41.3543 | F5: 30.1175 | G5: 46.6073 | H5: 74.8871 | I5: 157.558 | J5: 156.8312 | K5: 126.2071 | L5: 121.0948 | M5: 59.8045 | N5: 38.7106
B6: Tổng SL | C6: =SUM(C3:C5) -> 126.0339 | D6: =SUM(D3:D5) -> 113.791 | E6: =SUM(E3:E5) -> 129.4287 | F6: =SUM(F3:F5) -> 79.61431 | G6: =SUM(G3:G5) -> 104.97209 | H6: =SUM(H3:H5) -> 173.5538 | I6: =SUM(I3:I5) -> 393.1694 | J6: =SUM(J3:J5) -> 382.6322 | ... N6: =SUM(N3:N5) -> 115.23801 | O6: =SUM(C6:N6) -> 2402.673
A7: Qv[m3/s] | B7: Buôn Tua Srah | C7: 35.14656 | D7: 27.159066 | E7: 23.631079 | F7: 40.349888 | G7: 51.112524 | H7: 91.451207 | I7: 161.7291 | J7: 192.08525 | K7: 178.71935 | L7: 117.00135 | M7: 66.74421 | N7: 56.586699
B8: Buôn Kuốp | C8: 93.210678 | D8: 85.132578 | E8: 96.811325 | F8: 61.131164 | G8: 75.17912 | H8: 132.88201 | I8: 298.58466 | J8: 310.17372 | K8: 254.12895 | L8: 239.04485 | M8: 111.36381 | N8: 98.869482
B9: Srê Pốk 3 | C9: 112.54409 | D9: 99.778604 | E9: 107.20042 | F9: 83.122756 | G9: 116.29652 | H9: 190.05413 | I9: 406.16879 | J9: 409.37731 | K9: 340.22951 | L9: 303.00463 | M9: 143.02083 | N9: 120.28483
A10: Nh độ trung bình Đak Lak

Sheet 2015
A2: 2015 | B2: Tháng | C2: 1 | D2: 2 | E2: 3 | F2: 4 | G2: 5 | H2: 6 | I2: 7 | J2: 8 | K2: 9 | L2: 10 | M2: 11 | N2: 12
A3: Sản lượng [tr.kwh] | B3: Buôn Tua Srah | C3: 19.6557 | D3: 16.1954 | E3: 21.9926 | F3: 19.5488 | G3: 14.5856 | H3: 16.866854 | I3: 30.4535 | J3: 23.6356 | K3: 10.947 | L3: 5.6862 | M3: 6.8306 | N3: 11.5308
B4: Buôn Kuốp | C4: 49.9482 | D4: 28.3017 | E4: 35.6988 | F4: 35.8584 | G4: 34.9673 | H4: 56.235633 | I4: 110.3762 | J4: 119.4764 | K4: 95.11 | L4: 71.2113 | M4: 51.6435 | N4: 47.1095
B5: Srê Pốk 3 | C5: 42.5503 | D5: 28.2159 | E5: 25.0046 | F5: 36.2131 | G5: 26.3318 | H5: 52.941454 | I5: 82.6439 | J5: 94.8208 | K5: 80.0471 | L5: 72.5511 | M5: 43.6264 | N5: 32.6814
B6: Tổng SL | C6: =SUM(C3:C5) -> 112.1542 | D6: =SUM(D3:D5) -> 72.713 | E6: =SUM(E3:E5) -> 82.696 | F6: =SUM(F3:F5) -> 91.6203 | G6: =SUM(G3:G5) -> 75.8847 | H6: =SUM(H3:H5) -> 126.04394 | I6: =SUM(I3:I5) -> 223.4736 | J6: =SUM(J3:J5) -> 237.9328 | ... N6: =SUM(N3:N5) -> 91.3217 | O6: =SUM(C6:N6) -> 1551.4934
A7: Qv[m3/s] | B7: Buôn Tua Srah | C7: 36.899219 | D7: 27.700378 | E7: 21.834744 | F7: 20.873681 | G7: 32.755231 | H7: 65.172759 | I7: 84.748947 | J7: 100.64194 | K7: 89.368024 | L7: 95.338733 | M7: 65.611737 | N7: 49.560215
B8: Buôn Kuốp | C8: 76.865498 | D8: 53.108223 | E8: 58.2926 | F8: 59.105112 | G8: 58.009431 | H8: 91.987962 | I8: 170.74673 | J8: 182.65645 | K8: 151.25769 | L8: 111.81286 | M8: 87.662924 | N8: 76.222092
B9: Srê Pốk 3 | C9: 103.06839 | D9: 67.2875 | E9: 73.099355 | F9: 76.455333 | G9: 77.667097 | H9: 125.206 | I9: 207.57806 | J9: 233.69065 | K9: 208.90114 | L9: 173.16861 | M9: 115.11289 | N9: 97.740853
A10: Nh độ trung bình Đak Lak

Sheet 2016
A2: 2016 | B2: Tháng | C2: 1 | D2: 2 | E2: 3 | F2: 4 | G2: 5 | H2: 6 | I2: 7 | J2: 8 | K2: 9 | L2: 10 | M2: 11 | N2: 12
A3: Sản lượng [tr.kwh] | B3: Buôn Tua Srah | C3: 20.582 | D3: 14.8163 | E3: 17.2857 | F3: 16.085 | G3: 14.9197 | H3: 13.799793 | I3: 24.193315 | J3: 24.424044 | K3: 11.858167 | L3: 39.069295 | M3: 50.507665 | N3: 46.91089
B4: Buôn Kuốp | C4: 44.5619 | D4: 24.2981 | E4: 28.2843 | F4: 27.1287 | G4: 34.7167 | H4: 54.870967 | I4: 94.481976 | J4: 101.94488 | K4: 75.76553 | L4: 156.2935 | M4: 185.10087 | N4: 195.29755
B5: Srê Pốk 3 | C5: 40.5199 | D5: 25.0884 | E5: 19.3545 | F5: 18.6318 | G5: 34.0952 | H5: 47.132133 | I5: 78.753672 | J5: 83.39679 | K5: 73.82829 | L5: 132.59153 | M5: 144.76706 | N5: 155.64489
B6: Tổng SL | C6: =SUM(C3:C5) -> 105.6638 | D6: =SUM(D3:D5) -> 64.2028 | E6: =SUM(E3:E5) -> 64.9245 | F6: =SUM(F3:F5) -> 61.8455 | G6: =SUM(G3:G5) -> 83.7316 | H6: =SUM(H3:H5) -> 115.80289 | I6: =SUM(I3:I5) -> 197.42896 | J6: =SUM(J3:J5) -> 209.76571 | ... N6: =SUM(N3:N5) -> 397.85334 | O6: =SUM(C6:N6) -> 2171.001
A7: Qv[m3/s] | B7: Buôn Tua Srah | C7: 29.580185 | D7: 16.848667 | E7: 18.407985 | F7: 16.031015 | G7: 33.494147 | H7: 59.30572 | I7: 76.749817 | J7: 99.231311 | K7: 121.8447 | L7: 202.08879 | M7: 187.22087 | N7: 135.9685
B8: Buôn Kuốp | C8: 70.392358 | D8: 43.487144 | E8: 45.855622 | F8: 47.572161 | G8: 57.765901 | H8: 91.75391 | I8: 143.95738 | J8: 155.58183 | K8: 123.93045 | L8: 235.81004 | M8: 504.5287 | N8: 439.25058
B9: Srê Pốk 3 | C9: 89.380078 | D9: 56.301844 | E9: 58.579712 | F9: 60.297955 | G9: 74.282482 | H9: 132.462 | I9: 182.57258 | J9: 204.89195 | K9: 193.66223 | L9: 327.74541 | M9: 586.31107 | N9: 502.26662
A10: Nh độ trung bình Đak Lak

Sheet 2017
A2: 2017 | B2: Tháng | C2: 1 | D2: 2 | E2: 3 | F2: 4 | G2: 5 | H2: 6 | I2: 7 | J2: 8 | K2: 9 | L2: 10 | M2: 11 | N2: 12
A3: Sản lượng [tr.kwh] | B3: Buôn Tua Srah | C3: 31.364886 | D3: 21.60449 | E3: 24.754403 | F3: 30.05862 | G3: 35.61779 | H3: 49.377231 | I3: 26.841632 | J3: 41.756316 | K3: 61.071907 | L3: 55.999552 | M3: 54.19413 | N3: 41.483337
B4: Buôn Kuốp | C4: 147.31777 | D4: 84.774965 | E4: 56.843451 | F4: 71.933518 | G4: 138.78362 | H4: 184.92082 | I4: 158.92539 | J4: 166.84723 | K4: 177.18828 | L4: 183.54134 | M4: 182.61075 | N4: 189.60796
B5: Srê Pốk 3 | C5: 108.60763 | D5: 60.113166 | E5: 46.122815 | F5: 47.596593 | G5: 110.79442 | H5: 147.72679 | I5: 132.76311 | J5: 131.70101 | K5: 140.74008 | L5: 143.57094 | M5: 150.22648 | N5: 154.08353
B6: Tổng SL | C6: =SUM(C3:C5) -> 287.29029 | D6: =SUM(D3:D5) -> 166.49262 | E6: =SUM(E3:E5) -> 127.72067 | F6: =SUM(F3:F5) -> 149.58873 | G6: =SUM(G3:G5) -> 285.19584 | H6: =SUM(H3:H5) -> 382.02484 | I6: =SUM(I3:I5) -> 318.53013 | J6: =SUM(J3:J5) -> 340.30456 | ... N6: =SUM(N3:N5) -> 385.17483 | O6: =SUM(C6:N6) -> 3591.466
A7: Qv[m3/s] | B7: Buôn Tua Srah | C7: 82.21947 | D7: 52.005773 | E7: 36.557854 | F7: 43.784482 | G7: 118.53983 | H7: 102.65489 | I7: 183.00931 | J7: 189.46759 | K7: 162.03647 | L7: 187.77008 | M7: 185.45051 | N7: 118.30959
B8: Buôn Kuốp | C8: 222.91057 | D8: 147.19554 | E8: 94.039588 | F8: 119.32148 | G8: 209.19464 | H8: 293.85304 | I8: 238.38863 | J8: 264.46797 | K8: 278.70858 | L8: 306.82673 | M8: 394.47959 | N8: 417.73706
B9: Srê Pốk 3 | C9: 265.1704 | D9: 167.97764 | E9: 105.82415 | F9: 137.94645 | G9: 274.45105 | H9: 377.66242 | I9: 324.0507 | J9: 347.81799 | K9: 359.16566 | L9: 415.63728 | M9: 473.73453 | N9: 476.69318
A10: Nh độ trung bình Đak Lak

Sheet 2018
A2: 2018 | B2: Tháng | C2: 1 | D2: 2 | E2: 3 | F2: 4 | G2: 5 | H2: 6 | I2: 7 | J2: 8 | K2: 9 | L2: 10 | M2: 11 | N2: 12
A3: Sản lượng [tr.kwh] | B3: Buôn Tua Srah | C3: 29.766293 | D3: 25.200817 | E3: 30.107096 | F3: 24.195173 | G3: 15.15389 | H3: 20.327558 | I3: 30.515135 | J3: 39.90778 | K3: 53.387757 | L3: 57.173652 | M3: 24.243527 | N3: 27.942358
B4: Buôn Kuốp | C4: 125.76103 | D4: 63.206233 | E4: 66.400333 | F4: 59.581733 | G4: 57.857051 | H4: 71.134424 | I4: 118.96296 | J4: 141.01818 | K4: 164.50247 | L4: 147.8251 | M4: 88.371789 | N4: 114.59878
B5: Srê Pốk 3 | C5: 84.546729 | D5: 51.033551 | E5: 46.668175 | F5: 40.693682 | G5: 41.664416 | H5: 62.748268 | I5: 93.599611 | J5: 113.87151 | K5: 131.23712 | L5: 110.50994 | M5: 56.484309 | N5: 83.636537
B6: Tổng SL | C6: =SUM(C3:C5) -> 240.07405 | D6: =SUM(D3:D5) -> 139.4406 | E6: =SUM(E3:E5) -> 143.1756 | F6: =SUM(F3:F5) -> 124.47059 | G6: =SUM(G3:G5) -> 114.67536 | H6: =SUM(H3:H5) -> 154.21025 | I6: =SUM(I3:I5) -> 243.0777 | J6: =SUM(J3:J5) -> 294.79748 | ... N6: =SUM(N3:N5) -> 226.17768 | O6: =SUM(C6:N6) -> 2513.835
A7: Qv[m3/s] | B7: Buôn Tua Srah | C7: 60.156741 | D7: 39.041922 | E7: 36.131442 | F7: 29.832383 | G7: 53.66219 | H7: 69.586727 | I7: 144.02002 | J7: 225.96623 | K7: 218.48003 | L7: 116.32079 | M7: 91.773558 | N7: 84.96806
B8: Buôn Kuốp | C8: 195.88534 | D8: 110.09904 | E8: 109.62335 | F8: 100.19696 | G8: 88.834883 | H8: 116.48197 | I8: 182.10581 | J8: 220.81793 | K8: 307.0659 | L8: 224.28876 | M8: 142.88118 | N8: 177.05547
B9: Srê Pốk 3 | C9: 224.46274 | D9: 125.70594 | E9: 118.27513 | F9: 111.48669 | G9: 119.52535 | H9: 150.98576 | I9: 230.32676 | J9: 282.68649 | K9: 414.17153 | L9: 266.45848 | M9: 167.84344 | N9: 203.0458
A10: Nh độ trung bình Đak Lak

Sheet 2019
A2: 2019 | B2: Tháng | C2: 1 | D2: 2 | E2: 3 | F2: 4 | G2: 5 | H2: 6 | I2: 7 | J2: 8 | K2: 9 | L2: 10 | M2: 11 | N2: 12
A3: Sản lượng [tr.kwh] | B3: Buôn Tua Srah | C3: 22.552582 | D3: 20.843499 | E3: 29.454129 | F3: 20.305261 | G3: 13.686037 | H3: 10.809939 | I3: 12.072376 | J3: 35.882241 | K3: 30.512249 | L3: 41.633334 | M3: 47.532623 | N3: 24.291548
B4: Buôn Kuốp | C4: 126.22684 | D4: 48.359608 | E4: 60.347191 | F4: 47.448669 | G4: 52.397392 | H4: 60.510795 | I4: 56.785312 | J4: 151.6073 | K4: 179.00043 | L4: 139.15063 | M4: 176.23853 | N4: 85.396231
B5: Srê Pốk 3 | C5: 91.580513 | D5: 37.416698 | E5: 43.255248 | F5: 33.997204 | G5: 39.573388 | H5: 49.437029 | I5: 43.086667 | J5: 123.83851 | K5: 139.80565 | L5: 110.98678 | M5: 138.42449 | N5: 63.395966
B6: Tổng SL | C6: =SUM(C3:C5) -> 240.35994 | D6: =SUM(D3:D5) -> 106.6198 | E6: =SUM(E3:E5) -> 133.05657 | F6: =SUM(F3:F5) -> 101.75113 | G6: =SUM(G3:G5) -> 105.65682 | H6: =SUM(H3:H5) -> 120.75776 | I6: =SUM(I3:I5) -> 111.94436 | J6: =SUM(J3:J5) -> 311.32804 | ... N6: =SUM(N3:N5) -> 173.08375 | O6: =SUM(C6:N6) -> 2407.8429
A7: Qv[m3/s] | B7: Buôn Tua Srah | C7: 71.103282 | D7: 33.986028 | E7: 27.042327 | F7: 29.647688 | G7: 32.275658 | H7: 46.812663 | I7: 63.078359 | J7: 151.61793 | K7: 234.25468 | L7: 107.68454 | M7: 167.07582 | N7: 66.735623
B8: Buôn Kuốp | C8: 191.71425 | D8: 85.032031 | E8: 95.812717 | F8: 79.89078 | G8: 79.719896 | H8: 98.342429 | I8: 83.888468 | J8: 228.90794 | K8: 279.39416 | L8: 207.80495 | M8: 361.99019 | N8: 130.82224
B9: Srê Pốk 3 | C9: 222.57467 | D9: 98.437766 | E9: 107.94456 | F9: 90.475965 | G9: 102.79357 | H9: 126.99468 | I9: 112.86932 | J9: 306.62201 | K9: 380.10066 | L9: 268.33363 | M9: 433.1337 | N9: 157.3719
A10: Nh độ trung bình Đak Lak

Sheet 2020
A2: 2020 | B2: Tháng | C2: 1 | D2: 2 | E2: 3 | F2: 4 | G2: 5 | H2: 6 | I2: 7 | J2: 8 | K2: 9 | L2: 10 | M2: 11 | N2: 12
A3: Sản lượng [tr.kwh] | B3: Buôn Tua Srah | C3: 24.566247 | D3: 22.680795 | E3: 25.492475 | F3: 14.732552 | G3: 13.924613 | H3: 10.573797 | I3: 21.065653 | J3: 36.942778 | K3: 37.933303 | L3: 22.716196 | M3: 46.793722 | N3: 43.477065
B4: Buôn Kuốp | C4: 52.160717 | D4: 38.226069 | E4: 44.340093 | F4: 29.286831 | G4: 28.97667 | H4: 75.012168 | I4: 99.726883 | J4: 195.32552 | K4: 179.58833 | L4: 193.41799 | M4: 189.00704 | N4: 202.91343
B5: Srê Pốk 3 | C5: 41.345302 | D5: 31.129698 | E5: 32.180596 | F5: 24.479286 | G5: 21.331489 | H5: 59.464099 | I5: 88.018131 | J5: 156.36365 | K5: 144.26588 | L5: 159.09288 | M5: 151.58335 | N5: 154.71384
B6: Tổng SL | C6: =SUM(C3:C5) -> 118.07227 | D6: =SUM(D3:D5) -> 92.036562 | E6: =SUM(E3:E5) -> 102.01316 | F6: =SUM(F3:F5) -> 68.498669 | G6: =SUM(G3:G5) -> 64.232772 | H6: =SUM(H3:H5) -> 145.05006 | I6: =SUM(I3:I5) -> 208.81067 | J6: =SUM(J3:J5) -> 388.63195 | ... N6: =SUM(N3:N5) -> 401.10433 | O6: =SUM(C6:N6) -> 2712.8491
A7: Qv[m3/s] | B7: Buôn Tua Srah | C7: 38.335743 | D7: 30.678343 | E7: 21.352688 | F7: 21.049056 | G7: 20.578763 | H7: 56.8435 | I7: 81.693978 | J7: 161.20344 | K7: 148.64895 | L7: 207.94839 | M7: 154.26261 | N7: 120.95
B8: Buôn Kuốp | C8: 81.947953 | D8: 71.063774 | E8: 76.290331 | F8: 51.970844 | G8: 54.088726 | H8: 114.60419 | I8: 152.08066 | J8: 294.63577 | K8: 281.7028 | L8: 305.00406 | M8: 375.07224 | N8: 478.93007
B9: Srê Pốk 3 | C9: 102.58008 | D9: 79.424073 | E9: 84.231183 | F9: 61.948611 | G9: 58.830645 | H9: 162.83056 | I9: 216.80645 | J9: 389.22446 | K9: 366.97639 | L9: 441.59005 | M9: 459.68472 | N9: 548.84274
A10: Nh độ trung bình Đak Lak

Sheet 2021
A2: 2021 | B2: Tháng | C2: 1 | D2: 2 | E2: 3 | F2: 4 | G2: 5 | H2: 6 | I2: 7 | J2: 8 | K2: 9 | L2: 10 | M2: 11 | N2: 12
A3: Sản lượng [tr.kwh] | B3: Buôn Tua Srah | C3: 29.164322 | D3: 26.659042 | E3: 29.322748 | F3: 17.608157 | G3: 14.824697 | H3: 11.728077 | I3: 19.794796 | J3: 20.401461 | K3: 26.350116 | L3: 44.472706 | M3: 56.895758 | N3: 42.598994
B4: Buôn Kuốp | C4: 110.36861 | D4: 61.981315 | E4: 61.426697 | F4: 46.831182 | G4: 53.630073 | H4: 49.802541 | I4: 81.105309 | J4: 86.792305 | K4: 166.61845 | L4: 192.76609 | M4: 192.90018 | N4: 181.47385
B5: Srê Pốk 3 | C5: 84.770698 | D5: 51.779504 | E5: 43.542483 | F5: 34.706388 | G5: 42.992444 | H5: 39.461504 | I5: 62.004547 | J5: 69.880806 | K5: 133.27867 | L5: 157.50554 | M5: 157.48853 | N5: 142.26363
B6: Tổng SL | C6: =SUM(C3:C5) -> 224.30363 | D6: =SUM(D3:D5) -> 140.41986 | E6: =SUM(E3:E5) -> 134.29193 | F6: =SUM(F3:F5) -> 99.145727 | G6: =SUM(G3:G5) -> 111.44721 | H6: =SUM(H3:H5) -> 100.99212 | I6: =SUM(I3:I5) -> 162.90465 | J6: =SUM(J3:J5) -> 177.07457 | ... N6: =SUM(N3:N5) -> 366.33647 | O6: =SUM(C6:N6) -> 2645.1922
A7: Qv[m3/s] | B7: Buôn Tua Srah | C7: 58.965484 | D7: 38.899464 | E7: 25.662796 | F7: 32.283333 | G7: 39.448387 | H7: 43.9515 | I7: 74.111022 | J7: 86.702097 | K7: 191.96167 | L7: 257.33812 | M7: 189.4975 | N7: 132.20188
B8: Buôn Kuốp | C8: 168.78632 | D8: 109.25754 | E8: 96.941623 | F8: 78.852807 | G8: 82.612942 | H8: 81.090311 | I8: 124.71106 | J8: 133.48928 | K8: 267.21809 | L8: 385.2704 | M8: 536.53333 | N8: 429.99194
B9: Srê Pốk 3 | C9: 205.91398 | D9: 128.625 | E9: 113.03495 | F9: 95.518056 | G9: 102.07392 | H9: 103.44444 | I9: 157.18409 | J9: 173.92204 | K9: 375.68194 | L9: 520.12941 | M9: 619.40972 | N9: 493.87097
A10: Nh độ trung bình Đak Lak

Sheet 2022
A2: 2022 | B2: Tháng | C2: 1 | D2: 2 | E2: 3 | F2: 4 | G2: 5 | H2: 6 | I2: 7 | J2: 8 | K2: 9 | L2: 10 | M2: 11 | N2: 12
A3: Sản lượng [tr.kwh] | B3: Buôn Tua Srah | C3: 33.846495 | D3: 26.111035 | E3: 29.464168 | F3: 23.123994 | G3: 24.26412 | H3: 19.669999 | I3: 33.584183 | J3: 33.506472 | K3: 49.386005 | L3: 50.809694 | M3: 38.933324 | N3: 26.922136 | O3: 389.62163
B4: Buôn Kuốp | C4: 122.50594 | D4: 66.919391 | E4: 74.536054 | F4: 71.592841 | G4: 110.18254 | H4: 115.54801 | I4: 163.90113 | J4: 194.26107 | K4: 193.20663 | L4: 196.85657 | M4: 168.38219 | N4: 153.62955
B5: Srê Pốk 3 | C5: 88.530286 | D5: 51.253605 | E5: 56.609789 | F5: 56.499315 | G5: 80.578216 | H5: 99.400854 | I5: 139.00227 | J5: 157.24092 | K5: 155.01226 | L5: 154.35775 | M5: 124.99819 | N5: 115.04165
B6: Tổng SL | C6: =SUM(C3:C5) -> 244.88273 | D6: =SUM(D3:D5) -> 144.28403 | E6: =SUM(E3:E5) -> 160.61001 | F6: =SUM(F3:F5) -> 151.21615 | G6: =SUM(G3:G5) -> 215.02488 | H6: =SUM(H3:H5) -> 234.61886 | I6: =SUM(I3:I5) -> 336.48757 | J6: =SUM(J3:J5) -> 385.00846 | ... N6: =SUM(N3:N5) -> 295.59334 | O6: =SUM(C6:N6) -> 3299.6686
A7: Qv[m3/s] | B7: Buôn Tua Srah | C7: 63.148602 | D7: 48.989226 | E7: 35.236559 | F7: 40.715333 | G7: 81.48172 | H7: 90.426889 | I7: 119.99634 | J7: 197.58253 | K7: 186.16006 | L7: 154.82903 | M7: 92.518556 | N7: 76.388763
B8: Buôn Kuốp | C8: 187.24462 | D8: 117.5372 | E8: 117.43145 | F8: 116.60139 | G8: 165.90059 | H8: 183.66533 | I8: 245.81183 | J8: 326.14773 | K8: 344.36883 | L8: 375.5905 | M8: 269.26935 | N8: 234.77127
B9: Srê Pốk 3 | C9: 222.71774 | D9: 141.22768 | E9: 140.88844 | F9: 139.59306 | G9: 219.69355 | H9: 258.53333 | I9: 336.91398 | J9: 459.18414 | K9: 485.46817 | L9: 472.53763 | M9: 327.00972 | N9: 281.7043
A10: Nh độ trung bình Đak Lak

Sheet 2023
A2: 2023 | B2: Tháng | C2: 1 | D2: 2 | E2: 3 | F2: 4 | G2: 5 | H2: 6 | I2: 7 | J2: 8 | K2: 9 | L2: 10 | M2: 11 | N2: 12
A3: Sản lượng [tr.kwh] | B3: Buôn Tua Srah | C3: 26.196023 | D3: 28.209338 | E3: 28.871706 | F3: 23.975395 | G3: 7.3071525 | H3: 18.939634 | I3: 27.245995 | J3: 42.1535 | K3: 60.604639 | L3: 53.14364 | M3: 42.16551 | N3: 31.564489
B4: Buôn Kuốp | C4: 113.13543 | D4: 71.298942 | E4: 70.493765 | F4: 62.21761 | G4: 43.759362 | H4: 86.330209 | I4: 141.67029 | J4: 165.0364 | K4: 195.23754 | L4: 198.50974 | M4: 163.31552 | N4: 125.96985
B5: Srê Pốk 3 | C5: 77.740175 | D5: 56.724159 | E5: 48.161091 | F5: 48.283617 | G5: 32.450061 | H5: 71.005335 | I5: 122.00622 | J5: 136.39896 | K5: 153.81894 | L5: 154.06885 | M5: 124.33634 | N5: 94.563952
B6: Tổng SL | C6: =SUM(C3:C5) -> 217.07163 | D6: =SUM(D3:D5) -> 156.23244 | E6: =SUM(E3:E5) -> 147.52656 | F6: =SUM(F3:F5) -> 134.47662 | G6: =SUM(G3:G5) -> 83.516576 | H6: =SUM(H3:H5) -> 176.27518 | I6: =SUM(I3:I5) -> 290.9225 | J6: =SUM(J3:J5) -> 343.58886 | ... N6: =SUM(N3:N5) -> 252.09829 | O6: =SUM(C6:N6) -> 2946.9094
A7: Qv[m3/s] | B7: Buôn Tua Srah | C7: 65.299086 | D7: 36.709524 | E7: 22.855645 | F7: 27.988111 | G7: 48.204839 | H7: 83.425333 | I7: 171.28839 | J7: 200.94759 | K7: 206.59583 | L7: 169.93817 | M7: 123.92639 | N7: 83
B8: Buôn Kuốp | C8: 174.73766 | D8: 127.35625 | E8: 108.60906 | F8: 105.0179 | G8: 64.385454 | H8: 133.54334 | I8: 220.71517 | J8: 263.93816 | K8: 392.73611 | L8: 340.18951 | M8: 273.68055 | N8: 195.77149
B9: Srê Pốk 3 | C9: 205.48522 | D9: 145.83036 | E9: 126.83871 | F9: 114.52639 | G9: 101.15995 | H9: 176.75694 | I9: 314.22849 | J9: 362.17071 | K9: 516.00834 | L9: 438.97984 | M9: 336.45695 | N9: 239.06183
A10: Nh độ trung bình Đak Lak

Sheet 2024
A2: 2024 | B2: Tháng | C2: 1 | D2: 2 | E2: 3 | F2: 4 | G2: 5 | H2: 6 | I2: 7 | J2: 8 | K2: 9 | L2: 10 | M2: 11 | N2: 12
A3: Sản lượng [tr.kwh] | B3: Buôn Tua Srah | C3: 27.937672 | D3: 20.617662 | E3: 18.585531 | F3: 17.219772 | G3: 15.081443 | H3: 23.646055 | I3: 25.25175 | J3: 41.779786 | K3: 44.453589 | L3: 55.450869 | M3: 34.91992 | N3: 19.430501
B4: Buôn Kuốp | C4: 73.596486 | D4: 42.83267 | E4: 35.955297 | F4: 35.97154 | G4: 54.107531 | H4: 76.060693 | I4: 135.6869 | J4: 176.95261 | K4: 179.47948 | L4: 185.35783 | M4: 134.72738 | N4: 137.06629
B5: Srê Pốk 3 | C5: 57.337101 | D5: 34.666365 | E5: 20.916936 | F5: 29.124926 | G5: 40.091331 | H5: 59.665924 | I5: 100.58271 | J5: 135.36586 | K5: 144.50772 | L5: 141.72221 | M5: 98.199024 | N5: 93.285053
B6: Tổng SL | C6: =SUM(C3:C5) -> 158.87126 | D6: =SUM(D3:D5) -> 98.116697 | E6: =SUM(E3:E5) -> 75.457763 | F6: =SUM(F3:F5) -> 82.316238 | G6: =SUM(G3:G5) -> 109.2803 | H6: =SUM(H3:H5) -> 159.37267 | I6: =SUM(I3:I5) -> 261.52136 | J6: =SUM(J3:J5) -> 354.09826 | ... N6: =SUM(N3:N5) -> 249.78184 | O6: =SUM(C6:N6) -> 2567.6344
A7: Qv[m3/s] | B7: Buôn Tua Srah | C7: 42.162626 | D7: 32.27 | E7: 20.516132 | F7: 23.573613 | G7: 55.27151 | H7: 51.7 | I7: 142.8629 | J7: 140.49597 | K7: 240.575 | L7: 137.51209 | M7: 113.1713 | N7: 112.09678
B8: Buôn Kuốp | C8: 113.54301 | D8: 75.311776 | E8: 59.876352 | F8: 62.27 | G8: 78.919355 | H8: 118.23888 | I8: 206.36828 | J8: 267.68945 | K8: 326.01 | L8: 290.95295 | M8: 227.44 | N8: 220.07124
B9: Srê Pốk 3 | C9: 136.53628 | D9: 89.978441 | E9: 71.677426 | F9: 76.03 | G9: 102.72984 | H9: 143.88194 | I9: 258.73252 | J9: 345.33737 | K9: 421.67 | L9: 344.87019 | M9: 268.59833 | N9: 248.40457
A10: Nh độ trung bình Đak Lak

Sheet BTS
C1: Sản lượng [tr.kwh] | Q1: Lưu lượng [m3/s]
C2: 1 | D2: 2 | E2: 3 | F2: 4 | G2: 5 | H2: 6 | I2: 7 | J2: 8 | K2: 9 | L2: 10 | M2: 11 | N2: 12 | O2: Tổng | Q2: 1 | R2: 2 | S2: 3 | T2: 4 | U2: 5 | V2: 6 | W2: 7 | X2: 8 | Y2: 9 | Z2: 10 | AA2: 11 | AB2: 12 | AC2: R | AD2: E | AE2: SHN | AF2: 8.88 | AG2: m3/khw
B3: 1977 | C3: =IF(Q3*DAY(EOMONTH(DATE($B3,$C$2,1),0))*24*3600/$AF$2/10^6>$AF$3,$AF$3,Q3*DAY(EOMONTH(DATE($B3,$C$2,1),0))*24*3600/$AF$2/10^6) -> 11.642595 | D3: =IF(R3*DAY(EOMONTH(DATE($B3,$D$2,1),0))*24*3600/$AF$2/10^6>$AF$3,$AF$3,R3*DAY(EOMONTH(DATE($B3,$D$2,1),0))*24*3600/$AF$2/10^6) -> 7.3284324 | E3: =IF(S3*DAY(EOMONTH(DATE($B3,$E$2,1),0))*24*3600/$AF$2/10^6>$AF$3,$AF$3,S3*DAY(EOMONTH(DATE($B3,$E$2,1),0))*24*3600/$AF$2/10^6) -> 5.4895135 | F3: =IF(T3*DAY(EOMONTH(DATE($B3,$F$2,1),0))*24*3600/$AF$2/10^6>$AF$3,$AF$3,T3*DAY(EOMONTH(DATE($B3,$F$2,1),0))*24*3600/$AF$2/10^6) -> 3.6486486 | G3: =IF(U3*DAY(EOMONTH(DATE($B3,$G$2,1),0))*24*3600/$AF$2/10^6>$AF$3,$AF$3,U3*DAY(EOMONTH(DATE($B3,$G$2,1),0))*24*3600/$AF$2/10^6) -> 5.2180541 | H3: =IF(V3*DAY(EOMONTH(DATE($B3,$H$2,1),0))*24*3600/$AF$2/10^6>$AF$3,$AF$3,V3*DAY(EOMONTH(DATE($B3,$H$2,1),0))*24*3600/$AF$2/10^6) -> 4.2032432 | I3: =IF(W3*DAY(EOMONTH(DATE($B3,$I$2,1),0))*24*3600/$AF$2/10^6>$AF$3,$AF$3,W3*DAY(EOMONTH(DATE($B3,$I$2,1),0))*24*3600/$AF$2/10^6) -> 14.779459 | J3: =IF(X3*DAY(EOMONTH(DATE($B3,$J$2,1),0))*24*3600/$AF$2/10^6>$AF$3,$AF$3,X3*DAY(EOMONTH(DATE($B3,$J$2,1),0))*24*3600/$AF$2/10^6) -> 14.93027 | K3: =IF(Y3*DAY(EOMONTH(DATE($B3,$K$2,1),0))*24*3600/$AF$2/10^6>$AF$3,$AF$3,Y3*DAY(EOMONTH(DATE($B3,$K$2,1),0))*24*3600/$AF$2/10^6) -> 48.454054 | L3: =IF(Z3*DAY(EOMONTH(DATE($B3,$L$2,1),0))*24*3600/$AF$2/10^6>$AF$3,$AF$3,Z3*DAY(EOMONTH(DATE($B3,$L$2,1),0))*24*3600/$AF$2/10^6) -> 46.44973 | M3: =IF(AA3*DAY(EOMONTH(DATE($B3,$M$2,1),0))*24*3600/$AF$2/10^6>$AF$3,$AF$3,AA3*DAY(EOMONTH(DATE($B3,$M$2,1),0))*24*3600/$AF$2/10^6) -> 25.744865 | N3: =IF(AB3*DAY(EOMONTH(DATE($B3,$N$2,1),0))*24*3600/$AF$2/10^6>$AF$3,$AF$3,AB3*DAY(EOMONTH(DATE($B3,$N$2,1),0))*24*3600/$AF$2/10^6) -> 13.271351 | O3: =SUM(C3:N3) -> 201.16022 | Q3: 38.6 | R3: 26.9 | S3: 18.2 | T3: 12.5 | U3: 17.3 | V3: 14.4 | W3: 49 | X3: 49.5 | Y3: 166 | Z3: 154 | AA3: 88.2 | AB3: 44 | AC3: =CORREL($Q$52:$V$52,Q3:V3) -> 0.87391486 | AD3: =SQRT(SUMXMY2($Q$52:$V$52,Q3:V3)) -> 59.353638 | AE3: A_max | AF3: 61.07 | AG3: tr.kwh
B4: 1978 | C4: =IF(Q4*DAY(EOMONTH(DATE($B4,$C$2,1),0))*24*3600/$AF$2/10^6>$AF$3,$AF$3,Q4*DAY(EOMONTH(DATE($B4,$C$2,1),0))*24*3600/$AF$2/10^6) -> 6.9372973 | D4: =IF(R4*DAY(EOMONTH(DATE($B4,$D$2,1),0))*24*3600/$AF$2/10^6>$AF$3,$AF$3,R4*DAY(EOMONTH(DATE($B4,$D$2,1),0))*24*3600/$AF$2/10^6) -> 4.4134054 | E4: =IF(S4*DAY(EOMONTH(DATE($B4,$E$2,1),0))*24*3600/$AF$2/10^6>$AF$3,$AF$3,S4*DAY(EOMONTH(DATE($B4,$E$2,1),0))*24*3600/$AF$2/10^6) -> 4.5544865 | F4: =IF(T4*DAY(EOMONTH(DATE($B4,$F$2,1),0))*24*3600/$AF$2/10^6>$AF$3,$AF$3,T4*DAY(EOMONTH(DATE($B4,$F$2,1),0))*24*3600/$AF$2/10^6) -> 4.2908108 | G4: =IF(U4*DAY(EOMONTH(DATE($B4,$G$2,1),0))*24*3600/$AF$2/10^6>$AF$3,$AF$3,U4*DAY(EOMONTH(DATE($B4,$G$2,1),0))*24*3600/$AF$2/10^6) -> 8.9883243 | H4: =IF(V4*DAY(EOMONTH(DATE($B4,$H$2,1),0))*24*3600/$AF$2/10^6>$AF$3,$AF$3,V4*DAY(EOMONTH(DATE($B4,$H$2,1),0))*24*3600/$AF$2/10^6) -> 9.0486486 | I4: =IF(W4*DAY(EOMONTH(DATE($B4,$I$2,1),0))*24*3600/$AF$2/10^6>$AF$3,$AF$3,W4*DAY(EOMONTH(DATE($B4,$I$2,1),0))*24*3600/$AF$2/10^6) -> 22.681946 | J4: =IF(X4*DAY(EOMONTH(DATE($B4,$J$2,1),0))*24*3600/$AF$2/10^6>$AF$3,$AF$3,X4*DAY(EOMONTH(DATE($B4,$J$2,1),0))*24*3600/$AF$2/10^6) -> 59.117838 | K4: =IF(Y4*DAY(EOMONTH(DATE($B4,$K$2,1),0))*24*3600/$AF$2/10^6>$AF$3,$AF$3,Y4*DAY(EOMONTH(DATE($B4,$K$2,1),0))*24*3600/$AF$2/10^6) -> 61.07 | L4: =IF(Z4*DAY(EOMONTH(DATE($B4,$L$2,1),0))*24*3600/$AF$2/10^6>$AF$3,$AF$3,Z4*DAY(EOMONTH(DATE($B4,$L$2,1),0))*24*3600/$AF$2/10^6) -> 61.07 | M4: =IF(AA4*DAY(EOMONTH(DATE($B4,$M$2,1),0))*24*3600/$AF$2/10^6>$AF$3,$AF$3,AA4*DAY(EOMONTH(DATE($B4,$M$2,1),0))*24*3600/$AF$2/10^6) -> 42.324324 | N4: =IF(AB4*DAY(EOMONTH(DATE($B4,$N$2,1),0))*24*3600/$AF$2/10^6>$AF$3,$AF$3,AB4*DAY(EOMONTH(DATE($B4,$N$2,1),0))*24*3600/$AF$2/10^6) -> 18.881514 | O4: =SUM(C4:N4) -> 303.37859 | Q4: 23 | R4: 16.2 | S4: 15.1 | T4: 14.7 | U4: 29.8 | V4: 31 | W4: 75.2 | X4: 196 | Y4: 225 | Z4: 275 | AA4: 145 | AB4: 62.6 | AC4: =CORREL($Q$52:$V$52,Q4:V4) -> 0.2667463 | AD4: =SQRT(SUMXMY2($Q$52:$V$52,Q4:V4)) -> 64.436933
B5: 1979 | C5: =IF(Q5*DAY(EOMONTH(DATE($B5,$C$2,1),0))*24*3600/$AF$2/10^6>$AF$3,$AF$3,Q5*DAY(EOMONTH(DATE($B5,$C$2,1),0))*24*3600/$AF$2/10^6) -> 11.16 | D5: =IF(R5*DAY(EOMONTH(DATE($B5,$D$2,1),0))*24*3600/$AF$2/10^6>$AF$3,$AF$3,R5*DAY(EOMONTH(DATE($B5,$D$2,1),0))*24*3600/$AF$2/10^6) -> 7.3284324 | E5: =IF(S5*DAY(EOMONTH(DATE($B5,$E$2,1),0))*24*3600/$AF$2/10^6>$AF$3,$AF$3,S5*DAY(EOMONTH(DATE($B5,$E$2,1),0))*24*3600/$AF$2/10^6) -> 6.4848649 | F5: =IF(T5*DAY(EOMONTH(DATE($B5,$F$2,1),0))*24*3600/$AF$2/10^6>$AF$3,$AF$3,T5*DAY(EOMONTH(DATE($B5,$F$2,1),0))*24*3600/$AF$2/10^6) -> 7.5308108 | G5: =IF(U5*DAY(EOMONTH(DATE($B5,$G$2,1),0))*24*3600/$AF$2/10^6>$AF$3,$AF$3,U5*DAY(EOMONTH(DATE($B5,$G$2,1),0))*24*3600/$AF$2/10^6) -> 10.526595 | H5: =IF(V5*DAY(EOMONTH(DATE($B5,$H$2,1),0))*24*3600/$AF$2/10^6>$AF$3,$AF$3,V5*DAY(EOMONTH(DATE($B5,$H$2,1),0))*24*3600/$AF$2/10^6) -> 25.803243 | I5: =IF(W5*DAY(EOMONTH(DATE($B5,$I$2,1),0))*24*3600/$AF$2/10^6>$AF$3,$AF$3,W5*DAY(EOMONTH(DATE($B5,$I$2,1),0))*24*3600/$AF$2/10^6) -> 49.767568 | J5: =IF(X5*DAY(EOMONTH(DATE($B5,$J$2,1),0))*24*3600/$AF$2/10^6>$AF$3,$AF$3,X5*DAY(EOMONTH(DATE($B5,$J$2,1),0))*24*3600/$AF$2/10^6) -> 61.07 | K5: =IF(Y5*DAY(EOMONTH(DATE($B5,$K$2,1),0))*24*3600/$AF$2/10^6>$AF$3,$AF$3,Y5*DAY(EOMONTH(DATE($B5,$K$2,1),0))*24*3600/$AF$2/10^6) -> 37.654054 | L5: =IF(Z5*DAY(EOMONTH(DATE($B5,$L$2,1),0))*24*3600/$AF$2/10^6>$AF$3,$AF$3,Z5*DAY(EOMONTH(DATE($B5,$L$2,1),0))*24*3600/$AF$2/10^6) -> 61.07 | M5: =IF(AA5*DAY(EOMONTH(DATE($B5,$M$2,1),0))*24*3600/$AF$2/10^6>$AF$3,$AF$3,AA5*DAY(EOMONTH(DATE($B5,$M$2,1),0))*24*3600/$AF$2/10^6) -> 43.783784 | N5: =IF(AB5*DAY(EOMONTH(DATE($B5,$N$2,1),0))*24*3600/$AF$2/10^6>$AF$3,$AF$3,AB5*DAY(EOMONTH(DATE($B5,$N$2,1),0))*24*3600/$AF$2/10^6) -> 24.491676 | O5: =SUM(C5:N5) -> 346.67103 | Q5: 37 | R5: 26.9 | S5: 21.5 | T5: 25.8 | U5: 34.9 | V5: 88.4 | W5: 165 | X5: 244 | Y5: 129 | Z5: 209 | AA5: 150 | AB5: 81.2 | AC5: =CORREL($Q$52:$V$52,Q5:V5) -> 0.23266446 | AD5: =SQRT(SUMXMY2($Q$52:$V$52,Q5:V5)) -> 58.674188
B6: 1980 | C6: =IF(Q6*DAY(EOMONTH(DATE($B6,$C$2,1),0))*24*3600/$AF$2/10^6>$AF$3,$AF$3,Q6*DAY(EOMONTH(DATE($B6,$C$2,1),0))*24*3600/$AF$2/10^6) -> 17.192432 | D6: =IF(R6*DAY(EOMONTH(DATE($B6,$D$2,1),0))*24*3600/$AF$2/10^6>$AF$3,$AF$3,R6*DAY(EOMONTH(DATE($B6,$D$2,1),0))*24*3600/$AF$2/10^6) -> 11.088973 | E6: =IF(S6*DAY(EOMONTH(DATE($B6,$E$2,1),0))*24*3600/$AF$2/10^6>$AF$3,$AF$3,S6*DAY(EOMONTH(DATE($B6,$E$2,1),0))*24*3600/$AF$2/10^6) -> 8.5358919 | F6: =IF(T6*DAY(EOMONTH(DATE($B6,$F$2,1),0))*24*3600/$AF$2/10^6>$AF$3,$AF$3,T6*DAY(EOMONTH(DATE($B6,$F$2,1),0))*24*3600/$AF$2/10^6) -> 8.2313514 | G6: =IF(U6*DAY(EOMONTH(DATE($B6,$G$2,1),0))*24*3600/$AF$2/10^6>$AF$3,$AF$3,U6*DAY(EOMONTH(DATE($B6,$G$2,1),0))*24*3600/$AF$2/10^6) -> 14.266703 | H6: =IF(V6*DAY(EOMONTH(DATE($B6,$H$2,1),0))*24*3600/$AF$2/10^6>$AF$3,$AF$3,V6*DAY(EOMONTH(DATE($B6,$H$2,1),0))*24*3600/$AF$2/10^6) -> 24.168649 | I6: =IF(W6*DAY(EOMONTH(DATE($B6,$I$2,1),0))*24*3600/$AF$2/10^6>$AF$3,$AF$3,W6*DAY(EOMONTH(DATE($B6,$I$2,1),0))*24*3600/$AF$2/10^6) -> 25.547351 | J6: =IF(X6*DAY(EOMONTH(DATE($B6,$J$2,1),0))*24*3600/$AF$2/10^6>$AF$3,$AF$3,X6*DAY(EOMONTH(DATE($B6,$J$2,1),0))*24*3600/$AF$2/10^6) -> 38.909189 | K6: =IF(Y6*DAY(EOMONTH(DATE($B6,$K$2,1),0))*24*3600/$AF$2/10^6>$AF$3,$AF$3,Y6*DAY(EOMONTH(DATE($B6,$K$2,1),0))*24*3600/$AF$2/10^6) -> 61.07 | L6: =IF(Z6*DAY(EOMONTH(DATE($B6,$L$2,1),0))*24*3600/$AF$2/10^6>$AF$3,$AF$3,Z6*DAY(EOMONTH(DATE($B6,$L$2,1),0))*24*3600/$AF$2/10^6) -> 61.07 | M6: =IF(AA6*DAY(EOMONTH(DATE($B6,$M$2,1),0))*24*3600/$AF$2/10^6>$AF$3,$AF$3,AA6*DAY(EOMONTH(DATE($B6,$M$2,1),0))*24*3600/$AF$2/10^6) -> 53.416216 | N6: =IF(AB6*DAY(EOMONTH(DATE($B6,$N$2,1),0))*24*3600/$AF$2/10^6>$AF$3,$AF$3,AB6*DAY(EOMONTH(DATE($B6,$N$2,1),0))*24*3600/$AF$2/10^6) -> 23.616973 | O6: =SUM(C6:N6) -> 347.11373 | Q6: 57 | R6: 39.3 | S6: 28.3 | T6: 28.2 | U6: 47.3 | V6: 82.8 | W6: 84.7 | X6: 129 | Y6: 249 | Z6: 241 | AA6: 183 | AB6: 78.3 | AC6: =CORREL($Q$52:$V$52,Q6:V6) -> 0.50383504 | AD6: =SQRT(SUMXMY2($Q$52:$V$52,Q6:V6)) -> 41.242845
B7: 1981 | C7: =IF(Q7*DAY(EOMONTH(DATE($B7,$C$2,1),0))*24*3600/$AF$2/10^6>$AF$3,$AF$3,Q7*DAY(EOMONTH(DATE($B7,$C$2,1),0))*24*3600/$AF$2/10^6) -> 14.236541 | D7: =IF(R7*DAY(EOMONTH(DATE($B7,$D$2,1),0))*24*3600/$AF$2/10^6>$AF$3,$AF$3,R7*DAY(EOMONTH(DATE($B7,$D$2,1),0))*24*3600/$AF$2/10^6) -> 9.2627027 | E7: =IF(S7*DAY(EOMONTH(DATE($B7,$E$2,1),0))*24*3600/$AF$2/10^6>$AF$3,$AF$3,S7*DAY(EOMONTH(DATE($B7,$E$2,1),0))*24*3600/$AF$2/10^6) -> 7.6913514 | F7: =IF(T7*DAY(EOMONTH(DATE($B7,$F$2,1),0))*24*3600/$AF$2/10^6>$AF$3,$AF$3,T7*DAY(EOMONTH(DATE($B7,$F$2,1),0))*24*3600/$AF$2/10^6) -> 7.0345946 | G7: =IF(U7*DAY(EOMONTH(DATE($B7,$G$2,1),0))*24*3600/$AF$2/10^6>$AF$3,$AF$3,U7*DAY(EOMONTH(DATE($B7,$G$2,1),0))*24*3600/$AF$2/10^6) -> 10.436108 | H7: =IF(V7*DAY(EOMONTH(DATE($B7,$H$2,1),0))*24*3600/$AF$2/10^6>$AF$3,$AF$3,V7*DAY(EOMONTH(DATE($B7,$H$2,1),0))*24*3600/$AF$2/10^6) -> 30.356757 | I7: =IF(W7*DAY(EOMONTH(DATE($B7,$I$2,1),0))*24*3600/$AF$2/10^6>$AF$3,$AF$3,W7*DAY(EOMONTH(DATE($B7,$I$2,1),0))*24*3600/$AF$2/10^6) -> 22.350162 | J7: =IF(X7*DAY(EOMONTH(DATE($B7,$J$2,1),0))*24*3600/$AF$2/10^6>$AF$3,$AF$3,X7*DAY(EOMONTH(DATE($B7,$J$2,1),0))*24*3600/$AF$2/10^6) -> 61.07 | K7: =IF(Y7*DAY(EOMONTH(DATE($B7,$K$2,1),0))*24*3600/$AF$2/10^6>$AF$3,$AF$3,Y7*DAY(EOMONTH(DATE($B7,$K$2,1),0))*24*3600/$AF$2/10^6) -> 43.783784 | L7: =IF(Z7*DAY(EOMONTH(DATE($B7,$L$2,1),0))*24*3600/$AF$2/10^6>$AF$3,$AF$3,Z7*DAY(EOMONTH(DATE($B7,$L$2,1),0))*24*3600/$AF$2/10^6) -> 61.07 | M7: =IF(AA7*DAY(EOMONTH(DATE($B7,$M$2,1),0))*24*3600/$AF$2/10^6>$AF$3,$AF$3,AA7*DAY(EOMONTH(DATE($B7,$M$2,1),0))*24*3600/$AF$2/10^6) -> 61.07 | N7: =IF(AB7*DAY(EOMONTH(DATE($B7,$N$2,1),0))*24*3600/$AF$2/10^6>$AF$3,$AF$3,AB7*DAY(EOMONTH(DATE($B7,$N$2,1),0))*24*3600/$AF$2/10^6) -> 47.656216 | O7: =SUM(C7:N7) -> 376.01822 | Q7: 47.2 | R7: 34 | S7: 25.5 | T7: 24.1 | U7: 34.6 | V7: 104 | W7: 74.1 | X7: 282 | Y7: 150 | Z7: 274 | AA7: 235 | AB7: 158 | AC7: =CORREL($Q$52:$V$52,Q7:V7) -> 0.34012835 | AD7: =SQRT(SUMXMY2($Q$52:$V$52,Q7:V7)) -> 63.862714
B8: 1982 | C8: =IF(Q8*DAY(EOMONTH(DATE($B8,$C$2,1),0))*24*3600/$AF$2/10^6>$AF$3,$AF$3,Q8*DAY(EOMONTH(DATE($B8,$C$2,1),0))*24*3600/$AF$2/10^6) -> 18.368757 | D8: =IF(R8*DAY(EOMONTH(DATE($B8,$D$2,1),0))*24*3600/$AF$2/10^6>$AF$3,$AF$3,R8*DAY(EOMONTH(DATE($B8,$D$2,1),0))*24*3600/$AF$2/10^6) -> 10.624865 | E8: =IF(S8*DAY(EOMONTH(DATE($B8,$E$2,1),0))*24*3600/$AF$2/10^6>$AF$3,$AF$3,S8*DAY(EOMONTH(DATE($B8,$E$2,1),0))*24*3600/$AF$2/10^6) -> 8.8676757 | F8: =IF(T8*DAY(EOMONTH(DATE($B8,$F$2,1),0))*24*3600/$AF$2/10^6>$AF$3,$AF$3,T8*DAY(EOMONTH(DATE($B8,$F$2,1),0))*24*3600/$AF$2/10^6) -> 9.1945946 | G8: =IF(U8*DAY(EOMONTH(DATE($B8,$G$2,1),0))*24*3600/$AF$2/10^6>$AF$3,$AF$3,U8*DAY(EOMONTH(DATE($B8,$G$2,1),0))*24*3600/$AF$2/10^6) -> 8.747027 | H8: =IF(V8*DAY(EOMONTH(DATE($B8,$H$2,1),0))*24*3600/$AF$2/10^6>$AF$3,$AF$3,V8*DAY(EOMONTH(DATE($B8,$H$2,1),0))*24*3600/$AF$2/10^6) -> 21.921081 | I8: =IF(W8*DAY(EOMONTH(DATE($B8,$I$2,1),0))*24*3600/$AF$2/10^6>$AF$3,$AF$3,W8*DAY(EOMONTH(DATE($B8,$I$2,1),0))*24*3600/$AF$2/10^6) -> 26.844324 | J8: =IF(X8*DAY(EOMONTH(DATE($B8,$J$2,1),0))*24*3600/$AF$2/10^6>$AF$3,$AF$3,X8*DAY(EOMONTH(DATE($B8,$J$2,1),0))*24*3600/$AF$2/10^6) -> 23.134378 | K8: =IF(Y8*DAY(EOMONTH(DATE($B8,$K$2,1),0))*24*3600/$AF$2/10^6>$AF$3,$AF$3,Y8*DAY(EOMONTH(DATE($B8,$K$2,1),0))*24*3600/$AF$2/10^6) -> 61.07 | L8: =IF(Z8*DAY(EOMONTH(DATE($B8,$L$2,1),0))*24*3600/$AF$2/10^6>$AF$3,$AF$3,Z8*DAY(EOMONTH(DATE($B8,$L$2,1),0))*24*3600/$AF$2/10^6) -> 40.718919 | M8: =IF(AA8*DAY(EOMONTH(DATE($B8,$M$2,1),0))*24*3600/$AF$2/10^6>$AF$3,$AF$3,AA8*DAY(EOMONTH(DATE($B8,$M$2,1),0))*24*3600/$AF$2/10^6) -> 23.555676 | N8: =IF(AB8*DAY(EOMONTH(DATE($B8,$N$2,1),0))*24*3600/$AF$2/10^6>$AF$3,$AF$3,AB8*DAY(EOMONTH(DATE($B8,$N$2,1),0))*24*3600/$AF$2/10^6) -> 14.779459 | O8: =SUM(C8:N8) -> 267.82676 | Q8: 60.9 | R8: 39 | S8: 29.4 | T8: 31.5 | U8: 29 | V8: 75.1 | W8: 89 | X8: 76.7 | Y8: 307 | Z8: 135 | AA8: 80.7 | AB8: 49 | AC8: =CORREL($Q$52:$V$52,Q8:V8) -> 0.65578929 | AD8: =SQRT(SUMXMY2($Q$52:$V$52,Q8:V8)) -> 32.815458
B9: 1983 | C9: =IF(Q9*DAY(EOMONTH(DATE($B9,$C$2,1),0))*24*3600/$AF$2/10^6>$AF$3,$AF$3,Q9*DAY(EOMONTH(DATE($B9,$C$2,1),0))*24*3600/$AF$2/10^6) -> 11.491784 | D9: =IF(R9*DAY(EOMONTH(DATE($B9,$D$2,1),0))*24*3600/$AF$2/10^6>$AF$3,$AF$3,R9*DAY(EOMONTH(DATE($B9,$D$2,1),0))*24*3600/$AF$2/10^6) -> 7.5191351 | E9: =IF(S9*DAY(EOMONTH(DATE($B9,$E$2,1),0))*24*3600/$AF$2/10^6>$AF$3,$AF$3,S9*DAY(EOMONTH(DATE($B9,$E$2,1),0))*24*3600/$AF$2/10^6) -> 6.6658378 | F9: =IF(T9*DAY(EOMONTH(DATE($B9,$F$2,1),0))*24*3600/$AF$2/10^6>$AF$3,$AF$3,T9*DAY(EOMONTH(DATE($B9,$F$2,1),0))*24*3600/$AF$2/10^6) -> 5.3416216 | G9: =IF(U9*DAY(EOMONTH(DATE($B9,$G$2,1),0))*24*3600/$AF$2/10^6>$AF$3,$AF$3,U9*DAY(EOMONTH(DATE($B9,$G$2,1),0))*24*3600/$AF$2/10^6) -> 8.5962162 | H9: =IF(V9*DAY(EOMONTH(DATE($B9,$H$2,1),0))*24*3600/$AF$2/10^6>$AF$3,$AF$3,V9*DAY(EOMONTH(DATE($B9,$H$2,1),0))*24*3600/$AF$2/10^6) -> 14.594595 | I9: =IF(W9*DAY(EOMONTH(DATE($B9,$I$2,1),0))*24*3600/$AF$2/10^6>$AF$3,$AF$3,W9*DAY(EOMONTH(DATE($B9,$I$2,1),0))*24*3600/$AF$2/10^6) -> 12.607784 | J9: =IF(X9*DAY(EOMONTH(DATE($B9,$J$2,1),0))*24*3600/$AF$2/10^6>$AF$3,$AF$3,X9*DAY(EOMONTH(DATE($B9,$J$2,1),0))*24*3600/$AF$2/10^6) -> 31.971892 | K9: =IF(Y9*DAY(EOMONTH(DATE($B9,$K$2,1),0))*24*3600/$AF$2/10^6>$AF$3,$AF$3,Y9*DAY(EOMONTH(DATE($B9,$K$2,1),0))*24*3600/$AF$2/10^6) -> 31.232432 | L9: =IF(Z9*DAY(EOMONTH(DATE($B9,$L$2,1),0))*24*3600/$AF$2/10^6>$AF$3,$AF$3,Z9*DAY(EOMONTH(DATE($B9,$L$2,1),0))*24*3600/$AF$2/10^6) -> 61.07 | M9: =IF(AA9*DAY(EOMONTH(DATE($B9,$M$2,1),0))*24*3600/$AF$2/10^6>$AF$3,$AF$3,AA9*DAY(EOMONTH(DATE($B9,$M$2,1),0))*24*3600/$AF$2/10^6) -> 35.902703 | N9: =IF(AB9*DAY(EOMONTH(DATE($B9,$N$2,1),0))*24*3600/$AF$2/10^6>$AF$3,$AF$3,AB9*DAY(EOMONTH(DATE($B9,$N$2,1),0))*24*3600/$AF$2/10^6) -> 18.429081 | O9: =SUM(C9:N9) -> 245.42308 | Q9: 38.1 | R9: 27.6 | S9: 22.1 | T9: 18.3 | U9: 28.5 | V9: 50 | W9: 41.8 | X9: 106 | Y9: 107 | Z9: 302 | AA9: 123 | AB9: 61.1 | AC9: =CORREL($Q$52:$V$52,Q9:V9) -> 0.60819158 | AD9: =SQRT(SUMXMY2($Q$52:$V$52,Q9:V9)) -> 42.632151
B10: 1984 | C10: =IF(Q10*DAY(EOMONTH(DATE($B10,$C$2,1),0))*24*3600/$AF$2/10^6>$AF$3,$AF$3,Q10*DAY(EOMONTH(DATE($B10,$C$2,1),0))*24*3600/$AF$2/10^6) -> 12.487135 | D10: =IF(R10*DAY(EOMONTH(DATE($B10,$D$2,1),0))*24*3600/$AF$2/10^6>$AF$3,$AF$3,R10*DAY(EOMONTH(DATE($B10,$D$2,1),0))*24*3600/$AF$2/10^6) -> 8.0134054 | E10: =IF(S10*DAY(EOMONTH(DATE($B10,$E$2,1),0))*24*3600/$AF$2/10^6>$AF$3,$AF$3,S10*DAY(EOMONTH(DATE($B10,$E$2,1),0))*24*3600/$AF$2/10^6) -> 6.6055135 | F10: =IF(T10*DAY(EOMONTH(DATE($B10,$F$2,1),0))*24*3600/$AF$2/10^6>$AF$3,$AF$3,T10*DAY(EOMONTH(DATE($B10,$F$2,1),0))*24*3600/$AF$2/10^6) -> 7.7935135 | G10: =IF(U10*DAY(EOMONTH(DATE($B10,$G$2,1),0))*24*3600/$AF$2/10^6>$AF$3,$AF$3,U10*DAY(EOMONTH(DATE($B10,$G$2,1),0))*24*3600/$AF$2/10^6) -> 13.241189 | H10: =IF(V10*DAY(EOMONTH(DATE($B10,$H$2,1),0))*24*3600/$AF$2/10^6>$AF$3,$AF$3,V10*DAY(EOMONTH(DATE($B10,$H$2,1),0))*24*3600/$AF$2/10^6) -> 23.672432 | I10: =IF(W10*DAY(EOMONTH(DATE($B10,$I$2,1),0))*24*3600/$AF$2/10^6>$AF$3,$AF$3,W10*DAY(EOMONTH(DATE($B10,$I$2,1),0))*24*3600/$AF$2/10^6) -> 28.623892 | J10: =IF(X10*DAY(EOMONTH(DATE($B10,$J$2,1),0))*24*3600/$AF$2/10^6>$AF$3,$AF$3,X10*DAY(EOMONTH(DATE($B10,$J$2,1),0))*24*3600/$AF$2/10^6) -> 61.07 | K10: =IF(Y10*DAY(EOMONTH(DATE($B10,$K$2,1),0))*24*3600/$AF$2/10^6>$AF$3,$AF$3,Y10*DAY(EOMONTH(DATE($B10,$K$2,1),0))*24*3600/$AF$2/10^6) -> 61.07 | L10: =IF(Z10*DAY(EOMONTH(DATE($B10,$L$2,1),0))*24*3600/$AF$2/10^6>$AF$3,$AF$3,Z10*DAY(EOMONTH(DATE($B10,$L$2,1),0))*24*3600/$AF$2/10^6) -> 61.07 | M10: =IF(AA10*DAY(EOMONTH(DATE($B10,$M$2,1),0))*24*3600/$AF$2/10^6>$AF$3,$AF$3,AA10*DAY(EOMONTH(DATE($B10,$M$2,1),0))*24*3600/$AF$2/10^6) -> 33.567568 | N10: =IF(AB10*DAY(EOMONTH(DATE($B10,$N$2,1),0))*24*3600/$AF$2/10^6>$AF$3,$AF$3,AB10*DAY(EOMONTH(DATE($B10,$N$2,1),0))*24*3600/$AF$2/10^6) -> 23.828108 | O10: =SUM(C10:N10) -> 341.04276 | Q10: 41.4 | R10: 28.4 | S10: 21.9 | T10: 26.7 | U10: 43.9 | V10: 81.1 | W10: 94.9 | X10: 296 | Y10: 250 | Z10: 254 | AA10: 115 | AB10: 79 | AC10: =CORREL($Q$52:$V$52,Q10:V10) -> 0.27121388 | AD10: =SQRT(SUMXMY2($Q$52:$V$52,Q10:V10)) -> 50.990178
B11: 1985 | C11: =IF(Q11*DAY(EOMONTH(DATE($B11,$C$2,1),0))*24*3600/$AF$2/10^6>$AF$3,$AF$3,Q11*DAY(EOMONTH(DATE($B11,$C$2,1),0))*24*3600/$AF$2/10^6) -> 12.96973 | D11: =IF(R11*DAY(EOMONTH(DATE($B11,$D$2,1),0))*24*3600/$AF$2/10^6>$AF$3,$AF$3,R11*DAY(EOMONTH(DATE($B11,$D$2,1),0))*24*3600/$AF$2/10^6) -> 8.172973 | E11: =IF(S11*DAY(EOMONTH(DATE($B11,$E$2,1),0))*24*3600/$AF$2/10^6>$AF$3,$AF$3,S11*DAY(EOMONTH(DATE($B11,$E$2,1),0))*24*3600/$AF$2/10^6) -> 7.0579459 | F11: =IF(T11*DAY(EOMONTH(DATE($B11,$F$2,1),0))*24*3600/$AF$2/10^6>$AF$3,$AF$3,T11*DAY(EOMONTH(DATE($B11,$F$2,1),0))*24*3600/$AF$2/10^6) -> 10.595676 | G11: =IF(U11*DAY(EOMONTH(DATE($B11,$G$2,1),0))*24*3600/$AF$2/10^6>$AF$3,$AF$3,U11*DAY(EOMONTH(DATE($B11,$G$2,1),0))*24*3600/$AF$2/10^6) -> 13.060216 | H11: =IF(V11*DAY(EOMONTH(DATE($B11,$H$2,1),0))*24*3600/$AF$2/10^6>$AF$3,$AF$3,V11*DAY(EOMONTH(DATE($B11,$H$2,1),0))*24*3600/$AF$2/10^6) -> 23.701622 | I11: =IF(W11*DAY(EOMONTH(DATE($B11,$I$2,1),0))*24*3600/$AF$2/10^6>$AF$3,$AF$3,W11*DAY(EOMONTH(DATE($B11,$I$2,1),0))*24*3600/$AF$2/10^6) -> 33.781622 | J11: =IF(X11*DAY(EOMONTH(DATE($B11,$J$2,1),0))*24*3600/$AF$2/10^6>$AF$3,$AF$3,X11*DAY(EOMONTH(DATE($B11,$J$2,1),0))*24*3600/$AF$2/10^6) -> 31.67027 | K11: =IF(Y11*DAY(EOMONTH(DATE($B11,$K$2,1),0))*24*3600/$AF$2/10^6>$AF$3,$AF$3,Y11*DAY(EOMONTH(DATE($B11,$K$2,1),0))*24*3600/$AF$2/10^6) -> 51.956757 | L11: =IF(Z11*DAY(EOMONTH(DATE($B11,$L$2,1),0))*24*3600/$AF$2/10^6>$AF$3,$AF$3,Z11*DAY(EOMONTH(DATE($B11,$L$2,1),0))*24*3600/$AF$2/10^6) -> 46.751351 | M11: =IF(AA11*DAY(EOMONTH(DATE($B11,$M$2,1),0))*24*3600/$AF$2/10^6>$AF$3,$AF$3,AA11*DAY(EOMONTH(DATE($B11,$M$2,1),0))*24*3600/$AF$2/10^6) -> 26.27027 | N11: =IF(AB11*DAY(EOMONTH(DATE($B11,$N$2,1),0))*24*3600/$AF$2/10^6>$AF$3,$AF$3,AB11*DAY(EOMONTH(DATE($B11,$N$2,1),0))*24*3600/$AF$2/10^6) -> 21.535784 | O11: =SUM(C11:N11) -> 287.52422 | Q11: 43 | R11: 30 | S11: 23.4 | T11: 36.3 | U11: 43.3 | V11: 81.2 | W11: 112 | X11: 105 | Y11: 178 | Z11: 155 | AA11: 90 | AB11: 71.4 | AC11: =CORREL($Q$52:$V$52,Q11:V11) -> 0.20759504 | AD11: =SQRT(SUMXMY2($Q$52:$V$52,Q11:V11)) -> 49.654328
B12: 1986 | C12: =IF(Q12*DAY(EOMONTH(DATE($B12,$C$2,1),0))*24*3600/$AF$2/10^6>$AF$3,$AF$3,Q12*DAY(EOMONTH(DATE($B12,$C$2,1),0))*24*3600/$AF$2/10^6) -> 11.763243 | D12: =IF(R12*DAY(EOMONTH(DATE($B12,$D$2,1),0))*24*3600/$AF$2/10^6>$AF$3,$AF$3,R12*DAY(EOMONTH(DATE($B12,$D$2,1),0))*24*3600/$AF$2/10^6) -> 6.8652973 | E12: =IF(S12*DAY(EOMONTH(DATE($B12,$E$2,1),0))*24*3600/$AF$2/10^6>$AF$3,$AF$3,S12*DAY(EOMONTH(DATE($B12,$E$2,1),0))*24*3600/$AF$2/10^6) -> 5.8514595 | F12: =IF(T12*DAY(EOMONTH(DATE($B12,$F$2,1),0))*24*3600/$AF$2/10^6>$AF$3,$AF$3,T12*DAY(EOMONTH(DATE($B12,$F$2,1),0))*24*3600/$AF$2/10^6) -> 3.8237838 | G12: =IF(U12*DAY(EOMONTH(DATE($B12,$G$2,1),0))*24*3600/$AF$2/10^6>$AF$3,$AF$3,U12*DAY(EOMONTH(DATE($B12,$G$2,1),0))*24*3600/$AF$2/10^6) -> 7.4198919 | H12: =IF(V12*DAY(EOMONTH(DATE($B12,$H$2,1),0))*24*3600/$AF$2/10^6>$AF$3,$AF$3,V12*DAY(EOMONTH(DATE($B12,$H$2,1),0))*24*3600/$AF$2/10^6) -> 9.9827027 | I12: =IF(W12*DAY(EOMONTH(DATE($B12,$I$2,1),0))*24*3600/$AF$2/10^6>$AF$3,$AF$3,W12*DAY(EOMONTH(DATE($B12,$I$2,1),0))*24*3600/$AF$2/10^6) -> 21.113514 | J12: =IF(X12*DAY(EOMONTH(DATE($B12,$J$2,1),0))*24*3600/$AF$2/10^6>$AF$3,$AF$3,X12*DAY(EOMONTH(DATE($B12,$J$2,1),0))*24*3600/$AF$2/10^6) -> 61.07 | K12: =IF(Y12*DAY(EOMONTH(DATE($B12,$K$2,1),0))*24*3600/$AF$2/10^6>$AF$3,$AF$3,Y12*DAY(EOMONTH(DATE($B12,$K$2,1),0))*24*3600/$AF$2/10^6) -> 48.745946 | L12: =IF(Z12*DAY(EOMONTH(DATE($B12,$L$2,1),0))*24*3600/$AF$2/10^6>$AF$3,$AF$3,Z12*DAY(EOMONTH(DATE($B12,$L$2,1),0))*24*3600/$AF$2/10^6) -> 49.465946 | M12: =IF(AA12*DAY(EOMONTH(DATE($B12,$M$2,1),0))*24*3600/$AF$2/10^6>$AF$3,$AF$3,AA12*DAY(EOMONTH(DATE($B12,$M$2,1),0))*24*3600/$AF$2/10^6) -> 28.225946 | N12: =IF(AB12*DAY(EOMONTH(DATE($B12,$N$2,1),0))*24*3600/$AF$2/10^6>$AF$3,$AF$3,AB12*DAY(EOMONTH(DATE($B12,$N$2,1),0))*24*3600/$AF$2/10^6) -> 34.083243 | O12: =SUM(C12:N12) -> 288.41097 | Q12: 39 | R12: 25.2 | S12: 19.4 | T12: 13.1 | U12: 24.6 | V12: 34.2 | W12: 70 | X12: 231 | Y12: 167 | Z12: 164 | AA12: 96.7 | AB12: 113 | AC12: =CORREL($Q$52:$V$52,Q12:V12) -> 0.89948351 | AD12: =SQRT(SUMXMY2($Q$52:$V$52,Q12:V12)) -> 48.347413
B13: 1987 | C13: =IF(Q13*DAY(EOMONTH(DATE($B13,$C$2,1),0))*24*3600/$AF$2/10^6>$AF$3,$AF$3,Q13*DAY(EOMONTH(DATE($B13,$C$2,1),0))*24*3600/$AF$2/10^6) -> 15.382703 | D13: =IF(R13*DAY(EOMONTH(DATE($B13,$D$2,1),0))*24*3600/$AF$2/10^6>$AF$3,$AF$3,R13*DAY(EOMONTH(DATE($B13,$D$2,1),0))*24*3600/$AF$2/10^6) -> 9.0447568 | E13: =IF(S13*DAY(EOMONTH(DATE($B13,$E$2,1),0))*24*3600/$AF$2/10^6>$AF$3,$AF$3,S13*DAY(EOMONTH(DATE($B13,$E$2,1),0))*24*3600/$AF$2/10^6) -> 7.4802162 | F13: =IF(T13*DAY(EOMONTH(DATE($B13,$F$2,1),0))*24*3600/$AF$2/10^6>$AF$3,$AF$3,T13*DAY(EOMONTH(DATE($B13,$F$2,1),0))*24*3600/$AF$2/10^6) -> 4.8745946 | G13: =IF(U13*DAY(EOMONTH(DATE($B13,$G$2,1),0))*24*3600/$AF$2/10^6>$AF$3,$AF$3,U13*DAY(EOMONTH(DATE($B13,$G$2,1),0))*24*3600/$AF$2/10^6) -> 6.7563243 | H13: =IF(V13*DAY(EOMONTH(DATE($B13,$H$2,1),0))*24*3600/$AF$2/10^6>$AF$3,$AF$3,V13*DAY(EOMONTH(DATE($B13,$H$2,1),0))*24*3600/$AF$2/10^6) -> 18.681081 | I13: =IF(W13*DAY(EOMONTH(DATE($B13,$I$2,1),0))*24*3600/$AF$2/10^6>$AF$3,$AF$3,W13*DAY(EOMONTH(DATE($B13,$I$2,1),0))*24*3600/$AF$2/10^6) -> 35.591351 | J13: =IF(X13*DAY(EOMONTH(DATE($B13,$J$2,1),0))*24*3600/$AF$2/10^6>$AF$3,$AF$3,X13*DAY(EOMONTH(DATE($B13,$J$2,1),0))*24*3600/$AF$2/10^6) -> 36.797838 | K13: =IF(Y13*DAY(EOMONTH(DATE($B13,$K$2,1),0))*24*3600/$AF$2/10^6>$AF$3,$AF$3,Y13*DAY(EOMONTH(DATE($B13,$K$2,1),0))*24*3600/$AF$2/10^6) -> 61.07 | L13: =IF(Z13*DAY(EOMONTH(DATE($B13,$L$2,1),0))*24*3600/$AF$2/10^6>$AF$3,$AF$3,Z13*DAY(EOMONTH(DATE($B13,$L$2,1),0))*24*3600/$AF$2/10^6) -> 41.925405 | M13: =IF(AA13*DAY(EOMONTH(DATE($B13,$M$2,1),0))*24*3600/$AF$2/10^6>$AF$3,$AF$3,AA13*DAY(EOMONTH(DATE($B13,$M$2,1),0))*24*3600/$AF$2/10^6) -> 32.4 | N13: =IF(AB13*DAY(EOMONTH(DATE($B13,$N$2,1),0))*24*3600/$AF$2/10^6>$AF$3,$AF$3,AB13*DAY(EOMONTH(DATE($B13,$N$2,1),0))*24*3600/$AF$2/10^6) -> 20.902378 | O13: =SUM(C13:N13) -> 290.90665 | Q13: 51 | R13: 33.2 | S13: 24.8 | T13: 16.7 | U13: 22.4 | V13: 64 | W13: 118 | X13: 122 | Y13: 213 | Z13: 139 | AA13: 111 | AB13: 69.3 | AC13: =CORREL($Q$52:$V$52,Q13:V13) -> 0.71058982 | AD13: =SQRT(SUMXMY2($Q$52:$V$52,Q13:V13)) -> 36.898785
B14: 1988 | C14: =IF(Q14*DAY(EOMONTH(DATE($B14,$C$2,1),0))*24*3600/$AF$2/10^6>$AF$3,$AF$3,Q14*DAY(EOMONTH(DATE($B14,$C$2,1),0))*24*3600/$AF$2/10^6) -> 13.392 | D14: =IF(R14*DAY(EOMONTH(DATE($B14,$D$2,1),0))*24*3600/$AF$2/10^6>$AF$3,$AF$3,R14*DAY(EOMONTH(DATE($B14,$D$2,1),0))*24*3600/$AF$2/10^6) -> 8.9163243 | E14: =IF(S14*DAY(EOMONTH(DATE($B14,$E$2,1),0))*24*3600/$AF$2/10^6>$AF$3,$AF$3,S14*DAY(EOMONTH(DATE($B14,$E$2,1),0))*24*3600/$AF$2/10^6) -> 6.4848649 | F14: =IF(T14*DAY(EOMONTH(DATE($B14,$F$2,1),0))*24*3600/$AF$2/10^6>$AF$3,$AF$3,T14*DAY(EOMONTH(DATE($B14,$F$2,1),0))*24*3600/$AF$2/10^6) -> 6.4216216 | G14: =IF(U14*DAY(EOMONTH(DATE($B14,$G$2,1),0))*24*3600/$AF$2/10^6>$AF$3,$AF$3,U14*DAY(EOMONTH(DATE($B14,$G$2,1),0))*24*3600/$AF$2/10^6) -> 12.426811 | H14: =IF(V14*DAY(EOMONTH(DATE($B14,$H$2,1),0))*24*3600/$AF$2/10^6>$AF$3,$AF$3,V14*DAY(EOMONTH(DATE($B14,$H$2,1),0))*24*3600/$AF$2/10^6) -> 18.330811 | I14: =IF(W14*DAY(EOMONTH(DATE($B14,$I$2,1),0))*24*3600/$AF$2/10^6>$AF$3,$AF$3,W14*DAY(EOMONTH(DATE($B14,$I$2,1),0))*24*3600/$AF$2/10^6) -> 20.118162 | J14: =IF(X14*DAY(EOMONTH(DATE($B14,$J$2,1),0))*24*3600/$AF$2/10^6>$AF$3,$AF$3,X14*DAY(EOMONTH(DATE($B14,$J$2,1),0))*24*3600/$AF$2/10^6) -> 24.732973 | K14: =IF(Y14*DAY(EOMONTH(DATE($B14,$K$2,1),0))*24*3600/$AF$2/10^6>$AF$3,$AF$3,Y14*DAY(EOMONTH(DATE($B14,$K$2,1),0))*24*3600/$AF$2/10^6) -> 40.572973 | L14: =IF(Z14*DAY(EOMONTH(DATE($B14,$L$2,1),0))*24*3600/$AF$2/10^6>$AF$3,$AF$3,Z14*DAY(EOMONTH(DATE($B14,$L$2,1),0))*24*3600/$AF$2/10^6) -> 61.07 | M14: =IF(AA14*DAY(EOMONTH(DATE($B14,$M$2,1),0))*24*3600/$AF$2/10^6>$AF$3,$AF$3,AA14*DAY(EOMONTH(DATE($B14,$M$2,1),0))*24*3600/$AF$2/10^6) -> 50.497297 | N14: =IF(AB14*DAY(EOMONTH(DATE($B14,$N$2,1),0))*24*3600/$AF$2/10^6>$AF$3,$AF$3,AB14*DAY(EOMONTH(DATE($B14,$N$2,1),0))*24*3600/$AF$2/10^6) -> 24.461514 | O14: =SUM(C14:N14) -> 287.42535 | Q14: 44.4 | R14: 31.6 | S14: 21.5 | T14: 22 | U14: 41.2 | V14: 62.8 | W14: 66.7 | X14: 82 | Y14: 139 | Z14: 211 | AA14: 173 | AB14: 81.1 | AC14: =CORREL($Q$52:$V$52,Q14:V14) -> 0.48456318 | AD14: =SQRT(SUMXMY2($Q$52:$V$52,Q14:V14)) -> 38.389768
B15: 1989 | C15: =IF(Q15*DAY(EOMONTH(DATE($B15,$C$2,1),0))*24*3600/$AF$2/10^6>$AF$3,$AF$3,Q15*DAY(EOMONTH(DATE($B15,$C$2,1),0))*24*3600/$AF$2/10^6) -> 16.679676 | D15: =IF(R15*DAY(EOMONTH(DATE($B15,$D$2,1),0))*24*3600/$AF$2/10^6>$AF$3,$AF$3,R15*DAY(EOMONTH(DATE($B15,$D$2,1),0))*24*3600/$AF$2/10^6) -> 9.1537297 | E15: =IF(S15*DAY(EOMONTH(DATE($B15,$E$2,1),0))*24*3600/$AF$2/10^6>$AF$3,$AF$3,S15*DAY(EOMONTH(DATE($B15,$E$2,1),0))*24*3600/$AF$2/10^6) -> 9.4709189 | F15: =IF(T15*DAY(EOMONTH(DATE($B15,$F$2,1),0))*24*3600/$AF$2/10^6>$AF$3,$AF$3,T15*DAY(EOMONTH(DATE($B15,$F$2,1),0))*24*3600/$AF$2/10^6) -> 9.107027 | G15: =IF(U15*DAY(EOMONTH(DATE($B15,$G$2,1),0))*24*3600/$AF$2/10^6>$AF$3,$AF$3,U15*DAY(EOMONTH(DATE($B15,$G$2,1),0))*24*3600/$AF$2/10^6) -> 22.078703 | H15: =IF(V15*DAY(EOMONTH(DATE($B15,$H$2,1),0))*24*3600/$AF$2/10^6>$AF$3,$AF$3,V15*DAY(EOMONTH(DATE($B15,$H$2,1),0))*24*3600/$AF$2/10^6) -> 30.648649 | I15: =IF(W15*DAY(EOMONTH(DATE($B15,$I$2,1),0))*24*3600/$AF$2/10^6>$AF$3,$AF$3,W15*DAY(EOMONTH(DATE($B15,$I$2,1),0))*24*3600/$AF$2/10^6) -> 39.512432 | J15: =IF(X15*DAY(EOMONTH(DATE($B15,$J$2,1),0))*24*3600/$AF$2/10^6>$AF$3,$AF$3,X15*DAY(EOMONTH(DATE($B15,$J$2,1),0))*24*3600/$AF$2/10^6) -> 58.212973 | K15: =IF(Y15*DAY(EOMONTH(DATE($B15,$K$2,1),0))*24*3600/$AF$2/10^6>$AF$3,$AF$3,Y15*DAY(EOMONTH(DATE($B15,$K$2,1),0))*24*3600/$AF$2/10^6) -> 61.07 | L15: =IF(Z15*DAY(EOMONTH(DATE($B15,$L$2,1),0))*24*3600/$AF$2/10^6>$AF$3,$AF$3,Z15*DAY(EOMONTH(DATE($B15,$L$2,1),0))*24*3600/$AF$2/10^6) -> 52.180541 | M15: =IF(AA15*DAY(EOMONTH(DATE($B15,$M$2,1),0))*24*3600/$AF$2/10^6>$AF$3,$AF$3,AA15*DAY(EOMONTH(DATE($B15,$M$2,1),0))*24*3600/$AF$2/10^6) -> 27.408649 | N15: =IF(AB15*DAY(EOMONTH(DATE($B15,$N$2,1),0))*24*3600/$AF$2/10^6>$AF$3,$AF$3,AB15*DAY(EOMONTH(DATE($B15,$N$2,1),0))*24*3600/$AF$2/10^6) -> 16.981297 | O15: =SUM(C15:N15) -> 352.50459 | Q15: 55.3 | R15: 33.6 | S15: 31.4 | T15: 31.2 | U15: 73.2 | V15: 105 | W15: 131 | X15: 193 | Y15: 243 | Z15: 173 | AA15: 93.9 | AB15: 56.3 | AC15: =CORREL($Q$52:$V$52,Q15:V15) -> 0.23818191 | AD15: =SQRT(SUMXMY2($Q$52:$V$52,Q15:V15)) -> 70.991452
... B36: 2010 | C36: =IF(Q36*DAY(EOMONTH(DATE($B36,$C$2,1),0))*24*3600/$AF$2/10^6>$AF$3,$AF$3,Q36*DAY(EOMONTH(DATE($B36,$C$2,1),0))*24*3600/$AF$2/10^6) -> 16.034089 | D36: =IF(R36*DAY(EOMONTH(DATE($B36,$D$2,1),0))*24*3600/$AF$2/10^6>$AF$3,$AF$3,R36*DAY(EOMONTH(DATE($B36,$D$2,1),0))*24*3600/$AF$2/10^6) -> 9.0586411 | E36: =IF(S36*DAY(EOMONTH(DATE($B36,$E$2,1),0))*24*3600/$AF$2/10^6>$AF$3,$AF$3,S36*DAY(EOMONTH(DATE($B36,$E$2,1),0))*24*3600/$AF$2/10^6) -> 7.5094735 | F36: =IF(T36*DAY(EOMONTH(DATE($B36,$F$2,1),0))*24*3600/$AF$2/10^6>$AF$3,$AF$3,T36*DAY(EOMONTH(DATE($B36,$F$2,1),0))*24*3600/$AF$2/10^6) -> 7.7386377 | G36: =IF(U36*DAY(EOMONTH(DATE($B36,$G$2,1),0))*24*3600/$AF$2/10^6>$AF$3,$AF$3,U36*DAY(EOMONTH(DATE($B36,$G$2,1),0))*24*3600/$AF$2/10^6) -> 10.114521 | H36: =IF(V36*DAY(EOMONTH(DATE($B36,$H$2,1),0))*24*3600/$AF$2/10^6>$AF$3,$AF$3,V36*DAY(EOMONTH(DATE($B36,$H$2,1),0))*24*3600/$AF$2/10^6) -> 13.731733 | I36: =IF(W36*DAY(EOMONTH(DATE($B36,$I$2,1),0))*24*3600/$AF$2/10^6>$AF$3,$AF$3,W36*DAY(EOMONTH(DATE($B36,$I$2,1),0))*24*3600/$AF$2/10^6) -> 18.8506 | J36: =IF(X36*DAY(EOMONTH(DATE($B36,$J$2,1),0))*24*3600/$AF$2/10^6>$AF$3,$AF$3,X36*DAY(EOMONTH(DATE($B36,$J$2,1),0))*24*3600/$AF$2/10^6) -> 26.568457 | K36: =IF(Y36*DAY(EOMONTH(DATE($B36,$K$2,1),0))*24*3600/$AF$2/10^6>$AF$3,$AF$3,Y36*DAY(EOMONTH(DATE($B36,$K$2,1),0))*24*3600/$AF$2/10^6) -> 25.086843 | L36: =IF(Z36*DAY(EOMONTH(DATE($B36,$L$2,1),0))*24*3600/$AF$2/10^6>$AF$3,$AF$3,Z36*DAY(EOMONTH(DATE($B36,$L$2,1),0))*24*3600/$AF$2/10^6) -> 34.561051 | M36: =IF(AA36*DAY(EOMONTH(DATE($B36,$M$2,1),0))*24*3600/$AF$2/10^6>$AF$3,$AF$3,AA36*DAY(EOMONTH(DATE($B36,$M$2,1),0))*24*3600/$AF$2/10^6) -> 51.483054 | N36: =IF(AB36*DAY(EOMONTH(DATE($B36,$N$2,1),0))*24*3600/$AF$2/10^6>$AF$3,$AF$3,AB36*DAY(EOMONTH(DATE($B36,$N$2,1),0))*24*3600/$AF$2/10^6) -> 26.371265 | O36: =SUM(C36:N36) -> 247.10836 | Q36: 53.159613 | R36: 33.250964 | S36: 24.897 | T36: 26.512 | U36: 33.533806 | V36: 47.0439 | W36: 62.497509 | X36: 88.085387 | Y36: 85.945667 | Z36: 114.58413 | AA36: 176.37713 | AB36: 87.431613 | AC36: =CORREL($Q$52:$V$52,Q36:V36) -> 0.85846823 | AD36: =SQRT(SUMXMY2($Q$52:$V$52,Q36:V36)) -> 25.819165
B37: 2011 | C37: ='2011'!C3 -> 20.36022 | D37: ='2011'!D3 -> 13.2335 | E37: ='2011'!E3 -> 32.38392 | F37: ='2011'!F3 -> 22.10473 | G37: ='2011'!G3 -> 13.20159 | H37: ='2011'!H3 -> 23.40821 | I37: ='2011'!I3 -> 26.18775 | J37: ='2011'!J3 -> 32.64566 | ... N37: ='2011'!N3 -> 35.03804 | O37: =SUM(C37:N37) -> 341.43642 | Q37: 38.738901 | R37: 27.375714 | S37: 31.266452 | T37: 28.102333 | U37: 44.509282 | V37: 93.037875 | W37: 99.703548 | X37: 132.49587 | Y37: 178.27869 | Z37: 269.91674 | AA37: 114.62364 | AB37: 78.933501 | AC37: =CORREL($Q$52:$V$52,Q37:V37) -> 0.17901992 | AD37: =SQRT(SUMXMY2($Q$52:$V$52,Q37:V37)) -> 58.993029
B38: 2012 | C38: ='2012'!C3 -> 17.5932 | D38: ='2012'!D3 -> 24.94517 | E38: ='2012'!E3 -> 30.77642 | F38: ='2012'!F3 -> 18.33162 | G38: ='2012'!G3 -> 32.24081 | H38: ='2012'!H3 -> 18.23986 | I38: ='2012'!I3 -> 23.38631 | J38: ='2012'!J3 -> 24.5884 | ... N38: ='2012'!N3 -> 26.21386 | O38: =SUM(C38:N38) -> 344.01715 | Q38: 55.972894 | R38: 40.181793 | S38: 32.362718 | T38: 67.798986 | U38: 64.259356 | V38: 69.118346 | W38: 99.439609 | X38: 99.352768 | Y38: 216.54866 | Z38: 230.99618 | AA38: 85.825744 | AB38: 50.229207 | AC38: =CORREL($Q$52:$V$52,Q38:V38) -> -0.10875781 | AD38: =SQRT(SUMXMY2($Q$52:$V$52,Q38:V38)) -> 55.069693
B39: 2013 | C39: ='2013'!C3 -> 14.8712 | D39: ='2013'!D3 -> 12.562 | E39: ='2013'!E3 -> 19.8315 | F39: ='2013'!F3 -> 15.3008 | G39: ='2013'!G3 -> 14.8426 | H39: ='2013'!H3 -> 25.203587 | I39: ='2013'!I3 -> 28.0868 | J39: ='2013'!J3 -> 28.7976 | ... N39: ='2013'!N3 -> 23.6578 | O39: =SUM(C39:N39) -> 292.87429 | Q39: 41.046547 | R39: 28.786989 | S39: 25.524188 | T39: 31.451485 | U39: 50.590148 | V39: 99.378532 | W39: 133.13818 | X39: 128.81654 | Y39: 188.24695 | Z39: 161.7535 | AA39: 97.149583 | AB39: 56.430754 | AC39: =CORREL($Q$52:$V$52,Q39:V39) -> 0.16080644 | AD39: =SQRT(SUMXMY2($Q$52:$V$52,Q39:V39)) -> 64.745831
B40: 2014 | C40: ='2014'!C3 -> 25.793 | D40: ='2014'!D3 -> 25.0957 | E40: ='2014'!E3 -> 29.4891 | F40: ='2014'!F3 -> 14.04501 | G40: ='2014'!G3 -> 10.383187 | H40: ='2014'!H3 -> 19.245 | I40: ='2014'!I3 -> 42.0276 | J40: ='2014'!J3 -> 38.6109 | ... N40: ='2014'!N3 -> 17.038915 | O40: =SUM(C40:N40) -> 321.60531 | Q40: 35.14656 | R40: 27.159066 | S40: 23.631079 | T40: 40.349888 | U40: 51.112524 | V40: 91.451207 | W40: 161.7291 | X40: 192.08525 | Y40: 178.71935 | Z40: 117.00135 | AA40: 66.74421 | AB40: 56.586699 | AC40: =CORREL($Q$52:$V$52,Q40:V40) -> 0.00038336679 | AD40: =SQRT(SUMXMY2($Q$52:$V$52,Q40:V40)) -> 63.765078
B41: 2015 | C41: ='2015'!C3 -> 19.6557 | D41: ='2015'!D3 -> 16.1954 | E41: ='2015'!E3 -> 21.9926 | F41: ='2015'!F3 -> 19.5488 | G41: ='2015'!G3 -> 14.5856 | H41: ='2015'!H3 -> 16.866854 | I41: ='2015'!I3 -> 30.4535 | J41: ='2015'!J3 -> 23.6356 | ... N41: ='2015'!N3 -> 11.5308 | O41: =SUM(C41:N41) -> 197.92865 | Q41: 36.899219 | R41: 27.700378 | S41: 21.834744 | T41: 20.873681 | U41: 32.755231 | V41: 65.172759 | W41: 84.748947 | X41: 100.64194 | Y41: 89.368024 | Z41: 95.338733 | AA41: 65.611737 | AB41: 49.560215 | AC41: =CORREL($Q$52:$V$52,Q41:V41) -> 0.37653427 | AD41: =SQRT(SUMXMY2($Q$52:$V$52,Q41:V41)) -> 45.932626
B42: 2016 | C42: ='2016'!C3 -> 20.582 | D42: ='2016'!D3 -> 14.8163 | E42: ='2016'!E3 -> 17.2857 | F42: ='2016'!F3 -> 16.085 | G42: ='2016'!G3 -> 14.9197 | H42: ='2016'!H3 -> 13.799793 | I42: ='2016'!I3 -> 24.193315 | J42: ='2016'!J3 -> 24.424044 | ... N42: ='2016'!N3 -> 46.91089 | O42: =SUM(C42:N42) -> 294.45187 | Q42: 29.580185 | R42: 16.848667 | S42: 18.407985 | T42: 16.031015 | U42: 33.494147 | V42: 59.30572 | W42: 76.749817 | X42: 99.231311 | Y42: 121.8447 | Z42: 202.08879 | AA42: 187.22087 | AB42: 135.9685 | AC42: =CORREL($Q$52:$V$52,Q42:V42) -> 0.2774778 | AD42: =SQRT(SUMXMY2($Q$52:$V$52,Q42:V42)) -> 56.399292
B43: 2017 | C43: ='2017'!C3 -> 31.364886 | D43: ='2017'!D3 -> 21.60449 | E43: ='2017'!E3 -> 24.754403 | F43: ='2017'!F3 -> 30.05862 | G43: ='2017'!G3 -> 35.61779 | H43: ='2017'!H3 -> 49.377231 | I43: ='2017'!I3 -> 26.841632 | J43: ='2017'!J3 -> 41.756316 | ... N43: ='2017'!N3 -> 41.483337 | O43: =SUM(C43:N43) -> 474.12429 | Q43: 82.21947 | R43: 52.005773 | S43: 36.557854 | T43: 43.784482 | U43: 118.53983 | V43: 102.65489 | W43: 183.00931 | X43: 189.46759 | Y43: 162.03647 | Z43: 187.77008 | AA43: 185.45051 | AB43: 118.30959 | AC43: =CORREL($Q$52:$V$52,Q43:V43) -> 0.25292601 | AD43: =SQRT(SUMXMY2($Q$52:$V$52,Q43:V43)) -> 100.74344
B44: 2018 | C44: ='2018'!C3 -> 29.766293 | D44: ='2018'!D3 -> 25.200817 | E44: ='2018'!E3 -> 30.107096 | F44: ='2018'!F3 -> 24.195173 | G44: ='2018'!G3 -> 15.15389 | H44: ='2018'!H3 -> 20.327558 | I44: ='2018'!I3 -> 30.515135 | J44: ='2018'!J3 -> 39.90778 | ... N44: ='2018'!N3 -> 27.942358 | O44: =SUM(C44:N44) -> 377.92104 | Q44: 60.156741 | R44: 39.041922 | S44: 36.131442 | T44: 29.832383 | U44: 53.66219 | V44: 69.586727 | W44: 144.02002 | X44: 225.96623 | Y44: 218.48003 | Z44: 116.32079 | AA44: 91.773558 | AB44: 84.96806 | AC44: =CORREL($Q$52:$V$52,Q44:V44) -> 0.61707931 | AD44: =SQRT(SUMXMY2($Q$52:$V$52,Q44:V44)) -> 30.176182
B45: 2019 | C45: ='2019'!C3 -> 22.552582 | D45: ='2019'!D3 -> 20.843499 | E45: ='2019'!E3 -> 29.454129 | F45: ='2019'!F3 -> 20.305261 | G45: ='2019'!G3 -> 13.686037 | H45: ='2019'!H3 -> 10.809939 | I45: ='2019'!I3 -> 12.072376 | J45: ='2019'!J3 -> 35.882241 | ... N45: ='2019'!N3 -> 24.291548 | O45: =SUM(C45:N45) -> 309.57582 | Q45: 71.103282 | R45: 33.986028 | S45: 27.042327 | T45: 29.647688 | U45: 32.275658 | V45: 46.812663 | W45: 63.078359 | X45: 151.61793 | Y45: 234.25468 | Z45: 107.68454 | AA45: 167.07582 | AB45: 66.735623 | AC45: =CORREL($Q$52:$V$52,Q45:V45) -> 0.93083595 | AD45: =SQRT(SUMXMY2($Q$52:$V$52,Q45:V45)) -> 17.808261
B46: 2020 | C46: ='2020'!C3 -> 24.566247 | D46: ='2020'!D3 -> 22.680795 | E46: ='2020'!E3 -> 25.492475 | F46: ='2020'!F3 -> 14.732552 | G46: ='2020'!G3 -> 13.924613 | H46: ='2020'!H3 -> 10.573797 | I46: ='2020'!I3 -> 21.065653 | J46: ='2020'!J3 -> 36.942778 | ... N46: ='2020'!N3 -> 43.477065 | O46: =SUM(C46:N46) -> 320.8992 | Q46: 38.335743 | R46: 30.678343 | S46: 21.352688 | T46: 21.049056 | U46: 20.578763 | V46: 56.8435 | W46: 81.693978 | X46: 161.20344 | Y46: 148.64895 | Z46: 207.94839 | AA46: 154.26261 | AB46: 120.95 | AC46: =CORREL($Q$52:$V$52,Q46:V46) -> 0.53441901 | AD46: =SQRT(SUMXMY2($Q$52:$V$52,Q46:V46)) -> 44.392945
