Workbook

Sheet Đầu vào
B2: Dữ kiện gồm có
B3: - Bảng tra lưu lượng ứng với từng nấc tần suất
B4: - Bảng tính sản lượng ứng với tần suất
B5: - Thống kê sản lượng điện qua các năm
B6: - Thủy văn 2024 của đài Tây nguyên và TCT theo dõi thực tế

Sheet TS Ho
A1: BUÔN KUỐP | L1: BUÔN TUA SRAH | U1: SRÊPÔK 3
A2: THÔNG SỐ HỒ CHỨA | D2: DUNG TÍCH HỮU ÍCH (10^6m3) | G2: SUẤT TIÊU HAO NƯỚC | J2: 3.9893291 | L2: THÔNG SỐ HỒ CHỨA | O2: DUNG TÍCH HỮU ÍCH (10^6m3) | R2: SUẤT TIÊU HAO NƯỚC | S2: =AVERAGE(S4:S2253) -> 8.8786378 | U2: THÔNG SỐ HỒ CHỨA | X2: DUNG TÍCH HỮU ÍCH (10^6m3) | AA2: SUẤT TIÊU HAO NƯỚC | AD2: 6.6505614
A3: MNH (m) | B3: DUNG TICH (10^6m3) | C3: DiỆN TÍCH (Km2) | D3: MNH (m) | E3: DUNG TICH HỮU ÍCH (10^6m3) | F3: MNH (m) | G3: MNH (m) | H3: Dung tích chạy máy (10^6m3) | I3: Sản lượng ngày (MWh) | J3: Suất hao nước (m3/kwh) | L3: MNH (m) | M3: DUNG TICH (10^6m3) | N3: DiỆN TÍCH (Km2) | O3: MNH (m) | P3: DUNG TICH HỮU ÍCH (10^6m3) | Q3: MNH (m) | R3: MNH (m) | S3: Suất hao nước (m3/kwh) | U3: MNH (m) | V3: DUNG TICH (10^6m3) | W3: DiỆN TÍCH (Km2) | X3: MNH (m) | Y3: DUNG TICH HỮU ÍCH (10^6m3) | Z3: MNH (m) | AA3: MNH (m) | AB3: Dung tích chạy máy (10^6m3) | AC3: Sản lượng ngày (MWh) | AD3: Suất hao nước (m3/kwh)
A4: 408 | B4: 45 | C4: 4.2 | D4: 408 | E4: =VLOOKUP(D4,THONGSOHO_BK,2,1)+(VLOOKUP(D4+1,THONGSOHO_BK,2,1)-VLOOKUP(D4,THONGSOHO_BK,2,1))/1*(D4-VLOOKUP(D4,THONGSOHO_BK,1,1))-48.55 -> #NAME? | F4: 408 | G4: 410 | H4: 7.5150643 | I4: 1885.5 | J4: =H4/I4*10^3 -> 3.9857143 | L4: 427 | M4: 0 | N4: 0 | O4: 464.5 | P4: =VLOOKUP(O4,THONGSOHO_BTS,2,1)+(VLOOKUP(O4+5,THONGSOHO_BTS,2,1)-VLOOKUP(O4,THONGSOHO_BTS,2,1))/5*(O4-VLOOKUP(O4,THONGSOHO_BTS,1,1))-264.29 -> #NAME? | Q4: 464.5 | R4: 465.01 | S4: 11.3792 | U4: 256 | V4: 43.851 | W4: 5.629 | X4: 267 | Y4: =VLOOKUP(X4,THONGSOHO_SP3,2,1)+(VLOOKUP(X4+2,THONGSOHO_SP3,2,1)-VLOOKUP(X4,THONGSOHO_SP3,2,1))/2*(X4-VLOOKUP(X4,THONGSOHO_SP3,1,1))-156.13 -> #NAME? | Z4: 267 | AA4: 271.01 | AB4: 8.4889 | AC4: 1273.1 | AD4: =AB4/AC4*10^3 -> 6.6678973
A5: 409 | B5: 48.55 | C5: 4.51 | D5: 408.01 | E5: =VLOOKUP(D5,THONGSOHO_BK,2,1)+(VLOOKUP(D5+1,THONGSOHO_BK,2,1)-VLOOKUP(D5,THONGSOHO_BK,2,1))/1*(D5-VLOOKUP(D5,THONGSOHO_BK,1,1))-48.55 -> #NAME? | F5: 408.01 | G5: 409.52 | H5: 6.4010571 | I5: 1606 | J5: =H5/I5*10^3 -> 3.9857143 | L5: 430 | M5: 0.77 | N5: 0.77 | O5: 464.51 | P5: =VLOOKUP(O5,THONGSOHO_BTS,2,1)+(VLOOKUP(O5+5,THONGSOHO_BTS,2,1)-VLOOKUP(O5,THONGSOHO_BTS,2,1))/5*(O5-VLOOKUP(O5,THONGSOHO_BTS,1,1))-264.29 -> #NAME? | Q5: 464.51 | R5: 465.02 | S5: 11.3784 | U5: 258 | V5: 56.118 | W5: 6.652 | X5: 267.01 | Y5: =VLOOKUP(X5,THONGSOHO_SP3,2,1)+(VLOOKUP(X5+2,THONGSOHO_SP3,2,1)-VLOOKUP(X5,THONGSOHO_SP3,2,1))/2*(X5-VLOOKUP(X5,THONGSOHO_SP3,1,1))-156.13 -> #NAME? | Z5: 267.01 | AA5: 270.961 | AB5: 11.7974 | AC5: 1726.8 | AD5: =AB5/AC5*10^3 -> 6.8319435
A6: 410 | B6: 53.15 | C6: 4.71 | D6: 408.02 | E6: =VLOOKUP(D6,THONGSOHO_BK,2,1)+(VLOOKUP(D6+1,THONGSOHO_BK,2,1)-VLOOKUP(D6,THONGSOHO_BK,2,1))/1*(D6-VLOOKUP(D6,THONGSOHO_BK,1,1))-48.55 -> #NAME? | F6: 408.02 | G6: 409.46 | H6: 4.4954871 | I6: 1127.9 | J6: =H6/I6*10^3 -> 3.9857143 | L6: 435 | M6: 7.13 | N6: 1.85 | O6: 464.52 | P6: =VLOOKUP(O6,THONGSOHO_BTS,2,1)+(VLOOKUP(O6+5,THONGSOHO_BTS,2,1)-VLOOKUP(O6,THONGSOHO_BTS,2,1))/5*(O6-VLOOKUP(O6,THONGSOHO_BTS,1,1))-264.29 -> #NAME? | Q6: 464.52 | R6: 465.03 | S6: 11.3776 | U6: 260 | V6: 70.678 | W6: 7.927 | X6: 267.02 | Y6: =VLOOKUP(X6,THONGSOHO_SP3,2,1)+(VLOOKUP(X6+2,THONGSOHO_SP3,2,1)-VLOOKUP(X6,THONGSOHO_SP3,2,1))/2*(X6-VLOOKUP(X6,THONGSOHO_SP3,1,1))-156.13 -> #NAME? | Z6: 267.02 | AA6: 270.592 | AB6: 13.8096 | AC6: 2076 | AD6: =AB6/AC6*10^3 -> 6.6520231
A7: 411 | B7: 57.98 | C7: 4.95 | D7: 408.03 | E7: =VLOOKUP(D7,THONGSOHO_BK,2,1)+(VLOOKUP(D7+1,THONGSOHO_BK,2,1)-VLOOKUP(D7,THONGSOHO_BK,2,1))/1*(D7-VLOOKUP(D7,THONGSOHO_BK,1,1))-48.55 -> #NAME? | F7: 408.03 | G7: 409.78 | H7: 4.19616 | I7: 1052.8 | J7: =H7/I7*10^3 -> 3.9857143 | L7: 440 | M7: 21.75 | N7: 4.15 | O7: 464.53 | P7: =VLOOKUP(O7,THONGSOHO_BTS,2,1)+(VLOOKUP(O7+5,THONGSOHO_BTS,2,1)-VLOOKUP(O7,THONGSOHO_BTS,2,1))/5*(O7-VLOOKUP(O7,THONGSOHO_BTS,1,1))-264.29 -> #NAME? | Q7: 464.53 | R7: 465.04 | S7: 11.3768 | U7: 262 | V7: 87.896 | W7: 9.309 | X7: 267.03 | Y7: =VLOOKUP(X7,THONGSOHO_SP3,2,1)+(VLOOKUP(X7+2,THONGSOHO_SP3,2,1)-VLOOKUP(X7,THONGSOHO_SP3,2,1))/2*(X7-VLOOKUP(X7,THONGSOHO_SP3,1,1))-156.13 -> #NAME? | Z7: 267.03 | AA7: 270.15 | AB7: 13.5379 | AC7: 1986.3 | AD7: =AB7/AC7*10^3 -> 6.8156371
A8: 412 | B8: 63.24 | C8: 5.57 | D8: 408.04 | E8: =VLOOKUP(D8,THONGSOHO_BK,2,1)+(VLOOKUP(D8+1,THONGSOHO_BK,2,1)-VLOOKUP(D8,THONGSOHO_BK,2,1))/1*(D8-VLOOKUP(D8,THONGSOHO_BK,1,1))-48.55 -> #NAME? | F8: 408.04 | G8: 409.48 | H8: 5.9163943 | I8: 1484.4 | J8: =H8/I8*10^3 -> 3.9857143 | L8: 445 | M8: 49.47 | N8: 7.07 | O8: 464.54 | P8: =VLOOKUP(O8,THONGSOHO_BTS,2,1)+(VLOOKUP(O8+5,THONGSOHO_BTS,2,1)-VLOOKUP(O8,THONGSOHO_BTS,2,1))/5*(O8-VLOOKUP(O8,THONGSOHO_BTS,1,1))-264.29 -> #NAME? | Q8: 464.54 | R8: 465.05 | S8: 11.376 | U8: 264 | V8: 107.91 | W8: 10.723 | X8: 267.04 | Y8: =VLOOKUP(X8,THONGSOHO_SP3,2,1)+(VLOOKUP(X8+2,THONGSOHO_SP3,2,1)-VLOOKUP(X8,THONGSOHO_SP3,2,1))/2*(X8-VLOOKUP(X8,THONGSOHO_SP3,1,1))-156.13 -> #NAME? | Z8: 267.04 | AA8: 270.14 | AB8: 6.2752 | AC8: 949.1 | AD8: =AB8/AC8*10^3 -> 6.6117374
A9: 413 | B9: 69.43 | C9: 6.82 | D9: 408.05 | E9: =VLOOKUP(D9,THONGSOHO_BK,2,1)+(VLOOKUP(D9+1,THONGSOHO_BK,2,1)-VLOOKUP(D9,THONGSOHO_BK,2,1))/1*(D9-VLOOKUP(D9,THONGSOHO_BK,1,1))-48.55 -> #NAME? | F9: 408.05 | G9: 409.57 | H9: 3.7178743 | I9: 932.8 | J9: =H9/I9*10^3 -> 3.9857143 | L9: 450 | M9: 89.3 | N9: 8.89 | O9: 464.55 | P9: =VLOOKUP(O9,THONGSOHO_BTS,2,1)+(VLOOKUP(O9+5,THONGSOHO_BTS,2,1)-VLOOKUP(O9,THONGSOHO_BTS,2,1))/5*(O9-VLOOKUP(O9,THONGSOHO_BTS,1,1))-264.29 -> #NAME? | Q9: 464.55 | R9: 465.06 | S9: 11.3752 | U9: 266 | V9: 130.53 | W9: 11.907 | X9: 267.05 | Y9: =VLOOKUP(X9,THONGSOHO_SP3,2,1)+(VLOOKUP(X9+2,THONGSOHO_SP3,2,1)-VLOOKUP(X9,THONGSOHO_SP3,2,1))/2*(X9-VLOOKUP(X9,THONGSOHO_SP3,1,1))-156.13 -> #NAME? | Z9: 267.05 | AA9: 270.115 | AB9: 9.3726 | AC9: 1405 | AD9: =AB9/AC9*10^3 -> 6.6708897
A10: 414 | B10: 78.49 | C10: 11.52 | D10: 408.06 | E10: =VLOOKUP(D10,THONGSOHO_BK,2,1)+(VLOOKUP(D10+1,THONGSOHO_BK,2,1)-VLOOKUP(D10,THONGSOHO_BK,2,1))/1*(D10-VLOOKUP(D10,THONGSOHO_BK,1,1))-48.55 -> #NAME? | F10: 408.06 | G10: 410.69 | H10: 0.58829143 | I10: 147.6 | J10: =H10/I10*10^3 -> 3.9857143 | L10: 455 | M10: 138.23 | N10: 10.71 | O10: 464.56 | P10: =VLOOKUP(O10,THONGSOHO_BTS,2,1)+(VLOOKUP(O10+5,THONGSOHO_BTS,2,1)-VLOOKUP(O10,THONGSOHO_BTS,2,1))/5*(O10-VLOOKUP(O10,THONGSOHO_BTS,1,1))-264.29 -> #NAME? | Q10: 464.56 | R10: 465.07 | S10: 11.3744 | U10: 268 | V10: 156.13 | W10: 13.716 | X10: 267.06 | Y10: =VLOOKUP(X10,THONGSOHO_SP3,2,1)+(VLOOKUP(X10+2,THONGSOHO_SP3,2,1)-VLOOKUP(X10,THONGSOHO_SP3,2,1))/2*(X10-VLOOKUP(X10,THONGSOHO_SP3,1,1))-156.13 -> #NAME? | Z10: 267.06 | AA10: 270.254 | AB10: 2.6945 | AC10: 407.7 | AD10: =AB10/AC10*10^3 -> 6.6090262
A11: 415 | B11: 95.71 | C11: 23.63 | D11: 408.07 | E11: =VLOOKUP(D11,THONGSOHO_BK,2,1)+(VLOOKUP(D11+1,THONGSOHO_BK,2,1)-VLOOKUP(D11,THONGSOHO_BK,2,1))/1*(D11-VLOOKUP(D11,THONGSOHO_BK,1,1))-48.55 -> #NAME? | F11: 408.07 | G11: 410.91 | H11: 2.6070557 | I11: 654.1 | J11: =H11/I11*10^3 -> 3.9857143 | L11: 460 | M11: 196.24 | N11: 12.52 | O11: 464.57 | P11: =VLOOKUP(O11,THONGSOHO_BTS,2,1)+(VLOOKUP(O11+5,THONGSOHO_BTS,2,1)-VLOOKUP(O11,THONGSOHO_BTS,2,1))/5*(O11-VLOOKUP(O11,THONGSOHO_BTS,1,1))-264.29 -> #NAME? | Q11: 464.57 | R11: 465.08 | S11: 11.3736 | U11: 270 | V11: 185.58 | W11: 15.751 | X11: 267.07 | Y11: =VLOOKUP(X11,THONGSOHO_SP3,2,1)+(VLOOKUP(X11+2,THONGSOHO_SP3,2,1)-VLOOKUP(X11,THONGSOHO_SP3,2,1))/2*(X11-VLOOKUP(X11,THONGSOHO_SP3,1,1))-156.13 -> #NAME? | Z11: 267.07 | AA11: 270.39 | AB11: 1.1 | AC11: 157.7 | AD11: =AB11/AC11*10^3 -> 6.9752695
D12: 408.08 | E12: =VLOOKUP(D12,THONGSOHO_BK,2,1)+(VLOOKUP(D12+1,THONGSOHO_BK,2,1)-VLOOKUP(D12,THONGSOHO_BK,2,1))/1*(D12-VLOOKUP(D12,THONGSOHO_BK,1,1))-48.55 -> #NAME? | F12: 408.08 | G12: 411.26 | H12: 2.8115229 | I12: 705.4 | J12: =H12/I12*10^3 -> 3.9857143 | L12: 465 | M12: 264.29 | N12: 14.73 | O12: 464.58 | P12: =VLOOKUP(O12,THONGSOHO_BTS,2,1)+(VLOOKUP(O12+5,THONGSOHO_BTS,2,1)-VLOOKUP(O12,THONGSOHO_BTS,2,1))/5*(O12-VLOOKUP(O12,THONGSOHO_BTS,1,1))-264.29 -> #NAME? | Q12: 464.58 | R12: 465.09 | S12: 11.3728 | U12: 272 | V12: 218.99 | W12: 17.676 | X12: 267.08 | Y12: =VLOOKUP(X12,THONGSOHO_SP3,2,1)+(VLOOKUP(X12+2,THONGSOHO_SP3,2,1)-VLOOKUP(X12,THONGSOHO_SP3,2,1))/2*(X12-VLOOKUP(X12,THONGSOHO_SP3,1,1))-156.13 -> #NAME? | Z12: 267.08 | AA12: 270.522 | AB12: 1.9667 | AC12: 294.6 | AD12: =AB12/AC12*10^3 -> 6.6758316
D13: 408.09 | E13: =VLOOKUP(D13,THONGSOHO_BK,2,1)+(VLOOKUP(D13+1,THONGSOHO_BK,2,1)-VLOOKUP(D13,THONGSOHO_BK,2,1))/1*(D13-VLOOKUP(D13,THONGSOHO_BK,1,1))-48.55 -> #NAME? | F13: 408.09 | G13: 411.35 | H13: 3.8031686 | I13: 954.2 | J13: =H13/I13*10^3 -> 3.9857143 | L13: 470 | M13: 344.25 | N13: 17.29 | O13: 464.59 | P13: =VLOOKUP(O13,THONGSOHO_BTS,2,1)+(VLOOKUP(O13+5,THONGSOHO_BTS,2,1)-VLOOKUP(O13,THONGSOHO_BTS,2,1))/5*(O13-VLOOKUP(O13,THONGSOHO_BTS,1,1))-264.29 -> #NAME? | Q13: 464.59 | R13: 465.1 | S13: 11.372 | U13: 274 | V13: 256.19 | W13: 19.54 | X13: 267.09 | Y13: =VLOOKUP(X13,THONGSOHO_SP3,2,1)+(VLOOKUP(X13+2,THONGSOHO_SP3,2,1)-VLOOKUP(X13,THONGSOHO_SP3,2,1))/2*(X13-VLOOKUP(X13,THONGSOHO_SP3,1,1))-156.13 -> #NAME? | Z13: 267.09 | AA13: 270.559 | AB13: 4.4147 | AC13: 630.8 | AD13: =AB13/AC13*10^3 -> 6.9985732
D14: 408.1 | E14: =VLOOKUP(D14,THONGSOHO_BK,2,1)+(VLOOKUP(D14+1,THONGSOHO_BK,2,1)-VLOOKUP(D14,THONGSOHO_BK,2,1))/1*(D14-VLOOKUP(D14,THONGSOHO_BK,1,1))-48.55 -> #NAME? | F14: 408.1 | G14: 411.47 | H14: 3.1084586 | I14: 779.9 | J14: =H14/I14*10^3 -> 3.9857143 | L14: 475 | M14: 437.34 | N14: 19.97 | O14: 464.6 | P14: =VLOOKUP(O14,THONGSOHO_BTS,2,1)+(VLOOKUP(O14+5,THONGSOHO_BTS,2,1)-VLOOKUP(O14,THONGSOHO_BTS,2,1))/5*(O14-VLOOKUP(O14,THONGSOHO_BTS,1,1))-264.29 -> #NAME? | Q14: 464.6 | R14: 465.11 | S14: 11.3712 | U14: 276 | V14: 297.3 | W14: 21.596 | X14: 267.1 | Y14: =VLOOKUP(X14,THONGSOHO_SP3,2,1)+(VLOOKUP(X14+2,THONGSOHO_SP3,2,1)-VLOOKUP(X14,THONGSOHO_SP3,2,1))/2*(X14-VLOOKUP(X14,THONGSOHO_SP3,1,1))-156.13 -> #NAME? | Z14: 267.1 | AA14: 270.699 | AB14: 3.3619 | AC14: 657.8 | AD14: =AB14/AC14*10^3 -> 5.110824
D15: 408.11 | E15: =VLOOKUP(D15,THONGSOHO_BK,2,1)+(VLOOKUP(D15+1,THONGSOHO_BK,2,1)-VLOOKUP(D15,THONGSOHO_BK,2,1))/1*(D15-VLOOKUP(D15,THONGSOHO_BK,1,1))-48.55 -> #NAME? | F15: 408.11 | G15: 411.42 | H15: 3.7294329 | I15: 935.7 | J15: =H15/I15*10^3 -> 3.9857143 | L15: 480 | M15: 550.11 | N15: 25.24 | O15: 464.61 | P15: =VLOOKUP(O15,THONGSOHO_BTS,2,1)+(VLOOKUP(O15+5,THONGSOHO_BTS,2,1)-VLOOKUP(O15,THONGSOHO_BTS,2,1))/5*(O15-VLOOKUP(O15,THONGSOHO_BTS,1,1))-264.29 -> #NAME? | Q15: 464.61 | R15: 465.12 | S15: 11.3704 | U15: 278 | V15: 342.66 | W15: 23.775 | X15: 267.11 | Y15: =VLOOKUP(X15,THONGSOHO_SP3,2,1)+(VLOOKUP(X15+2,THONGSOHO_SP3,2,1)-VLOOKUP(X15,THONGSOHO_SP3,2,1))/2*(X15-VLOOKUP(X15,THONGSOHO_SP3,1,1))-156.13 -> #NAME? | Z15: 267.11 | AA15: 270.808 | AB15: 3.9559 | AC15: 588.5 | AD15: =AB15/AC15*10^3 -> 6.7220051
D16: 408.12 | E16: =VLOOKUP(D16,THONGSOHO_BK,2,1)+(VLOOKUP(D16+1,THONGSOHO_BK,2,1)-VLOOKUP(D16,THONGSOHO_BK,2,1))/1*(D16-VLOOKUP(D16,THONGSOHO_BK,1,1))-48.55 -> #NAME? | F16: 408.12 | G16: 411.38 | H16: 3.3515871 | I16: 840.9 | J16: =H16/I16*10^3 -> 3.9857143 | L16: 485 | M16: 694.31 | N16: 32.59 | O16: 464.62 | P16: =VLOOKUP(O16,THONGSOHO_BTS,2,1)+(VLOOKUP(O16+5,THONGSOHO_BTS,2,1)-VLOOKUP(O16,THONGSOHO_BTS,2,1))/5*(O16-VLOOKUP(O16,THONGSOHO_BTS,1,1))-264.29 -> #NAME? | Q16: 464.62 | R16: 465.13 | S16: 11.3696 | U16: 280 | V16: 392.64 | W16: 26.229 | X16: 267.12 | Y16: =VLOOKUP(X16,THONGSOHO_SP3,2,1)+(VLOOKUP(X16+2,THONGSOHO_SP3,2,1)-VLOOKUP(X16,THONGSOHO_SP3,2,1))/2*(X16-VLOOKUP(X16,THONGSOHO_SP3,1,1))-156.13 -> #NAME? | Z16: 267.12 | AA16: 270.899 | AB16: 4.153408 | AC16: 587.7 | AD16: =AB16/AC16*10^3 -> 7.0672248
D17: 408.13 | E17: =VLOOKUP(D17,THONGSOHO_BK,2,1)+(VLOOKUP(D17+1,THONGSOHO_BK,2,1)-VLOOKUP(D17,THONGSOHO_BK,2,1))/1*(D17-VLOOKUP(D17,THONGSOHO_BK,1,1))-48.55 -> #NAME? | F17: 408.13 | G17: 411.68 | H17: 2.67003 | I17: 669.9 | J17: =H17/I17*10^3 -> 3.9857143 | L17: 490 | M17: 879.43 | N17: 41.64 | O17: 464.63 | P17: =VLOOKUP(O17,THONGSOHO_BTS,2,1)+(VLOOKUP(O17+5,THONGSOHO_BTS,2,1)-VLOOKUP(O17,THONGSOHO_BTS,2,1))/5*(O17-VLOOKUP(O17,THONGSOHO_BTS,1,1))-264.29 -> #NAME? | Q17: 464.63 | R17: 465.14 | S17: 11.3688 | X17: 267.13 | Y17: =VLOOKUP(X17,THONGSOHO_SP3,2,1)+(VLOOKUP(X17+2,THONGSOHO_SP3,2,1)-VLOOKUP(X17,THONGSOHO_SP3,2,1))/2*(X17-VLOOKUP(X17,THONGSOHO_SP3,1,1))-156.13 -> #NAME? | Z17: 267.13 | AA17: 270.938 | AB17: 5.2407 | AC17: 778.9 | AD17: =AB17/AC17*10^3 -> 6.7283348
D18: 408.14 | E18: =VLOOKUP(D18,THONGSOHO_BK,2,1)+(VLOOKUP(D18+1,THONGSOHO_BK,2,1)-VLOOKUP(D18,THONGSOHO_BK,2,1))/1*(D18-VLOOKUP(D18,THONGSOHO_BK,1,1))-48.55 -> #NAME? | F18: 408.14 | G18: 411.7 | H18: 3.8119371 | I18: 956.4 | J18: =H18/I18*10^3 -> 3.9857143 | L18: 495 | M18: 1114.15 | N18: 52.46 | O18: 464.64 | P18: =VLOOKUP(O18,THONGSOHO_BTS,2,1)+(VLOOKUP(O18+5,THONGSOHO_BTS,2,1)-VLOOKUP(O18,THONGSOHO_BTS,2,1))/5*(O18-VLOOKUP(O18,THONGSOHO_BTS,1,1))-264.29 -> #NAME? | Q18: 464.64 | R18: 465.15 | S18: 11.368 | X18: 267.14 | Y18: =VLOOKUP(X18,THONGSOHO_SP3,2,1)+(VLOOKUP(X18+2,THONGSOHO_SP3,2,1)-VLOOKUP(X18,THONGSOHO_SP3,2,1))/2*(X18-VLOOKUP(X18,THONGSOHO_SP3,1,1))-156.13 -> #NAME? | Z18: 267.14 | AA18: 270.938 | AB18: 5.2407 | AC18: 778.9 | AD18: =AB18/AC18*10^3 -> 6.7283348
D19: 408.15 | E19: =VLOOKUP(D19,THONGSOHO_BK,2,1)+(VLOOKUP(D19+1,THONGSOHO_BK,2,1)-VLOOKUP(D19,THONGSOHO_BK,2,1))/1*(D19-VLOOKUP(D19,THONGSOHO_BK,1,1))-48.55 -> #NAME? | F19: 408.15 | G19: 411.5 | H19: 3.6636686 | I19: 919.2 | J19: =H19/I19*10^3 -> 3.9857143 | L19: 500 | M19: 1406.4 | N19: 64.65 | O19: 464.65 | P19: =VLOOKUP(O19,THONGSOHO_BTS,2,1)+(VLOOKUP(O19+5,THONGSOHO_BTS,2,1)-VLOOKUP(O19,THONGSOHO_BTS,2,1))/5*(O19-VLOOKUP(O19,THONGSOHO_BTS,1,1))-264.29 -> #NAME? | Q19: 464.65 | R19: 465.16 | S19: 11.3672 | X19: 267.15 | Y19: =VLOOKUP(X19,THONGSOHO_SP3,2,1)+(VLOOKUP(X19+2,THONGSOHO_SP3,2,1)-VLOOKUP(X19,THONGSOHO_SP3,2,1))/2*(X19-VLOOKUP(X19,THONGSOHO_SP3,1,1))-156.13 -> #NAME? | Z19: 267.15 | AA19: 271.332 | AB19: 4.19 | AC19: 649 | AD19: =AB19/AC19*10^3 -> 6.4560863
D20: 408.16 | E20: =VLOOKUP(D20,THONGSOHO_BK,2,1)+(VLOOKUP(D20+1,THONGSOHO_BK,2,1)-VLOOKUP(D20,THONGSOHO_BK,2,1))/1*(D20-VLOOKUP(D20,THONGSOHO_BK,1,1))-48.55 -> #NAME? | F20: 408.16 | G20: 411.58 | H20: 3.7688914 | I20: 945.6 | J20: =H20/I20*10^3 -> 3.9857143 | O20: 464.66 | P20: =VLOOKUP(O20,THONGSOHO_BTS,2,1)+(VLOOKUP(O20+5,THONGSOHO_BTS,2,1)-VLOOKUP(O20,THONGSOHO_BTS,2,1))/5*(O20-VLOOKUP(O20,THONGSOHO_BTS,1,1))-264.29 -> #NAME? | Q20: 464.66 | R20: 465.17 | S20: 11.3664 | X20: 267.16 | Y20: =VLOOKUP(X20,THONGSOHO_SP3,2,1)+(VLOOKUP(X20+2,THONGSOHO_SP3,2,1)-VLOOKUP(X20,THONGSOHO_SP3,2,1))/2*(X20-VLOOKUP(X20,THONGSOHO_SP3,1,1))-156.13 -> #NAME? | Z20: 267.16 | AA20: 271.1128 | AB20: 7.8856 | AC20: 1185.7 | AD20: =AB20/AC20*10^3 -> 6.6505862
D21: 408.17 | E21: =VLOOKUP(D21,THONGSOHO_BK,2,1)+(VLOOKUP(D21+1,THONGSOHO_BK,2,1)-VLOOKUP(D21,THONGSOHO_BK,2,1))/1*(D21-VLOOKUP(D21,THONGSOHO_BK,1,1))-48.55 -> #NAME? | F21: 408.17 | G21: 411.5 | H21: 4.2053271 | I21: 1055.1 | J21: =H21/I21*10^3 -> 3.9857143 | O21: 464.67 | P21: =VLOOKUP(O21,THONGSOHO_BTS,2,1)+(VLOOKUP(O21+5,THONGSOHO_BTS,2,1)-VLOOKUP(O21,THONGSOHO_BTS,2,1))/5*(O21-VLOOKUP(O21,THONGSOHO_BTS,1,1))-264.29 -> #NAME? | Q21: 464.67 | R21: 465.18 | S21: 11.3656 | X21: 267.17 | Y21: =VLOOKUP(X21,THONGSOHO_SP3,2,1)+(VLOOKUP(X21+2,THONGSOHO_SP3,2,1)-VLOOKUP(X21,THONGSOHO_SP3,2,1))/2*(X21-VLOOKUP(X21,THONGSOHO_SP3,1,1))-156.13 -> #NAME? | Z21: 267.17 | AA21: 271.197 | AB21: 6.3777 | AC21: 954.8 | AD21: =AB21/AC21*10^3 -> 6.6796188
D22: 408.18 | E22: =VLOOKUP(D22,THONGSOHO_BK,2,1)+(VLOOKUP(D22+1,THONGSOHO_BK,2,1)-VLOOKUP(D22,THONGSOHO_BK,2,1))/1*(D22-VLOOKUP(D22,THONGSOHO_BK,1,1))-48.55 -> #NAME? | F22: 408.18 | G22: 411.94 | H22: 1.7373729 | I22: 435.9 | J22: =H22/I22*10^3 -> 3.9857143 | O22: 464.68 | P22: =VLOOKUP(O22,THONGSOHO_BTS,2,1)+(VLOOKUP(O22+5,THONGSOHO_BTS,2,1)-VLOOKUP(O22,THONGSOHO_BTS,2,1))/5*(O22-VLOOKUP(O22,THONGSOHO_BTS,1,1))-264.29 -> #NAME? | Q22: 464.68 | R22: 465.19 | S22: 11.3648 | X22: 267.18 | Y22: =VLOOKUP(X22,THONGSOHO_SP3,2,1)+(VLOOKUP(X22+2,THONGSOHO_SP3,2,1)-VLOOKUP(X22,THONGSOHO_SP3,2,1))/2*(X22-VLOOKUP(X22,THONGSOHO_SP3,1,1))-156.13 -> #NAME? | Z22: 267.18 | AA22: 271.162 | AB22: 4.8698 | AC22: 727.6 | AD22: =AB22/AC22*10^3 -> 6.6929632
D23: 408.19 | E23: =VLOOKUP(D23,THONGSOHO_BK,2,1)+(VLOOKUP(D23+1,THONGSOHO_BK,2,1)-VLOOKUP(D23,THONGSOHO_BK,2,1))/1*(D23-VLOOKUP(D23,THONGSOHO_BK,1,1))-48.55 -> #NAME? | F23: 408.19 | G23: 410.88 | H23: 9.72315 | I23: 2439.5 | J23: =H23/I23*10^3 -> 3.9857143 | O23: 464.69 | P23: =VLOOKUP(O23,THONGSOHO_BTS,2,1)+(VLOOKUP(O23+5,THONGSOHO_BTS,2,1)-VLOOKUP(O23,THONGSOHO_BTS,2,1))/5*(O23-VLOOKUP(O23,THONGSOHO_BTS,1,1))-264.29 -> #NAME? | Q23: 464.69 | R23: 465.2 | S23: 11.364 | X23: 267.19 | Y23: =VLOOKUP(X23,THONGSOHO_SP3,2,1)+(VLOOKUP(X23+2,THONGSOHO_SP3,2,1)-VLOOKUP(X23,THONGSOHO_SP3,2,1))/2*(X23-VLOOKUP(X23,THONGSOHO_SP3,1,1))-156.13 -> #NAME? | Z23: 267.19 | AA23: 271.098 | AB23: 5.3148 | AC23: 785.7 | AD23: =AB23/AC23*10^3 -> 6.7644139
D24: 408.2 | E24: =VLOOKUP(D24,THONGSOHO_BK,2,1)+(VLOOKUP(D24+1,THONGSOHO_BK,2,1)-VLOOKUP(D24,THONGSOHO_BK,2,1))/1*(D24-VLOOKUP(D24,THONGSOHO_BK,1,1))-48.55 -> #NAME? | F24: 408.2 | G24: 411.33 | H24: 2.0936957 | I24: 525.3 | J24: =H24/I24*10^3 -> 3.9857143 | O24: 464.7 | P24: =VLOOKUP(O24,THONGSOHO_BTS,2,1)+(VLOOKUP(O24+5,THONGSOHO_BTS,2,1)-VLOOKUP(O24,THONGSOHO_BTS,2,1))/5*(O24-VLOOKUP(O24,THONGSOHO_BTS,1,1))-264.29 -> #NAME? | Q24: 464.7 | R24: 465.21 | S24: 11.3632 | X24: 267.2 | Y24: =VLOOKUP(X24,THONGSOHO_SP3,2,1)+(VLOOKUP(X24+2,THONGSOHO_SP3,2,1)-VLOOKUP(X24,THONGSOHO_SP3,2,1))/2*(X24-VLOOKUP(X24,THONGSOHO_SP3,1,1))-156.13 -> #NAME? | Z24: 267.2 | AA24: 271.196 | AB24: 9.5667 | AC24: 1424.7 | AD24: =AB24/AC24*10^3 -> 6.7148873
D25: 408.21 | E25: =VLOOKUP(D25,THONGSOHO_BK,2,1)+(VLOOKUP(D25+1,THONGSOHO_BK,2,1)-VLOOKUP(D25,THONGSOHO_BK,2,1))/1*(D25-VLOOKUP(D25,THONGSOHO_BK,1,1))-48.55 -> #NAME? | F25: 408.21 | G25: 411.57 | H25: 3.6509143 | I25: 916 | J25: =H25/I25*10^3 -> 3.9857143 | O25: 464.71 | P25: =VLOOKUP(O25,THONGSOHO_BTS,2,1)+(VLOOKUP(O25+5,THONGSOHO_BTS,2,1)-VLOOKUP(O25,THONGSOHO_BTS,2,1))/5*(O25-VLOOKUP(O25,THONGSOHO_BTS,1,1))-264.29 -> #NAME? | Q25: 464.71 | R25: 465.22 | S25: 11.3624 | X25: 267.21 | Y25: =VLOOKUP(X25,THONGSOHO_SP3,2,1)+(VLOOKUP(X25+2,THONGSOHO_SP3,2,1)-VLOOKUP(X25,THONGSOHO_SP3,2,1))/2*(X25-VLOOKUP(X25,THONGSOHO_SP3,1,1))-156.13 -> #NAME? | Z25: 267.21 | AA25: 270.702 | AB25: 13.8077 | AC25: 2066.4 | AD25: =AB25/AC25*10^3 -> 6.6820074
D26: 408.22 | E26: =VLOOKUP(D26,THONGSOHO_BK,2,1)+(VLOOKUP(D26+1,THONGSOHO_BK,2,1)-VLOOKUP(D26,THONGSOHO_BK,2,1))/1*(D26-VLOOKUP(D26,THONGSOHO_BK,1,1))-48.55 -> #NAME? | F26: 408.22 | G26: 411.73 | H26: 3.1048714 | I26: 779 | J26: =H26/I26*10^3 -> 3.9857143 | O26: 464.72 | P26: =VLOOKUP(O26,THONGSOHO_BTS,2,1)+(VLOOKUP(O26+5,THONGSOHO_BTS,2,1)-VLOOKUP(O26,THONGSOHO_BTS,2,1))/5*(O26-VLOOKUP(O26,THONGSOHO_BTS,1,1))-264.29 -> #NAME? | Q26: 464.72 | R26: 465.23 | S26: 11.3616 | X26: 267.22 | Y26: =VLOOKUP(X26,THONGSOHO_SP3,2,1)+(VLOOKUP(X26+2,THONGSOHO_SP3,2,1)-VLOOKUP(X26,THONGSOHO_SP3,2,1))/2*(X26-VLOOKUP(X26,THONGSOHO_SP3,1,1))-156.13 -> #NAME? | Z26: 267.22 | AA26: 270.791 | AB26: 3.9923 | AC26: 594 | AD26: =AB26/AC26*10^3 -> 6.7210438
D27: 408.23 | E27: =VLOOKUP(D27,THONGSOHO_BK,2,1)+(VLOOKUP(D27+1,THONGSOHO_BK,2,1)-VLOOKUP(D27,THONGSOHO_BK,2,1))/1*(D27-VLOOKUP(D27,THONGSOHO_BK,1,1))-48.55 -> #NAME? | F27: 408.23 | G27: 411.59 | H27: 4.3878729 | I27: 1100.9 | J27: =H27/I27*10^3 -> 3.9857143 | O27: 464.73 | P27: =VLOOKUP(O27,THONGSOHO_BTS,2,1)+(VLOOKUP(O27+5,THONGSOHO_BTS,2,1)-VLOOKUP(O27,THONGSOHO_BTS,2,1))/5*(O27-VLOOKUP(O27,THONGSOHO_BTS,1,1))-264.29 -> #NAME? | Q27: 464.73 | R27: 465.24 | S27: 11.3608 | X27: 267.23 | Y27: =VLOOKUP(X27,THONGSOHO_SP3,2,1)+(VLOOKUP(X27+2,THONGSOHO_SP3,2,1)-VLOOKUP(X27,THONGSOHO_SP3,2,1))/2*(X27-VLOOKUP(X27,THONGSOHO_SP3,1,1))-156.13 -> #NAME? | Z27: 267.23 | AA27: 270.791 | AB27: 5.5746 | AC27: 833.3 | AD27: =AB27/AC27*10^3 -> 6.6897876
D28: 408.24 | E28: =VLOOKUP(D28,THONGSOHO_BK,2,1)+(VLOOKUP(D28+1,THONGSOHO_BK,2,1)-VLOOKUP(D28,THONGSOHO_BK,2,1))/1*(D28-VLOOKUP(D28,THONGSOHO_BK,1,1))-48.55 -> #NAME? | F28: 408.24 | G28: 411.18 | H28: 6.5808129 | I28: 1651.1 | J28: =H28/I28*10^3 -> 3.9857143 | O28: 464.74 | P28: =VLOOKUP(O28,THONGSOHO_BTS,2,1)+(VLOOKUP(O28+5,THONGSOHO_BTS,2,1)-VLOOKUP(O28,THONGSOHO_BTS,2,1))/5*(O28-VLOOKUP(O28,THONGSOHO_BTS,1,1))-264.29 -> #NAME? | Q28: 464.74 | R28: 465.25 | S28: 11.36 | X28: 267.24 | Y28: =VLOOKUP(X28,THONGSOHO_SP3,2,1)+(VLOOKUP(X28+2,THONGSOHO_SP3,2,1)-VLOOKUP(X28,THONGSOHO_SP3,2,1))/2*(X28-VLOOKUP(X28,THONGSOHO_SP3,1,1))-156.13 -> #NAME? | Z28: 267.24 | AA28: 270.578 | AB28: 10.0486 | AC28: 1497.4 | AD28: =AB28/AC28*10^3 -> 6.7106985
D29: 408.25 | E29: =VLOOKUP(D29,THONGSOHO_BK,2,1)+(VLOOKUP(D29+1,THONGSOHO_BK,2,1)-VLOOKUP(D29,THONGSOHO_BK,2,1))/1*(D29-VLOOKUP(D29,THONGSOHO_BK,1,1))-48.55 -> #NAME? | F29: 408.25 | G29: 411.29 | H29: 4.3500086 | I29: 1091.4 | J29: =H29/I29*10^3 -> 3.9857143 | O29: 464.75 | P29: =VLOOKUP(O29,THONGSOHO_BTS,2,1)+(VLOOKUP(O29+5,THONGSOHO_BTS,2,1)-VLOOKUP(O29,THONGSOHO_BTS,2,1))/5*(O29-VLOOKUP(O29,THONGSOHO_BTS,1,1))-264.29 -> #NAME? | Q29: 464.75 | R29: 465.26 | S29: 11.3592 | X29: 267.25 | Y29: =VLOOKUP(X29,THONGSOHO_SP3,2,1)+(VLOOKUP(X29+2,THONGSOHO_SP3,2,1)-VLOOKUP(X29,THONGSOHO_SP3,2,1))/2*(X29-VLOOKUP(X29,THONGSOHO_SP3,1,1))-156.13 -> #NAME? | Z29: 267.25 | AA29: 270.508 | AB29: 7.861 | AC29: 1188 | AD29: =AB29/AC29*10^3 -> 6.6170034
D30: 408.26 | E30: =VLOOKUP(D30,THONGSOHO_BK,2,1)+(VLOOKUP(D30+1,THONGSOHO_BK,2,1)-VLOOKUP(D30,THONGSOHO_BK,2,1))/1*(D30-VLOOKUP(D30,THONGSOHO_BK,1,1))-48.55 -> #NAME? | F30: 408.26 | G30: 411.34 | H30: 4.3974386 | I30: 1103.3 | J30: =H30/I30*10^3 -> 3.9857143 | O30: 464.76 | P30: =VLOOKUP(O30,THONGSOHO_BTS,2,1)+(VLOOKUP(O30+5,THONGSOHO_BTS,2,1)-VLOOKUP(O30,THONGSOHO_BTS,2,1))/5*(O30-VLOOKUP(O30,THONGSOHO_BTS,1,1))-264.29 -> #NAME? | Q30: 464.76 | R30: 465.27 | S30: 11.3584 | X30: 267.26 | Y30: =VLOOKUP(X30,THONGSOHO_SP3,2,1)+(VLOOKUP(X30+2,THONGSOHO_SP3,2,1)-VLOOKUP(X30,THONGSOHO_SP3,2,1))/2*(X30-VLOOKUP(X30,THONGSOHO_SP3,1,1))-156.13 -> #NAME? | Z30: 267.26 | AA30: 270.4965 | AB30: 10.1599 | AC30: 1503.3 | AD30: =AB30/AC30*10^3 -> 6.7583982
D31: 408.27 | E31: =VLOOKUP(D31,THONGSOHO_BK,2,1)+(VLOOKUP(D31+1,THONGSOHO_BK,2,1)-VLOOKUP(D31,THONGSOHO_BK,2,1))/1*(D31-VLOOKUP(D31,THONGSOHO_BK,1,1))-48.55 -> #NAME? | F31: 408.27 | G31: 411.6 | H31: 3.5285529 | I31: 885.3 | J31: =H31/I31*10^3 -> 3.9857143 | O31: 464.77 | P31: =VLOOKUP(O31,THONGSOHO_BTS,2,1)+(VLOOKUP(O31+5,THONGSOHO_BTS,2,1)-VLOOKUP(O31,THONGSOHO_BTS,2,1))/5*(O31-VLOOKUP(O31,THONGSOHO_BTS,1,1))-264.29 -> #NAME? | Q31: 464.77 | R31: 465.28 | S31: 11.3576 | X31: 267.27 | Y31: =VLOOKUP(X31,THONGSOHO_SP3,2,1)+(VLOOKUP(X31+2,THONGSOHO_SP3,2,1)-VLOOKUP(X31,THONGSOHO_SP3,2,1))/2*(X31-VLOOKUP(X31,THONGSOHO_SP3,1,1))-156.13 -> #NAME? | Z31: 267.27 | AA31: 270.303 | AB31: 11.1359 | AC31: 1698.2 | AD31: =AB31/AC31*10^3 -> 6.5574726
... D327: 411.23 | E327: =VLOOKUP(D327,THONGSOHO_BK,2,1)+(VLOOKUP(D327+1,THONGSOHO_BK,2,1)-VLOOKUP(D327,THONGSOHO_BK,2,1))/1*(D327-VLOOKUP(D327,THONGSOHO_BK,1,1))-48.55 -> #NAME? | F327: 411.23 | G327: 409.28 | H327: 6.6593314 | I327: 1670.8 | J327: =H327/I327*10^3 -> 3.9857143 | O327: 467.73 | P327: =VLOOKUP(O327,THONGSOHO_BTS,2,1)+(VLOOKUP(O327+5,THONGSOHO_BTS,2,1)-VLOOKUP(O327,THONGSOHO_BTS,2,1))/5*(O327-VLOOKUP(O327,THONGSOHO_BTS,1,1))-264.29 -> #NAME? | Q327: 467.73 | R327: 468.24 | S327: 10.5408 | X327: 270.23 | Y327: =VLOOKUP(X327,THONGSOHO_SP3,2,1)+(VLOOKUP(X327+2,THONGSOHO_SP3,2,1)-VLOOKUP(X327,THONGSOHO_SP3,2,1))/2*(X327-VLOOKUP(X327,THONGSOHO_SP3,1,1))-156.13 -> #NAME? | Z327: 270.23 | AA327: 268.986 | AB327: 9.5806 | AC327: 1445.5 | AD327: =AB327/AC327*10^3 -> 6.6278796
D328: 411.24 | E328: =VLOOKUP(D328,THONGSOHO_BK,2,1)+(VLOOKUP(D328+1,THONGSOHO_BK,2,1)-VLOOKUP(D328,THONGSOHO_BK,2,1))/1*(D328-VLOOKUP(D328,THONGSOHO_BK,1,1))-48.55 -> #NAME? | F328: 411.24 | O328: 467.74 | P328: =VLOOKUP(O328,THONGSOHO_BTS,2,1)+(VLOOKUP(O328+5,THONGSOHO_BTS,2,1)-VLOOKUP(O328,THONGSOHO_BTS,2,1))/5*(O328-VLOOKUP(O328,THONGSOHO_BTS,1,1))-264.29 -> #NAME? | Q328: 467.74 | R328: 468.25 | S328: 10.5375 | X328: 270.24 | Y328: =VLOOKUP(X328,THONGSOHO_SP3,2,1)+(VLOOKUP(X328+2,THONGSOHO_SP3,2,1)-VLOOKUP(X328,THONGSOHO_SP3,2,1))/2*(X328-VLOOKUP(X328,THONGSOHO_SP3,1,1))-156.13 -> #NAME? | Z328: 270.24 | AA328: 268.57 | AB328: 13.9741 | AC328: 2102.7 | AD328: =AB328/AC328*10^3 -> 6.6457887
D329: 411.25 | E329: =VLOOKUP(D329,THONGSOHO_BK,2,1)+(VLOOKUP(D329+1,THONGSOHO_BK,2,1)-VLOOKUP(D329,THONGSOHO_BK,2,1))/1*(D329-VLOOKUP(D329,THONGSOHO_BK,1,1))-48.55 -> #NAME? | F329: 411.25 | O329: 467.75 | P329: =VLOOKUP(O329,THONGSOHO_BTS,2,1)+(VLOOKUP(O329+5,THONGSOHO_BTS,2,1)-VLOOKUP(O329,THONGSOHO_BTS,2,1))/5*(O329-VLOOKUP(O329,THONGSOHO_BTS,1,1))-264.29 -> #NAME? | Q329: 467.75 | R329: 468.26 | S329: 10.5342 | X329: 270.25 | Y329: =VLOOKUP(X329,THONGSOHO_SP3,2,1)+(VLOOKUP(X329+2,THONGSOHO_SP3,2,1)-VLOOKUP(X329,THONGSOHO_SP3,2,1))/2*(X329-VLOOKUP(X329,THONGSOHO_SP3,1,1))-156.13 -> #NAME? | Z329: 270.25 | AA329: 268.308 | AB329: 10.7092 | AC329: 1591 | AD329: =AB329/AC329*10^3 -> 6.7311125
D330: 411.26 | E330: =VLOOKUP(D330,THONGSOHO_BK,2,1)+(VLOOKUP(D330+1,THONGSOHO_BK,2,1)-VLOOKUP(D330,THONGSOHO_BK,2,1))/1*(D330-VLOOKUP(D330,THONGSOHO_BK,1,1))-48.55 -> #NAME? | F330: 411.26 | O330: 467.76 | P330: =VLOOKUP(O330,THONGSOHO_BTS,2,1)+(VLOOKUP(O330+5,THONGSOHO_BTS,2,1)-VLOOKUP(O330,THONGSOHO_BTS,2,1))/5*(O330-VLOOKUP(O330,THONGSOHO_BTS,1,1))-264.29 -> #NAME? | Q330: 467.76 | R330: 468.27 | S330: 10.5309 | X330: 270.26 | Y330: =VLOOKUP(X330,THONGSOHO_SP3,2,1)+(VLOOKUP(X330+2,THONGSOHO_SP3,2,1)-VLOOKUP(X330,THONGSOHO_SP3,2,1))/2*(X330-VLOOKUP(X330,THONGSOHO_SP3,1,1))-156.13 -> #NAME? | Z330: 270.26 | AA330: 268.037 | AB330: 12.22 | AC330: 1813.7 | AD330: =AB330/AC330*10^3 -> 6.7376082
D331: 411.27 | E331: =VLOOKUP(D331,THONGSOHO_BK,2,1)+(VLOOKUP(D331+1,THONGSOHO_BK,2,1)-VLOOKUP(D331,THONGSOHO_BK,2,1))/1*(D331-VLOOKUP(D331,THONGSOHO_BK,1,1))-48.55 -> #NAME? | F331: 411.27 | O331: 467.77 | P331: =VLOOKUP(O331,THONGSOHO_BTS,2,1)+(VLOOKUP(O331+5,THONGSOHO_BTS,2,1)-VLOOKUP(O331,THONGSOHO_BTS,2,1))/5*(O331-VLOOKUP(O331,THONGSOHO_BTS,1,1))-264.29 -> #NAME? | Q331: 467.77 | R331: 468.28 | S331: 10.5276 | X331: 270.27 | Y331: =VLOOKUP(X331,THONGSOHO_SP3,2,1)+(VLOOKUP(X331+2,THONGSOHO_SP3,2,1)-VLOOKUP(X331,THONGSOHO_SP3,2,1))/2*(X331-VLOOKUP(X331,THONGSOHO_SP3,1,1))-156.13 -> #NAME? | Z331: 270.27
D332: 411.28 | E332: =VLOOKUP(D332,THONGSOHO_BK,2,1)+(VLOOKUP(D332+1,THONGSOHO_BK,2,1)-VLOOKUP(D332,THONGSOHO_BK,2,1))/1*(D332-VLOOKUP(D332,THONGSOHO_BK,1,1))-48.55 -> #NAME? | F332: 411.28 | O332: 467.78 | P332: =VLOOKUP(O332,THONGSOHO_BTS,2,1)+(VLOOKUP(O332+5,THONGSOHO_BTS,2,1)-VLOOKUP(O332,THONGSOHO_BTS,2,1))/5*(O332-VLOOKUP(O332,THONGSOHO_BTS,1,1))-264.29 -> #NAME? | Q332: 467.78 | R332: 468.29 | S332: 10.5243 | X332: 270.28 | Y332: =VLOOKUP(X332,THONGSOHO_SP3,2,1)+(VLOOKUP(X332+2,THONGSOHO_SP3,2,1)-VLOOKUP(X332,THONGSOHO_SP3,2,1))/2*(X332-VLOOKUP(X332,THONGSOHO_SP3,1,1))-156.13 -> #NAME? | Z332: 270.28
D333: 411.29 | E333: =VLOOKUP(D333,THONGSOHO_BK,2,1)+(VLOOKUP(D333+1,THONGSOHO_BK,2,1)-VLOOKUP(D333,THONGSOHO_BK,2,1))/1*(D333-VLOOKUP(D333,THONGSOHO_BK,1,1))-48.55 -> #NAME? | F333: 411.29 | O333: 467.79 | P333: =VLOOKUP(O333,THONGSOHO_BTS,2,1)+(VLOOKUP(O333+5,THONGSOHO_BTS,2,1)-VLOOKUP(O333,THONGSOHO_BTS,2,1))/5*(O333-VLOOKUP(O333,THONGSOHO_BTS,1,1))-264.29 -> #NAME? | Q333: 467.79 | R333: 468.3 | S333: 10.521 | X333: 270.29 | Y333: =VLOOKUP(X333,THONGSOHO_SP3,2,1)+(VLOOKUP(X333+2,THONGSOHO_SP3,2,1)-VLOOKUP(X333,THONGSOHO_SP3,2,1))/2*(X333-VLOOKUP(X333,THONGSOHO_SP3,1,1))-156.13 -> #NAME? | Z333: 270.29
D334: 411.3 | E334: =VLOOKUP(D334,THONGSOHO_BK,2,1)+(VLOOKUP(D334+1,THONGSOHO_BK,2,1)-VLOOKUP(D334,THONGSOHO_BK,2,1))/1*(D334-VLOOKUP(D334,THONGSOHO_BK,1,1))-48.55 -> #NAME? | F334: 411.3 | O334: 467.8 | P334: =VLOOKUP(O334,THONGSOHO_BTS,2,1)+(VLOOKUP(O334+5,THONGSOHO_BTS,2,1)-VLOOKUP(O334,THONGSOHO_BTS,2,1))/5*(O334-VLOOKUP(O334,THONGSOHO_BTS,1,1))-264.29 -> #NAME? | Q334: 467.8 | R334: 468.31 | S334: 10.5177 | X334: 270.3 | Y334: =VLOOKUP(X334,THONGSOHO_SP3,2,1)+(VLOOKUP(X334+2,THONGSOHO_SP3,2,1)-VLOOKUP(X334,THONGSOHO_SP3,2,1))/2*(X334-VLOOKUP(X334,THONGSOHO_SP3,1,1))-156.13 -> #NAME? | Z334: 270.3
D335: 411.31 | E335: =VLOOKUP(D335,THONGSOHO_BK,2,1)+(VLOOKUP(D335+1,THONGSOHO_BK,2,1)-VLOOKUP(D335,THONGSOHO_BK,2,1))/1*(D335-VLOOKUP(D335,THONGSOHO_BK,1,1))-48.55 -> #NAME? | F335: 411.31 | O335: 467.81 | P335: =VLOOKUP(O335,THONGSOHO_BTS,2,1)+(VLOOKUP(O335+5,THONGSOHO_BTS,2,1)-VLOOKUP(O335,THONGSOHO_BTS,2,1))/5*(O335-VLOOKUP(O335,THONGSOHO_BTS,1,1))-264.29 -> #NAME? | Q335: 467.81 | R335: 468.32 | S335: 10.5144 | X335: 270.31 | Y335: =VLOOKUP(X335,THONGSOHO_SP3,2,1)+(VLOOKUP(X335+2,THONGSOHO_SP3,2,1)-VLOOKUP(X335,THONGSOHO_SP3,2,1))/2*(X335-VLOOKUP(X335,THONGSOHO_SP3,1,1))-156.13 -> #NAME? | Z335: 270.31
...

Sheet Bảng tra TS-SL BTS
A1: Biểu số 2-a.1
A2: BẢNG TRA TẦN SUẤT NƯỚC VỀ | P2: SẢN LƯỢNG TÍNH THEO TẦN SUẤT | AD2: A_max | AE2: ='ThK SL điện'!Q217 -> 61.071907 | AF2: tr.kwh
A3: Nhà máy Thủy điện Buôn Tua Srah | P3: Nhà máy Thủy điện Buôn Tua Srah | AD3: SHN | AE3: 8.88 | AF3: m3/kwh
A4: Tháng | B4: 1 | C4: 2 | D4: 3 | E4: 4 | F4: 5 | G4: 6 | H4: 7 | I4: 8 | J4: 9 | K4: 10 | L4: 11 | M4: 12 | N4: TB | P4: Tháng | Q4: 1 | R4: 2 | S4: 3 | T4: 4 | U4: 5 | V4: 6 | W4: 7 | X4: 8 | Y4: 9 | Z4: 10 | AA4: 11 | AB4: 12 | AC4: TC | AE4: Tính nội suy lưu lượng ngược ra tần suất | AM4: Tính nội suy tần suất ra sản lượng, lưu lượng
A5: Tần suất | B5: m3/s | P5: Tần suất | Q5: 31 | R5: 29 | S5: 31 | T5: 30 | U5: 31 | V5: 30 | W5: 31 | X5: 31 | Y5: 30 | Z5: 31 | AA5: 30 | AB5: 31 | AC5: tr.kwh | AD5: month | AE5: Q | AF5: Q1 | AG5: Q2 | AH5: F1 | AI5: F2 | AJ5: F | AL5: month | AM5: F[%] | AN5: F1 | AO5: F2 | AP5: A1 | AQ5: A2 | AR5: A[tr.kwh] | AS5: Q1 | AT5: Q2 | AU5: Q[m3/s]
A6: 5 | B6: 76.895 | C6: 51.793753 | D6: 39.7 | E6: 45.614569 | F6: 78.583118 | G6: 105 | H6: 169.08745 | I6: 291.1 | J6: 268.45 | K6: 311.1 | L6: 257.4 | M6: 188.1 | N6: 134.48667 | P6: 5 | Q6: =IF(B6*Q5*24*3600/$AE$3/10^6>$AE$2,$AE$2,B6*Q5*24*3600/$AE$3/10^6) -> 23.193195 | R6: =IF(C6*R5*24*3600/$AE$3/10^6>$AE$2,$AE$2,C6*R5*24*3600/$AE$3/10^6) -> 14.614237 | S6: =IF(D6*S5*24*3600/$AE$3/10^6>$AE$2,$AE$2,D6*S5*24*3600/$AE$3/10^6) -> 11.974378 | T6: =IF(E6*T5*24*3600/$AE$3/10^6>$AE$2,$AE$2,E6*T5*24*3600/$AE$3/10^6) -> 13.314523 | U6: =IF(F6*U5*24*3600/$AE$3/10^6>$AE$2,$AE$2,F6*U5*24*3600/$AE$3/10^6) -> 23.702368 | V6: =IF(G6*V5*24*3600/$AE$3/10^6>$AE$2,$AE$2,G6*V5*24*3600/$AE$3/10^6) -> 30.648649 | W6: =IF(H6*W5*24*3600/$AE$3/10^6>$AE$2,$AE$2,H6*W5*24*3600/$AE$3/10^6) -> 51.000431 | X6: =IF(I6*X5*24*3600/$AE$3/10^6>$AE$2,$AE$2,I6*X5*24*3600/$AE$3/10^6) -> 61.071907 | ... AB6: =IF(M6*AB5*24*3600/$AE$3/10^6>$AE$2,$AE$2,M6*AB5*24*3600/$AE$3/10^6) -> 56.735027 | AC6: =SUM(Q6:AB6) -> 469.47044 | AD6: 1 | AE6: ='Theo dõi TV'!H8 -> 45.692365 | AF6: =_xlfn.XLOOKUP(AE6,B$6:B$24,B$6:B$24,,-1,1) -> 44.79 | AG6: =_xlfn.XLOOKUP(AE6,B$6:B$24,B$6:B$24,,1,1) -> 48.75 | AH6: =_xlfn.XLOOKUP(AE6,$B$6:$B$24,A$6:A$24,,-1,1) -> 55 | AI6: =_xlfn.XLOOKUP(AE6,$B$6:$B$24,A$6:A$24,,1,1) -> 50 | AJ6: =IF(AE6=AF6,AH6,FORECAST(AE6,AH6:AI6,AF6:AG6)) -> 53.860651 | AL6: 1 | AM6: 53.860651 | AN6: =_xlfn.XLOOKUP(AM6,$P$6:$P$24,$P$6:$P$24,,-1,1) -> 50 | AO6: =_xlfn.XLOOKUP(AM6,$P$6:$P$24,$P$6:$P$24,,1,1) -> 55 | AP6: =_xlfn.XLOOKUP(AM6,$P$6:$P$24,$Q$6:$Q$24,,-1,1) -> 14.704054 | AQ6: =_xlfn.XLOOKUP(AM6,$P$6:$P$24,$Q$6:$Q$24,,1,1) -> 13.509632 | AR6: =IF(AM6=AN6,AP6,FORECAST(AM6,AP6:AQ6,AN6:AO6)) -> 13.781805 | AS6: =_xlfn.XLOOKUP(AM6,$A$6:$A$24,$B$6:$B$24,,-1,1) -> 48.75 | AT6: =_xlfn.XLOOKUP(AM6,$A$6:$A$24,$B$6:$B$24,,1,1) -> 44.79 | AU6: =IF(AM6=AN6,AS6,FORECAST(AM6,AS6:AT6,AN6:AO6)) -> 45.692365
A7: 10 | B7: 70.890985 | C7: 50.4 | D7: 37.410498 | E7: 41.250733 | F7: 65.141549 | G7: 103.05843 | H7: 150.01873 | I7: 271 | J7: 249.3 | K7: 286.4 | L7: 206.8 | M7: 167.2 | N7: 122.37701 | P7: 10 | Q7: =IF(B7*Q5*24*3600/$AE$3/10^6>$AE$2,$AE$2,B7*Q5*24*3600/$AE$3/10^6) -> 21.382254 | R7: =IF(C7*R5*24*3600/$AE$3/10^6>$AE$2,$AE$2,C7*R5*24*3600/$AE$3/10^6) -> 14.220973 | S7: =IF(D7*S5*24*3600/$AE$3/10^6>$AE$2,$AE$2,D7*S5*24*3600/$AE$3/10^6) -> 11.283815 | T7: =IF(E7*T5*24*3600/$AE$3/10^6>$AE$2,$AE$2,E7*T5*24*3600/$AE$3/10^6) -> 12.040755 | U7: =IF(F7*U5*24*3600/$AE$3/10^6>$AE$2,$AE$2,F7*U5*24*3600/$AE$3/10^6) -> 19.6481 | V7: =IF(G7*V5*24*3600/$AE$3/10^6>$AE$2,$AE$2,G7*V5*24*3600/$AE$3/10^6) -> 30.081919 | W7: =IF(H7*W5*24*3600/$AE$3/10^6>$AE$2,$AE$2,H7*W5*24*3600/$AE$3/10^6) -> 45.248893 | X7: =IF(I7*X5*24*3600/$AE$3/10^6>$AE$2,$AE$2,I7*X5*24*3600/$AE$3/10^6) -> 61.071907 | ... AB7: =IF(M7*AB5*24*3600/$AE$3/10^6>$AE$2,$AE$2,M7*AB5*24*3600/$AE$3/10^6) -> 50.431135 | AC7: =SUM(Q7:AB7) -> 447.91681 | AD7: 2 | AE7: ='Theo dõi TV'!H9 -> 31.174346 | AF7: =_xlfn.XLOOKUP(AE7,C$6:C$24,C$6:C$24,,-1,1) -> 30.602674 | AG7: =_xlfn.XLOOKUP(AE7,C$6:C$24,C$6:C$24,,1,1) -> 31.786017 | AH7: =_xlfn.XLOOKUP(AE7,$C$6:$C$24,$A$6:$A$24,,-1,1) -> 60 | AI7: =_xlfn.XLOOKUP(AE7,$C$6:$C$24,$A$6:$A$24,,1,1) -> 55 | AJ7: =IF(AE7=AF7,AH7,FORECAST(AE7,AH7:AI7,AF7:AG7)) -> 57.584506 | AL7: 2 | AM7: 57.584506 | AN7: =_xlfn.XLOOKUP(AM7,$P$6:$P$24,$P$6:$P$24,,-1,1) -> 55 | AO7: =_xlfn.XLOOKUP(AM7,$P$6:$P$24,$P$6:$P$24,,1,1) -> 60 | AP7: =_xlfn.XLOOKUP(AM7,$P$6:$P$24,$R$6:$R$24,,-1,1) -> 8.9688114 | AQ7: =_xlfn.XLOOKUP(AM7,$P$6:$P$24,$R$6:$R$24,,1,1) -> 8.6349168 | AR7: =IF(AM7=AN7,AP7,FORECAST(AM7,AP7:AQ7,AN7:AO7)) -> 8.7962209 | AS7: =_xlfn.XLOOKUP(AM7,$A$6:$A$24,$C$6:$C$24,,-1,1) -> 31.786017 | AT7: =_xlfn.XLOOKUP(AM7,$A$6:$A$24,$C$6:$C$24,,1,1) -> 30.602674 | AU7: =IF(AM7=AN7,AS7,FORECAST(AM7,AS7:AT7,AN7:AO7)) -> 31.174346
A8: 15 | B8: 67.5 | C8: 43.76 | D8: 35.234731 | E8: 36.295 | F8: 55.191755 | G8: 94.806894 | H8: 143.94316 | I8: 241.95 | J8: 242.87877 | K8: 273.79584 | L8: 187.44853 | M8: 138.17165 | N8: 111.01875 | P8: 15 | Q8: =IF(B8*Q5*24*3600/$AE$3/10^6>$AE$2,$AE$2,B8*Q5*24*3600/$AE$3/10^6) -> 20.359459 | R8: =IF(C8*R5*24*3600/$AE$3/10^6>$AE$2,$AE$2,C8*R5*24*3600/$AE$3/10^6) -> 12.347416 | S8: =IF(D8*S5*24*3600/$AE$3/10^6>$AE$2,$AE$2,D8*S5*24*3600/$AE$3/10^6) -> 10.627557 | T8: =IF(E8*T5*24*3600/$AE$3/10^6>$AE$2,$AE$2,E8*T5*24*3600/$AE$3/10^6) -> 10.594216 | U8: =IF(F8*U5*24*3600/$AE$3/10^6>$AE$2,$AE$2,F8*U5*24*3600/$AE$3/10^6) -> 16.647027 | V8: =IF(G8*V5*24*3600/$AE$3/10^6>$AE$2,$AE$2,G8*V5*24*3600/$AE$3/10^6) -> 27.673364 | W8: =IF(H8*W5*24*3600/$AE$3/10^6>$AE$2,$AE$2,H8*W5*24*3600/$AE$3/10^6) -> 43.41637 | X8: =IF(I8*X5*24*3600/$AE$3/10^6>$AE$2,$AE$2,I8*X5*24*3600/$AE$3/10^6) -> 61.071907 | ... AB8: =IF(M8*AB5*24*3600/$AE$3/10^6>$AE$2,$AE$2,M8*AB5*24*3600/$AE$3/10^6) -> 41.675557 | AC8: =SUM(Q8:AB8) -> 421.27139 | AD8: 3 | AE8: ='Theo dõi TV'!H10 -> 24.670412 | AF8: =_xlfn.XLOOKUP(AE8,D$6:D$24,D$6:D$24,,-1,1) -> 23.584864 | AG8: =_xlfn.XLOOKUP(AE8,D$6:D$24,D$6:D$24,,1,1) -> 24.98745 | AH8: =_xlfn.XLOOKUP(AE8,$D$6:$D$24,$A$6:$A$24,,-1,1) -> 60 | AI8: =_xlfn.XLOOKUP(AE8,$D$6:$D$24,$A$6:$A$24,,1,1) -> 55 | AJ8: =IF(AE8=AF8,AH8,FORECAST(AE8,AH8:AI8,AF8:AG8)) -> 56.130192 | AL8: 3 | AM8: 56.130192 | AN8: =_xlfn.XLOOKUP(AM8,$P$6:$P$24,$P$6:$P$24,,-1,1) -> 55 | AO8: =_xlfn.XLOOKUP(AM8,$P$6:$P$24,$P$6:$P$24,,1,1) -> 60 | AP8: =_xlfn.XLOOKUP(AM8,$P$6:$P$24,$S$6:$S$24,,-1,1) -> 7.5367552 | AQ8: =_xlfn.XLOOKUP(AM8,$P$6:$P$24,$S$6:$S$24,,1,1) -> 7.1137048 | AR8: =IF(AM8=AN8,AP8,FORECAST(AM8,AP8:AQ8,AN8:AO8)) -> 7.4411296 | AS8: =_xlfn.XLOOKUP(AM8,$A$6:$A$24,$D$6:$D$24,,-1,1) -> 24.98745 | AT8: =_xlfn.XLOOKUP(AM8,$A$6:$A$24,$D$6:$D$24,,1,1) -> 23.584864 | AU8: =IF(AM8=AN8,AS8,FORECAST(AM8,AS8:AT8,AN8:AO8)) -> 24.670412
A9: 20 | B9: 65.419634 | C9: 39.829076 | D9: 33.36 | E9: 35.4 | F9: 52.5 | G9: 91.04148 | H9: 133.65527 | I9: 228.98649 | J9: 230.55281 | K9: 256.00287 | L9: 184.96041 | M9: 120.42192 | N9: 103.72269 | P9: 20 | Q9: =IF(B9*Q5*24*3600/$AE$3/10^6>$AE$2,$AE$2,B9*Q5*24*3600/$AE$3/10^6) -> 19.731976 | R9: =IF(C9*R5*24*3600/$AE$3/10^6>$AE$2,$AE$2,C9*R5*24*3600/$AE$3/10^6) -> 11.238258 | S9: =IF(D9*S5*24*3600/$AE$3/10^6>$AE$2,$AE$2,D9*S5*24*3600/$AE$3/10^6) -> 10.062097 | T9: =IF(E9*T5*24*3600/$AE$3/10^6>$AE$2,$AE$2,E9*T5*24*3600/$AE$3/10^6) -> 10.332973 | U9: =IF(F9*U5*24*3600/$AE$3/10^6>$AE$2,$AE$2,F9*U5*24*3600/$AE$3/10^6) -> 15.835135 | V9: =IF(G9*V5*24*3600/$AE$3/10^6>$AE$2,$AE$2,G9*V5*24*3600/$AE$3/10^6) -> 26.57427 | W9: =IF(H9*W5*24*3600/$AE$3/10^6>$AE$2,$AE$2,H9*W5*24*3600/$AE$3/10^6) -> 40.31332 | X9: =IF(I9*X5*24*3600/$AE$3/10^6>$AE$2,$AE$2,I9*X5*24*3600/$AE$3/10^6) -> 61.071907 | ... AB9: =IF(M9*AB5*24*3600/$AE$3/10^6>$AE$2,$AE$2,M9*AB5*24*3600/$AE$3/10^6) -> 36.321854 | AC9: =SUM(Q9:AB9) -> 407.61405 | AD9: 4 | AE9: ='Theo dõi TV'!H11 -> 23.55115 | AF9: =_xlfn.XLOOKUP(AE9,E$6:E$24,E$6:E$24,,-1,1) -> 21.462264 | AG9: =_xlfn.XLOOKUP(AE9,E$6:E$24,E$6:E$24,,1,1) -> 23.6063 | AH9: =_xlfn.XLOOKUP(AE9,$E$6:$E$24,$A$6:$A$24,,-1,1) -> 75 | AI9: =_xlfn.XLOOKUP(AE9,$E$6:$E$24,$A$6:$A$24,,1,1) -> 70 | AJ9: =IF(AE9=AF9,AH9,FORECAST(AE9,AH9:AI9,AF9:AG9)) -> 70.128612 | AL9: 4 | AM9: 70.128612 | AN9: =_xlfn.XLOOKUP(AM9,$P$6:$P$24,$P$6:$P$24,,-1,1) -> 70 | AO9: =_xlfn.XLOOKUP(AM9,$P$6:$P$24,$P$6:$P$24,,1,1) -> 75 | AP9: =_xlfn.XLOOKUP(AM9,$P$6:$P$24,$T$6:$T$24,,-1,1) -> 6.8904876 | AQ9: =_xlfn.XLOOKUP(AM9,$P$6:$P$24,$T$6:$T$24,,1,1) -> 6.2646608 | AR9: =IF(AM9=AN9,AP9,FORECAST(AM9,AP9:AQ9,AN9:AO9)) -> 6.8743897 | AS9: =_xlfn.XLOOKUP(AM9,$A$6:$A$24,$E$6:$E$24,,-1,1) -> 23.6063 | AT9: =_xlfn.XLOOKUP(AM9,$A$6:$A$24,$E$6:$E$24,,1,1) -> 21.462264 | AU9: =IF(AM9=AN9,AS9,FORECAST(AM9,AS9:AT9,AN9:AO9)) -> 23.55115
A10: 25 | B10: 62.437151 | C10: 39.081442 | D10: 32.015679 | E10: 32.925 | F10: 52.175 | G10: 85.325 | H10: 126.5 | I10: 206 | J10: 225 | K10: 233.49713 | L10: 174.68856 | M10: 107 | N10: 102.04792 | P10: 25 | Q10: =IF(B10*Q5*24*3600/$AE$3/10^6>$AE$2,$AE$2,B10*Q5*24*3600/$AE$3/10^6) -> 18.832395 | R10: =IF(C10*R5*24*3600/$AE$3/10^6>$AE$2,$AE$2,C10*R5*24*3600/$AE$3/10^6) -> 11.027304 | S10: =IF(D10*S5*24*3600/$AE$3/10^6>$AE$2,$AE$2,D10*S5*24*3600/$AE$3/10^6) -> 9.6566211 | T10: =IF(E10*T5*24*3600/$AE$3/10^6>$AE$2,$AE$2,E10*T5*24*3600/$AE$3/10^6) -> 9.6105405 | U10: =IF(F10*U5*24*3600/$AE$3/10^6>$AE$2,$AE$2,F10*U5*24*3600/$AE$3/10^6) -> 15.737108 | V10: =IF(G10*V5*24*3600/$AE$3/10^6>$AE$2,$AE$2,G10*V5*24*3600/$AE$3/10^6) -> 24.905676 | W10: =IF(H10*W5*24*3600/$AE$3/10^6>$AE$2,$AE$2,H10*W5*24*3600/$AE$3/10^6) -> 38.155135 | X10: =IF(I10*X5*24*3600/$AE$3/10^6>$AE$2,$AE$2,I10*X5*24*3600/$AE$3/10^6) -> 61.071907 | ... AB10: =IF(M10*AB5*24*3600/$AE$3/10^6>$AE$2,$AE$2,M10*AB5*24*3600/$AE$3/10^6) -> 32.273514 | AC10: =SUM(Q10:AB10) -> 394.40419 | AD10: 5 | AE10: ='Theo dõi TV'!H12 -> 35.340364 | AF10: =_xlfn.XLOOKUP(AE10,F$6:F$24,F$6:F$24,,-1,1) -> 34.013594 | AG10: =_xlfn.XLOOKUP(AE10,F$6:F$24,F$6:F$24,,1,1) -> 37.38 | AH10: =_xlfn.XLOOKUP(AE10,$F$6:$F$24,$A$6:$A$24,,-1,1) -> 65 | AI10: =_xlfn.XLOOKUP(AE10,$F$6:$F$24,$A$6:$A$24,,1,1) -> 60 | AJ10: =IF(AE10=AF10,AH10,FORECAST(AE10,AH10:AI10,AF10:AG10)) -> 63.029396 | AL10: 5 | AM10: 63.029396 | AN10: =_xlfn.XLOOKUP(AM10,$P$6:$P$24,$P$6:$P$24,,-1,1) -> 60 | AO10: =_xlfn.XLOOKUP(AM10,$P$6:$P$24,$P$6:$P$24,,1,1) -> 65 | AP10: =_xlfn.XLOOKUP(AM10,$P$6:$P$24,$U$6:$U$24,,-1,1) -> 11.274616 | AQ10: =_xlfn.XLOOKUP(AM10,$P$6:$P$24,$U$6:$U$24,,1,1) -> 10.259235 | AR10: =IF(AM10=AN10,AP10,FORECAST(AM10,AP10:AQ10,AN10:AO10)) -> 10.659418 | AS10: =_xlfn.XLOOKUP(AM10,$A$6:$A$24,$F$6:$F$24,,-1,1) -> 37.38 | AT10: =_xlfn.XLOOKUP(AM10,$A$6:$A$24,$F$6:$F$24,,1,1) -> 34.013594 | AU10: =IF(AM10=AN10,AS10,FORECAST(AM10,AS10:AT10,AN10:AO10)) -> 35.340364
A11: 30 | B11: 60.037615 | C11: 38.889518 | D11: 31.219806 | E11: 31.495149 | F11: 50.561133 | G11: 82.64 | H11: 119.79671 | I11: 197.42427 | J11: 216.95487 | K11: 210.8 | L11: 168.26065 | M11: 93.2 | N11: 100.88019 | P11: 30 | Q11: =IF(B11*Q5*24*3600/$AE$3/10^6>$AE$2,$AE$2,B11*Q5*24*3600/$AE$3/10^6) -> 18.108643 | R11: =IF(C11*R5*24*3600/$AE$3/10^6>$AE$2,$AE$2,C11*R5*24*3600/$AE$3/10^6) -> 10.97315 | S11: =IF(D11*S5*24*3600/$AE$3/10^6>$AE$2,$AE$2,D11*S5*24*3600/$AE$3/10^6) -> 9.4165686 | T11: =IF(E11*T5*24*3600/$AE$3/10^6>$AE$2,$AE$2,E11*T5*24*3600/$AE$3/10^6) -> 9.1931785 | U11: =IF(F11*U5*24*3600/$AE$3/10^6>$AE$2,$AE$2,F11*U5*24*3600/$AE$3/10^6) -> 15.250331 | V11: =IF(G11*V5*24*3600/$AE$3/10^6>$AE$2,$AE$2,G11*V5*24*3600/$AE$3/10^6) -> 24.121946 | W11: =IF(H11*W5*24*3600/$AE$3/10^6>$AE$2,$AE$2,H11*W5*24*3600/$AE$3/10^6) -> 36.133278 | X11: =IF(I11*X5*24*3600/$AE$3/10^6>$AE$2,$AE$2,I11*X5*24*3600/$AE$3/10^6) -> 59.54743 | ... AB11: =IF(M11*AB5*24*3600/$AE$3/10^6>$AE$2,$AE$2,M11*AB5*24*3600/$AE$3/10^6) -> 28.111135 | AC11: =SUM(Q11:AB11) -> 382.11339 | AD11: 6 | AE11: ='Theo dõi TV'!H13 -> 71.350534 | AF11: =_xlfn.XLOOKUP(AE11,G$6:G$24,G$6:G$24,,-1,1) -> 68.665594 | AG11: =_xlfn.XLOOKUP(AE11,G$6:G$24,G$6:G$24,,1,1) -> 73.1 | AH11: =_xlfn.XLOOKUP(AE11,$G$6:$G$24,$A$6:$A$24,,-1,1) -> 45 | AI11: =_xlfn.XLOOKUP(AE11,$G$6:$G$24,$A$6:$A$24,,1,1) -> 40 | AJ11: =IF(AE11=AF11,AH11,FORECAST(AE11,AH11:AI11,AF11:AG11)) -> 41.972604 | AL11: 6 | AM11: 41.972604 | AN11: =_xlfn.XLOOKUP(AM11,$P$6:$P$24,$P$6:$P$24,,-1,1) -> 40 | AO11: =_xlfn.XLOOKUP(AM11,$P$6:$P$24,$P$6:$P$24,,1,1) -> 45 | AP11: =_xlfn.XLOOKUP(AM11,$P$6:$P$24,$V$6:$V$24,,-1,1) -> 21.337297 | AQ11: =_xlfn.XLOOKUP(AM11,$P$6:$P$24,$V$6:$V$24,,1,1) -> 20.04293 | AR11: =IF(AM11=AN11,AP11,FORECAST(AM11,AP11:AQ11,AN11:AO11)) -> 20.826642 | AS11: =_xlfn.XLOOKUP(AM11,$A$6:$A$24,$G$6:$G$24,,-1,1) -> 73.1 | AT11: =_xlfn.XLOOKUP(AM11,$A$6:$A$24,$G$6:$G$24,,1,1) -> 68.665594 | AU11: =IF(AM11=AN11,AS11,FORECAST(AM11,AS11:AT11,AN11:AO11)) -> 71.350534
A12: 35 | B12: 56.537802 | C12: 37.034286 | D12: 29.95 | E12: 31.155 | F12: 47.797661 | G12: 80.56 | H12: 111.1 | I12: 192.58836 | J12: 212.1 | K12: 206.17161 | L12: 149.5 | M12: 84.741195 | N12: 98.228333 | P12: 35 | Q12: =IF(B12*Q5*24*3600/$AE$3/10^6>$AE$2,$AE$2,B12*Q5*24*3600/$AE$3/10^6) -> 17.053024 | R12: =IF(C12*R5*24*3600/$AE$3/10^6>$AE$2,$AE$2,C12*R5*24*3600/$AE$3/10^6) -> 10.449674 | S12: =IF(D12*S5*24*3600/$AE$3/10^6>$AE$2,$AE$2,D12*S5*24*3600/$AE$3/10^6) -> 9.0335676 | T12: =IF(E12*T5*24*3600/$AE$3/10^6>$AE$2,$AE$2,E12*T5*24*3600/$AE$3/10^6) -> 9.0938919 | U12: =IF(F12*U5*24*3600/$AE$3/10^6>$AE$2,$AE$2,F12*U5*24*3600/$AE$3/10^6) -> 14.416808 | V12: =IF(G12*V5*24*3600/$AE$3/10^6>$AE$2,$AE$2,G12*V5*24*3600/$AE$3/10^6) -> 23.514811 | W12: =IF(H12*W5*24*3600/$AE$3/10^6>$AE$2,$AE$2,H12*W5*24*3600/$AE$3/10^6) -> 33.510162 | X12: =IF(I12*X5*24*3600/$AE$3/10^6>$AE$2,$AE$2,I12*X5*24*3600/$AE$3/10^6) -> 58.088814 | ... AB12: =IF(M12*AB5*24*3600/$AE$3/10^6>$AE$2,$AE$2,M12*AB5*24*3600/$AE$3/10^6) -> 25.559777 | AC12: =SUM(Q12:AB12) -> 366.50218 | AD12: 7 | AE12: ='Theo dõi TV'!H14 -> 75 | AF12: =_xlfn.XLOOKUP(AE12,H$6:H$24,H$6:H$24,,-1,1) -> 74.219919 | AG12: =_xlfn.XLOOKUP(AE12,H$6:H$24,H$6:H$24,,1,1) -> 78.97469 | AH12: =_xlfn.XLOOKUP(AE12,$H$6:$H$24,$A$6:$A$24,,-1,1) -> 70 | AI12: =_xlfn.XLOOKUP(AE12,$H$6:$H$24,$A$6:$A$24,,1,1) -> 65 | AJ12: =IF(AE12=AF12,AH12,FORECAST(AE12,AH12:AI12,AF12:AG12)) -> 69.179686 | AL12: 7 | AM12: =AJ12 -> 69.179686 | AN12: =_xlfn.XLOOKUP(AM12,$P$6:$P$24,$P$6:$P$24,,-1,1) -> 65 | AO12: =_xlfn.XLOOKUP(AM12,$P$6:$P$24,$P$6:$P$24,,1,1) -> 70 | AP12: =_xlfn.XLOOKUP(AM12,$P$6:$P$24,$W$6:$W$24,,-1,1) -> 23.820474 | AQ12: =_xlfn.XLOOKUP(AM12,$P$6:$P$24,$W$6:$W$24,,1,1) -> 22.386332 | AR12: =IF(AM12=AN12,AP12,FORECAST(AM12,AP12:AQ12,AN12:AO12)) -> 22.621622 | AS12: =_xlfn.XLOOKUP(AM12,$A$6:$A$24,$H$6:$H$24,,-1,1) -> 78.97469 | AT12: =_xlfn.XLOOKUP(AM12,$A$6:$A$24,$H$6:$H$24,,1,1) -> 74.219919 | AU12: =IF(AM12=AN12,AS12,FORECAST(AM12,AS12:AT12,AN12:AO12)) -> 75
A13: 40 | B13: 55.14 | C13: 35.18 | D13: 28.06 | E13: 29.684627 | F13: 44.021856 | G13: 73.1 | H13: 104.2 | I13: 166.85627 | J13: 204.5192 | K13: 190.63382 | L13: 139 | M13: 81.16 | N13: 97.51306 | P13: 40 | Q13: =IF(B13*Q5*24*3600/$AE$3/10^6>$AE$2,$AE$2,B13*Q5*24*3600/$AE$3/10^6) -> 16.631416 | R13: =IF(C13*R5*24*3600/$AE$3/10^6>$AE$2,$AE$2,C13*R5*24*3600/$AE$3/10^6) -> 9.9264649 | S13: =IF(D13*S5*24*3600/$AE$3/10^6>$AE$2,$AE$2,D13*S5*24*3600/$AE$3/10^6) -> 8.4635027 | T13: =IF(E13*T5*24*3600/$AE$3/10^6>$AE$2,$AE$2,E13*T5*24*3600/$AE$3/10^6) -> 8.6647019 | U13: =IF(F13*U5*24*3600/$AE$3/10^6>$AE$2,$AE$2,F13*U5*24*3600/$AE$3/10^6) -> 13.277944 | V13: =IF(G13*V5*24*3600/$AE$3/10^6>$AE$2,$AE$2,G13*V5*24*3600/$AE$3/10^6) -> 21.337297 | W13: =IF(H13*W5*24*3600/$AE$3/10^6>$AE$2,$AE$2,H13*W5*24*3600/$AE$3/10^6) -> 31.428973 | X13: =IF(I13*X5*24*3600/$AE$3/10^6>$AE$2,$AE$2,I13*X5*24*3600/$AE$3/10^6) -> 50.327459 | ... AB13: =IF(M13*AB5*24*3600/$AE$3/10^6>$AE$2,$AE$2,M13*AB5*24*3600/$AE$3/10^6) -> 24.479611 | AC13: =SUM(Q13:AB13) -> 342.30712 | AD13: 8 | AE13: ='Theo dõi TV'!H15 -> 115 | AF13: =_xlfn.XLOOKUP(AE13,I$6:I$24,I$6:I$24,,-1,1) -> 106.9 | AG13: =_xlfn.XLOOKUP(AE13,I$6:I$24,I$6:I$24,,1,1) -> 122.9 | AH13: =_xlfn.XLOOKUP(AE13,$I$6:$I$24,$A$6:$A$24,,-1,1) -> 70 | AI13: =_xlfn.XLOOKUP(AE13,$I$6:$I$24,$A$6:$A$24,,1,1) -> 65 | AJ13: =IF(AE13=AF13,AH13,FORECAST(AE13,AH13:AI13,AF13:AG13)) -> 67.46875 | AL13: 8 | AM13: 91 | AN13: =_xlfn.XLOOKUP(AM13,$P$6:$P$24,$P$6:$P$24,,-1,1) -> 90 | AO13: =_xlfn.XLOOKUP(AM13,$P$6:$P$24,$P$6:$P$24,,1,1) -> 95 | AP13: =_xlfn.XLOOKUP(AM13,$P$6:$P$24,$X$6:$X$24,,-1,1) -> 25.725751 | AQ13: =_xlfn.XLOOKUP(AM13,$P$6:$P$24,$X$6:$X$24,,1,1) -> 21.781605 | AR13: =IF(AM13=AN13,AP13,FORECAST(AM13,AP13:AQ13,AN13:AO13)) -> 24.936922 | AS13: =_xlfn.XLOOKUP(AM13,$A$6:$A$24,$I$6:$I$24,,-1,1) -> 85.291468 | AT13: =_xlfn.XLOOKUP(AM13,$A$6:$A$24,$I$6:$I$24,,1,1) -> 72.215 | AU13: =IF(AM13=AN13,AS13,FORECAST(AM13,AS13:AT13,AN13:AO13)) -> 82.676174
A14: 45 | B14: 51.68 | C14: 33.928124 | D14: 26.665 | E14: 28.0852 | F14: 43.045 | G14: 68.665594 | H14: 98.773667 | I14: 151.52524 | J14: 191.66878 | K14: 178.55 | L14: 126.64913 | M14: 79.3 | N14: 94.437341 | P14: 45 | Q14: =IF(B14*Q5*24*3600/$AE$3/10^6>$AE$2,$AE$2,B14*Q5*24*3600/$AE$3/10^6) -> 15.587805 | R14: =IF(C14*R5*24*3600/$AE$3/10^6>$AE$2,$AE$2,C14*R5*24*3600/$AE$3/10^6) -> 9.5732329 | S14: =IF(D14*S5*24*3600/$AE$3/10^6>$AE$2,$AE$2,D14*S5*24*3600/$AE$3/10^6) -> 8.0427405 | T14: =IF(E14*T5*24*3600/$AE$3/10^6>$AE$2,$AE$2,E14*T5*24*3600/$AE$3/10^6) -> 8.1978422 | U14: =IF(F14*U5*24*3600/$AE$3/10^6>$AE$2,$AE$2,F14*U5*24*3600/$AE$3/10^6) -> 12.983303 | V14: =IF(G14*V5*24*3600/$AE$3/10^6>$AE$2,$AE$2,G14*V5*24*3600/$AE$3/10^6) -> 20.04293 | W14: =IF(H14*W5*24*3600/$AE$3/10^6>$AE$2,$AE$2,H14*W5*24*3600/$AE$3/10^6) -> 29.792274 | X14: =IF(I14*X5*24*3600/$AE$3/10^6>$AE$2,$AE$2,I14*X5*24*3600/$AE$3/10^6) -> 45.703288 | ... AB14: =IF(M14*AB5*24*3600/$AE$3/10^6>$AE$2,$AE$2,M14*AB5*24*3600/$AE$3/10^6) -> 23.918595 | AC14: =SUM(Q14:AB14) -> 320.61097 | AD14: 9 | AE14: ='Theo dõi TV'!H16 -> 153 | AF14: =_xlfn.XLOOKUP(AE14,J$6:J$24,J$6:J$24,,-1,1) -> 146.23671 | AG14: =_xlfn.XLOOKUP(AE14,J$6:J$24,J$6:J$24,,1,1) -> 162.23282 | AH14: =_xlfn.XLOOKUP(AE14,$J$6:$J$24,$A$6:$A$24,,-1,1) -> 75 | AI14: =_xlfn.XLOOKUP(AE14,$J$6:$J$24,$A$6:$A$24,,1,1) -> 70 | AJ14: =IF(AE14=AF14,AH14,FORECAST(AE14,AH14:AI14,AF14:AG14)) -> 72.885958 | AL14: 9 | AM14: 47 | AN14: =_xlfn.XLOOKUP(AM14,$P$6:$P$24,$P$6:$P$24,,-1,1) -> 45 | AO14: =_xlfn.XLOOKUP(AM14,$P$6:$P$24,$P$6:$P$24,,1,1) -> 50 | AP14: =_xlfn.XLOOKUP(AM14,$P$6:$P$24,$Y$6:$Y$24,,-1,1) -> 55.946561 | AQ14: =_xlfn.XLOOKUP(AM14,$P$6:$P$24,$Y$6:$Y$24,,1,1) -> 53.744149 | AR14: =IF(AM14=AN14,AP14,FORECAST(AM14,AP14:AQ14,AN14:AO14)) -> 55.065596 | AS14: =_xlfn.XLOOKUP(AM14,$A$6:$A$24,$J$6:$J$24,,-1,1) -> 191.66878 | AT14: =_xlfn.XLOOKUP(AM14,$A$6:$A$24,$J$6:$J$24,,1,1) -> 184.12347 | AU14: =IF(AM14=AN14,AS14,FORECAST(AM14,AS14:AT14,AN14:AO14)) -> 188.65065
A15: 50 | B15: 48.75 | C15: 33.225482 | D15: 25.593492 | E15: 27.15 | F15: 40.95 | G15: 64.58638 | H15: 91.95 | I15: 143.74804 | J15: 184.12347 | K15: 173.5 | L15: 122 | M15: 78.933501 | N15: 91.334399 | P15: 50 | Q15: =IF(B15*Q5*24*3600/$AE$3/10^6>$AE$2,$AE$2,B15*Q5*24*3600/$AE$3/10^6) -> 14.704054 | R15: =IF(C15*R5*24*3600/$AE$3/10^6>$AE$2,$AE$2,C15*R5*24*3600/$AE$3/10^6) -> 9.3749739 | S15: =IF(D15*S5*24*3600/$AE$3/10^6>$AE$2,$AE$2,D15*S5*24*3600/$AE$3/10^6) -> 7.7195505 | T15: =IF(E15*T5*24*3600/$AE$3/10^6>$AE$2,$AE$2,E15*T5*24*3600/$AE$3/10^6) -> 7.9248649 | U15: =IF(F15*U5*24*3600/$AE$3/10^6>$AE$2,$AE$2,F15*U5*24*3600/$AE$3/10^6) -> 12.351405 | V15: =IF(G15*V5*24*3600/$AE$3/10^6>$AE$2,$AE$2,G15*V5*24*3600/$AE$3/10^6) -> 18.852241 | W15: =IF(H15*W5*24*3600/$AE$3/10^6>$AE$2,$AE$2,H15*W5*24*3600/$AE$3/10^6) -> 27.734108 | X15: =IF(I15*X5*24*3600/$AE$3/10^6>$AE$2,$AE$2,I15*X5*24*3600/$AE$3/10^6) -> 43.357517 | ... AB15: =IF(M15*AB5*24*3600/$AE$3/10^6>$AE$2,$AE$2,M15*AB5*24*3600/$AE$3/10^6) -> 23.80805 | AC15: =SUM(Q15:AB15) -> 307.51308 | AD15: 10 | AE15: ='Theo dõi TV'!H17 -> 160 | AF15: =_xlfn.XLOOKUP(AE15,K$6:K$24,K$6:K$24,,-1,1) -> 158.03908 | AG15: =_xlfn.XLOOKUP(AE15,K$6:K$24,K$6:K$24,,1,1) -> 164 | AH15: =_xlfn.XLOOKUP(AE15,$K$6:$K$24,$A$6:$A$24,,-1,1) -> 65 | AI15: =_xlfn.XLOOKUP(AE15,$K$6:$K$24,$A$6:$A$24,,1,1) -> 60 | AJ15: =IF(AE15=AF15,AH15,FORECAST(AE15,AH15:AI15,AF15:AG15)) -> 63.355184 | AL15: 10 | AM15: 57 | AN15: =_xlfn.XLOOKUP(AM15,$P$6:$P$24,$P$6:$P$24,,-1,1) -> 55 | AO15: =_xlfn.XLOOKUP(AM15,$P$6:$P$24,$P$6:$P$24,,1,1) -> 60 | AP15: =_xlfn.XLOOKUP(AM15,$P$6:$P$24,$Z$6:$Z$24,,-1,1) -> 49.991098 | AQ15: =_xlfn.XLOOKUP(AM15,$P$6:$P$24,$Z$6:$Z$24,,1,1) -> 49.465946 | AR15: =IF(AM15=AN15,AP15,FORECAST(AM15,AP15:AQ15,AN15:AO15)) -> 49.781037 | AS15: =_xlfn.XLOOKUP(AM15,$A$6:$A$24,$K$6:$K$24,,-1,1) -> 165.7411 | AT15: =_xlfn.XLOOKUP(AM15,$A$6:$A$24,$K$6:$K$24,,1,1) -> 164 | AU15: =IF(AM15=AN15,AS15,FORECAST(AM15,AS15:AT15,AN15:AO15)) -> 165.04466
A16: 55 | B16: 44.79 | C16: 31.786017 | D16: 24.98745 | E16: 26.5402 | F16: 39.66 | G16: 62.29 | H16: 87.13 | I16: 133.17149 | J16: 178.34478 | K16: 165.7411 | L16: 114.88709 | M16: 74.952134 | N16: 88.85197 | P16: 55 | Q16: =IF(B16*Q5*24*3600/$AE$3/10^6>$AE$2,$AE$2,B16*Q5*24*3600/$AE$3/10^6) -> 13.509632 | R16: =IF(C16*R5*24*3600/$AE$3/10^6>$AE$2,$AE$2,C16*R5*24*3600/$AE$3/10^6) -> 8.9688114 | S16: =IF(D16*S5*24*3600/$AE$3/10^6>$AE$2,$AE$2,D16*S5*24*3600/$AE$3/10^6) -> 7.5367552 | T16: =IF(E16*T5*24*3600/$AE$3/10^6>$AE$2,$AE$2,E16*T5*24*3600/$AE$3/10^6) -> 7.7468691 | U16: =IF(F16*U5*24*3600/$AE$3/10^6>$AE$2,$AE$2,F16*U5*24*3600/$AE$3/10^6) -> 11.962314 | V16: =IF(G16*V5*24*3600/$AE$3/10^6>$AE$2,$AE$2,G16*V5*24*3600/$AE$3/10^6) -> 18.181946 | W16: =IF(H16*W5*24*3600/$AE$3/10^6>$AE$2,$AE$2,H16*W5*24*3600/$AE$3/10^6) -> 26.280292 | X16: =IF(I16*X5*24*3600/$AE$3/10^6>$AE$2,$AE$2,I16*X5*24*3600/$AE$3/10^6) -> 40.1674 | ... AB16: =IF(M16*AB5*24*3600/$AE$3/10^6>$AE$2,$AE$2,M16*AB5*24*3600/$AE$3/10^6) -> 22.607184 | AC16: =SUM(Q16:AB16) -> 292.54431 | AD16: 11 | AE16: ='Theo dõi TV'!H18 -> 105 | AF16: =_xlfn.XLOOKUP(AE16,L$6:L$24,L$6:L$24,,-1,1) -> 98.034624 | AG16: =_xlfn.XLOOKUP(AE16,L$6:L$24,L$6:L$24,,1,1) -> 108.6 | AH16: =_xlfn.XLOOKUP(AE16,$L$6:$L$24,$A$6:$A$24,,-1,1) -> 65 | AI16: =_xlfn.XLOOKUP(AE16,$L$6:$L$24,$A$6:$A$24,,1,1) -> 60 | AJ16: =IF(AE16=AF16,AH16,FORECAST(AE16,AH16:AI16,AF16:AG16)) -> 61.703678 | AL16: 11 | AM16: 34 | AN16: =_xlfn.XLOOKUP(AM16,$P$6:$P$24,$P$6:$P$24,,-1,1) -> 30 | AO16: =_xlfn.XLOOKUP(AM16,$P$6:$P$24,$P$6:$P$24,,1,1) -> 35 | AP16: =_xlfn.XLOOKUP(AM16,$P$6:$P$24,$AA$6:$AA$24,,-1,1) -> 49.113921 | AQ16: =_xlfn.XLOOKUP(AM16,$P$6:$P$24,$AA$6:$AA$24,,1,1) -> 43.637838 | AR16: =IF(AM16=AN16,AP16,FORECAST(AM16,AP16:AQ16,AN16:AO16)) -> 44.733054 | AS16: =_xlfn.XLOOKUP(AM16,$A$6:$A$24,$L$6:$L$24,,-1,1) -> 168.26065 | AT16: =_xlfn.XLOOKUP(AM16,$A$6:$A$24,$L$6:$L$24,,1,1) -> 149.5 | AU16: =IF(AM16=AN16,AS16,FORECAST(AM16,AS16:AT16,AN16:AO16)) -> 153.25213
A17: 60 | B17: 43.16 | C17: 30.602674 | D17: 23.584864 | E17: 25.76 | F17: 37.38 | G17: 58.813276 | H17: 84.2 | I17: 128.25323 | J17: 176.6 | K17: 164 | L17: 108.6 | M17: 70.14 | N17: 86.636329 | P17: 60 | Q17: =IF(B17*Q5*24*3600/$AE$3/10^6>$AE$2,$AE$2,B17*Q5*24*3600/$AE$3/10^6) -> 13.017989 | R17: =IF(C17*R5*24*3600/$AE$3/10^6>$AE$2,$AE$2,C17*R5*24*3600/$AE$3/10^6) -> 8.6349168 | S17: =IF(D17*S5*24*3600/$AE$3/10^6>$AE$2,$AE$2,D17*S5*24*3600/$AE$3/10^6) -> 7.1137048 | T17: =IF(E17*T5*24*3600/$AE$3/10^6>$AE$2,$AE$2,E17*T5*24*3600/$AE$3/10^6) -> 7.5191351 | U17: =IF(F17*U5*24*3600/$AE$3/10^6>$AE$2,$AE$2,F17*U5*24*3600/$AE$3/10^6) -> 11.274616 | V17: =IF(G17*V5*24*3600/$AE$3/10^6>$AE$2,$AE$2,G17*V5*24*3600/$AE$3/10^6) -> 17.167118 | W17: =IF(H17*W5*24*3600/$AE$3/10^6>$AE$2,$AE$2,H17*W5*24*3600/$AE$3/10^6) -> 25.396541 | X17: =IF(I17*X5*24*3600/$AE$3/10^6>$AE$2,$AE$2,I17*X5*24*3600/$AE$3/10^6) -> 38.683948 | ... AB17: =IF(M17*AB5*24*3600/$AE$3/10^6>$AE$2,$AE$2,M17*AB5*24*3600/$AE$3/10^6) -> 21.155741 | AC17: =SUM(Q17:AB17) -> 282.67722 | AD17: 12 | AE17: ='Theo dõi TV'!H19 -> 73.5 | AF17: =_xlfn.XLOOKUP(AE17,M$6:M$24,M$6:M$24,,-1,1) -> 70.14 | AG17: =_xlfn.XLOOKUP(AE17,M$6:M$24,M$6:M$24,,1,1) -> 74.952134 | AH17: =_xlfn.XLOOKUP(AE17,M$6:M$24,$A$6:$A$24,,-1,1) -> 60 | AI17: =_xlfn.XLOOKUP(AE17,M$6:M$24,$A$6:$A$24,,1,1) -> 55 | AJ17: =IF(AE17=AF17,AH17,FORECAST(AE17,AH17:AI17,AF17:AG17)) -> 56.508826 | AL17: 12 | AM17: 27 | AN17: =_xlfn.XLOOKUP(AM17,$P$6:$P$24,$P$6:$P$24,,-1,1) -> 25 | AO17: =_xlfn.XLOOKUP(AM17,$P$6:$P$24,$P$6:$P$24,,1,1) -> 30 | AP17: =_xlfn.XLOOKUP(AM17,$P$6:$P$24,$AB$6:$AB$24,,-1,1) -> 32.273514 | AQ17: =_xlfn.XLOOKUP(AM17,$P$6:$P$24,$AB$6:$AB$24,,1,1) -> 28.111135 | AR17: =IF(AM17=AN17,AP17,FORECAST(AM17,AP17:AQ17,AN17:AO17)) -> 30.608562 | AS17: =_xlfn.XLOOKUP(AM17,$A$6:$A$24,$M$6:$M$24,,-1,1) -> 107 | AT17: =_xlfn.XLOOKUP(AM17,$A$6:$A$24,$M$6:$M$24,,1,1) -> 93.2 | AU17: =IF(AM17=AN17,AS17,FORECAST(AM17,AS17:AT17,AN17:AO17)) -> 101.48
A18: 65 | B18: 41.743016 | C18: 30.09 | D18: 22.44004 | E18: 24.595 | F18: 34.013594 | G18: 54.155 | H18: 78.97469 | I18: 122.9 | J18: 166.45 | K18: 158.03908 | L18: 98.034624 | M18: 64.903562 | N18: 84.1325 | P18: 65 | Q18: =IF(B18*Q5*24*3600/$AE$3/10^6>$AE$2,$AE$2,B18*Q5*24*3600/$AE$3/10^6) -> 12.590596 | R18: =IF(C18*R5*24*3600/$AE$3/10^6>$AE$2,$AE$2,C18*R5*24*3600/$AE$3/10^6) -> 8.4902595 | S18: =IF(D18*S5*24*3600/$AE$3/10^6>$AE$2,$AE$2,D18*S5*24*3600/$AE$3/10^6) -> 6.7684014 | T18: =IF(E18*T5*24*3600/$AE$3/10^6>$AE$2,$AE$2,E18*T5*24*3600/$AE$3/10^6) -> 7.1790811 | U18: =IF(F18*U5*24*3600/$AE$3/10^6>$AE$2,$AE$2,F18*U5*24*3600/$AE$3/10^6) -> 10.259235 | V18: =IF(G18*V5*24*3600/$AE$3/10^6>$AE$2,$AE$2,G18*V5*24*3600/$AE$3/10^6) -> 15.807405 | W18: =IF(H18*W5*24*3600/$AE$3/10^6>$AE$2,$AE$2,H18*W5*24*3600/$AE$3/10^6) -> 23.820474 | X18: =IF(I18*X5*24*3600/$AE$3/10^6>$AE$2,$AE$2,I18*X5*24*3600/$AE$3/10^6) -> 37.069297 | ... AB18: =IF(M18*AB5*24*3600/$AE$3/10^6>$AE$2,$AE$2,M18*AB5*24*3600/$AE$3/10^6) -> 19.576318 | AC18: =SUM(Q18:AB18) -> 266.42999 | AM18: Vào | AR18: Ra
A19: 70 | B19: 40.194655 | C19: 28.82829 | D19: 21.84127 | E19: 23.6063 | F19: 32.829122 | G19: 51.7809 | H19: 74.219919 | I19: 106.9 | J19: 162.23282 | K19: 154.0829 | L19: 93.623711 | M19: 62.3 | N19: 83.067878 | P19: 70 | Q19: =IF(B19*Q5*24*3600/$AE$3/10^6>$AE$2,$AE$2,B19*Q5*24*3600/$AE$3/10^6) -> 12.123577 | R19: =IF(C19*R5*24*3600/$AE$3/10^6>$AE$2,$AE$2,C19*R5*24*3600/$AE$3/10^6) -> 8.1342527 | S19: =IF(D19*S5*24*3600/$AE$3/10^6>$AE$2,$AE$2,D19*S5*24*3600/$AE$3/10^6) -> 6.5877992 | T19: =IF(E19*T5*24*3600/$AE$3/10^6>$AE$2,$AE$2,E19*T5*24*3600/$AE$3/10^6) -> 6.8904876 | U19: =IF(F19*U5*24*3600/$AE$3/10^6>$AE$2,$AE$2,F19*U5*24*3600/$AE$3/10^6) -> 9.9019731 | V19: =IF(G19*V5*24*3600/$AE$3/10^6>$AE$2,$AE$2,G19*V5*24*3600/$AE$3/10^6) -> 15.114425 | W19: =IF(H19*W5*24*3600/$AE$3/10^6>$AE$2,$AE$2,H19*W5*24*3600/$AE$3/10^6) -> 22.386332 | X19: =IF(I19*X5*24*3600/$AE$3/10^6>$AE$2,$AE$2,I19*X5*24*3600/$AE$3/10^6) -> 32.243351 | ... AB19: =IF(M19*AB5*24*3600/$AE$3/10^6>$AE$2,$AE$2,M19*AB5*24*3600/$AE$3/10^6) -> 18.791027 | AC19: =SUM(Q19:AB19) -> 253.33041
A20: 75 | B20: 38.704176 | C20: 27.675283 | D20: 21.65 | E20: 21.462264 | F20: 31.1 | G20: 50.775 | H20: 69.175 | I20: 105.75 | J20: 146.23671 | K20: 147.5 | L20: 90.886779 | M20: 56.508726 | N20: 81.197917 | P20: 75 | Q20: =IF(B20*$Q$5*24*3600/$AE$3/10^6>$AE$2,$AE$2,B20*$Q$5*24*3600/$AE$3/10^6) -> 11.674016 | R20: =IF(C20*$R$5*24*3600/$AE$3/10^6>$AE$2,$AE$2,C20*$R$5*24*3600/$AE$3/10^6) -> 7.8089178 | S20: =IF(D20*$S$5*24*3600/$AE$3/10^6>$AE$2,$AE$2,D20*$S$5*24*3600/$AE$3/10^6) -> 6.5301081 | T20: =IF(E20*$T$5*24*3600/$AE$3/10^6>$AE$2,$AE$2,E20*$T$5*24*3600/$AE$3/10^6) -> 6.2646608 | U20: =IF(F20*$U$5*24*3600/$AE$3/10^6>$AE$2,$AE$2,F20*$U$5*24*3600/$AE$3/10^6) -> 9.3804324 | V20: =IF(G20*$V$5*24*3600/$AE$3/10^6>$AE$2,$AE$2,G20*$V$5*24*3600/$AE$3/10^6) -> 14.820811 | W20: =IF(H20*$W$5*24*3600/$AE$3/10^6>$AE$2,$AE$2,H20*$W$5*24*3600/$AE$3/10^6) -> 20.864676 | X20: =IF(I20*$X$5*24*3600/$AE$3/10^6>$AE$2,$AE$2,I20*$X$5*24*3600/$AE$3/10^6) -> 31.896486 | Y20: =IF(J20*$Y$5*24*3600/$AE$3/10^6>$AE$2,$AE$2,J20*$Y$5*24*3600/$AE$3/10^6) -> 42.68531 | Z20: =IF(K20*$Z$5*24*3600/$AE$3/10^6>$AE$2,$AE$2,K20*$Z$5*24*3600/$AE$3/10^6) -> 44.489189 | AA20: =IF(L20*$AA$5*24*3600/$AE$3/10^6>$AE$2,$AE$2,L20*$AA$5*24*3600/$AE$3/10^6) -> 26.529114 | AB20: =IF(M20*$AB$5*24*3600/$AE$3/10^6>$AE$2,$AE$2,M20*$AB$5*24*3600/$AE$3/10^6) -> 17.044254 | AC20: =SUM(Q20:AB20) -> 239.98797
A21: 80 | B21: 38.194297 | C21: 27.245725 | D21: 21.44 | E21: 20.924209 | F21: 29.32 | G21: 48.68 | H21: 63.127016 | I21: 99.868435 | J21: 137.4 | K21: 136.6 | L21: 86.300595 | M21: 55.82 | N21: 80.05 | P21: 80 | Q21: =IF(B21*$Q$5*24*3600/$AE$3/10^6>$AE$2,$AE$2,B21*$Q$5*24*3600/$AE$3/10^6) -> 11.520226 | R21: =IF(C21*$R$5*24*3600/$AE$3/10^6>$AE$2,$AE$2,C21*$R$5*24*3600/$AE$3/10^6) -> 7.6877127 | S21: =IF(D21*$S$5*24*3600/$AE$3/10^6>$AE$2,$AE$2,D21*$S$5*24*3600/$AE$3/10^6) -> 6.4667676 | T21: =IF(E21*$T$5*24*3600/$AE$3/10^6>$AE$2,$AE$2,E21*$T$5*24*3600/$AE$3/10^6) -> 6.1076069 | U21: =IF(F21*$U$5*24*3600/$AE$3/10^6>$AE$2,$AE$2,F21*$U$5*24*3600/$AE$3/10^6) -> 8.8435459 | V21: =IF(G21*$V$5*24*3600/$AE$3/10^6>$AE$2,$AE$2,G21*$V$5*24*3600/$AE$3/10^6) -> 14.209297 | W21: =IF(H21*$W$5*24*3600/$AE$3/10^6>$AE$2,$AE$2,H21*$W$5*24*3600/$AE$3/10^6) -> 19.040473 | X21: =IF(I21*$X$5*24*3600/$AE$3/10^6>$AE$2,$AE$2,I21*$X$5*24*3600/$AE$3/10^6) -> 30.122479 | Y21: =IF(J21*$Y$5*24*3600/$AE$3/10^6>$AE$2,$AE$2,J21*$Y$5*24*3600/$AE$3/10^6) -> 40.105946 | Z21: =IF(K21*$Z$5*24*3600/$AE$3/10^6>$AE$2,$AE$2,K21*$Z$5*24*3600/$AE$3/10^6) -> 41.201514 | AA21: =IF(L21*$AA$5*24*3600/$AE$3/10^6>$AE$2,$AE$2,L21*$AA$5*24*3600/$AE$3/10^6) -> 25.190444 | AB21: =IF(M21*$AB$5*24*3600/$AE$3/10^6>$AE$2,$AE$2,M21*$AB$5*24*3600/$AE$3/10^6) -> 16.836519 | AC21: =SUM(Q21:AB21) -> 227.33253
